Workbook

Sheet RESUMEN APU BELMONTE
A1: ITEM | B1: DESCRIPCIÓN | C1: VALOR
A2: 2.1 | B2: Lavado de superficie | C2: ='APU BELMONTE'!E29 -> 4200
A4: 2.4 | B4: Retiro y Reemplazo de Superboard | C4: =SUM(C5:C6) -> 78500
A5: 2.4.1 | B5: Remoción de lámina superboard | C5: ='APU BELMONTE'!E59 -> 12600
A6: 2.4.2 | B6: Restructuración e Instalación de lámina de fibrocemento | C6: ='APU BELMONTE'!E92 -> 65900
A8: 2.5 | B8: Retiro y Reemplazo de lamina Drywall | C8: =SUM(C9:C10) -> 57200
A9: 2.5.1 | B9: Remoción de lámina de panel yeso | C9: =C5 -> 12600
A10: 2.5.2 | B10: Restructuración e Instalación de lámina de fibrocemento | C10: ='APU BELMONTE'!E123 -> 44600
A12: 4.1.1 | B12: Suministro y Aplicación de Pintura para exteriores | C12: =SUM(C13:C13) -> 20000
B13: Suministro y Aplicación de Pintura para exteriores | C13: ='APU BELMONTE'!E301 -> 20000
A15: 4.3.1 | B15: Suministro y Aplicación de Pintura para interiores | C15: =SUM(C16:C16) -> 13000
B16: Suministro y Aplicación de Pintura para interiores | C16: ='APU BELMONTE'!E331 -> 13000
A18: 4.2.1 | B18: Suministro y Aplicación de Esmalte Pintulux | C18: =SUM(C19:C19) -> 24300
B19: Suministro y Aplicación de Pintura en barandas | C19: ='APU BELMONTE'!E364 -> 24300
A21: 3.1 | B21: Impermeabilización de placas y de cubierta en concreto | C21: =SUM(C22:C23) -> 165200
A22: 3.1.1 | B22: Limpieza Profunda | C22: ='APU BELMONTE'!E153 -> 6230.992
A23: 3.1.2 | B23: Impermeabilización Sikalastic 612 | C23: ='APU BELMONTE'!E182 -> 158969.01
A25: 3.3 | B25: Impermeabilización de viga canal | C25: =C26 -> 13600
A26: 3.3.1 | B26: Lavado e impermeabilización de Viga Canal | C26: ='APU BELMONTE'!E212 -> 13600
A28: 3.9 | B28: Sellado Perimetral de ventaneria | C28: =C29 -> 5200
A29: 3.9.1 | B29: Sellado Perimetral de ventaneria | C29: ='APU BELMONTE'!E241 -> 5200
A31: 3.10 | B31: Sellado Laminas de Superboard | C31: =C32 -> 5700.0001
A32: 3.10.1 | B32: Sellado Laminas de Superboard | C32: ='APU BELMONTE'!E270 -> 5700.0001

Sheet APU BELMONTE
A1: ACTIVIDAD: Lavado General de Superficies | D1: ITEM | E1: 1.0
D2: UNIDAD | E2: M2
A3: I. EQUIPOS
A4: DESCRIPCIÓN | B4: UNIDAD | C4: RENDIMIENTO | D4: TARIFA | E4: VALOR - PARCIAL
A5: Herramienta menor | B5: %MO | C5: 0.1 | D5: =E27 -> 475 | E5: =C5*D5 -> 47.5
A6: Equipos Freshouse | B6: Día | C6: 0.015 | D6: 25000 | E6: =C6*D6 -> 375
A7: Equipo Hidrolavadora | B7: Día | C7: 0.01 | D7: 15000 | E7: =C7*D7 -> 150
A9: SUB - TOTAL | E9: =SUM(E5:E7) -> 572.5
A10: II. MATERIALES
A11: DESCRIPCIÓN | B11: UNIDAD | C11: CANTIDAD | D11: PRECIO - UNIT | E11: VALOR - PARCIAL
A12: Hipoclorito | B12: GL | C12: 0.05 | D12: 35000 | E12: =C12*D12 -> 1750
A13: Limpiador desegrasante | B13: GL | C13: 0.022620968 | D13: 62000 | E13: =C13*D13 -> 1402.5
A15: Desperdicio 2% | E15: 0
A17: SUB - TOTAL | E17: =SUM(E12:E15) -> 3152.5
A18: III. TRANSPORTE
A19: DESCRIPCIÓN | B19: UNIDAD | C19: RENDIMIENTO | D19: TARIFA | E19: VALOR - PARCIAL
A20: Acarreo LUV | B20: Día | C20: 0 | D20: 0 | E20: 0
A22: SUB - TOTAL | E22: =SUM(E20) -> 0
A23: IV. MANO DE OBRA
A24: DESCRIPCIÓN | B24: UNIDAD | C24: RENDIMIENTO | D24: JORNAL | E24: VALOR - PARCIAL
A25: Práctico | B25: Día | C25: 200 | D25: 95000 | E25: =D25/C25 -> 475
A27: SUB - TOTAL | E27: =SUM(E25) -> 475
A29: TOTAL UNITARIO | E29: =SUM(E9,E17,E22,E27) -> 4200
A32: Retiro y Reemplazo de Superboard y Drywall
A34: ACTIVIDAD: Remoción de lámina superboard | D34: ITEM | E34: 1.0
D35: UNIDAD | E35: M2
A36: I. EQUIPOS
A37: DESCRIPCIÓN | B37: UNIDAD | C37: RENDIMIENTO | D37: TARIFA | E37: VALOR - PARCIAL
A38: Herramienta menor | B38: %MO | C38: 0.1 | D38: =E57 -> 11000 | E38: =C38*D38 -> 1100
A39: Equipos Freshouse | B39: Día | C39: 0.02 | D39: 25000 | E39: =C39*D39 -> 500
A41: SUB - TOTAL | E41: =SUM(E38:E39) -> 1600
A42: II. MATERIALES
A43: DESCRIPCIÓN | B43: UNIDAD | C43: CANTIDAD | D43: PRECIO - UNIT | E43: VALOR - PARCIAL
A45: Desperdicio 2% | E45: =SUM(E44:E44)*0.02 -> 0
A47: SUB - TOTAL | E47: =SUM(E44:E45) -> 0
A48: III. TRANSPORTE
A49: DESCRIPCIÓN | B49: UNIDAD | C49: RENDIMIENTO | D49: TARIFA | E49: VALOR - PARCIAL
A50: Acarreo LUV | B50: Día | C50: 0 | D50: 45000 | E50: =D50*C50 -> 0
A52: SUB - TOTAL | E52: =SUM(E50) -> 0
A53: IV. MANO DE OBRA
...
