Workbook

Sheet acta 01 nov 5 2025
A1: ACTA 01 DE AVANCE DE OBRA-PARQUE RESIDENCIAL LOS CEDROS
A2: Contratante: Parque residencial Los Cedros | D2: INTERVENTOR: Ing. Luis Fernando Márquez Jaramillo
A3: Contratista: Freshouse SAS | D3: FECHA: 04/03/2026 | G3: PNK-001-2025 | H3: Acta 01- Periodo del
A4: Periodo de Ejecucion: 15/01/2026 a 28/02/3026 | H4: sept 22 a noviembre 5 de 2025
A5: CAPT | B5: ITEMS | C5: DESCRIPCION | D5: UNIDAD | E5: CANTIDAD | F5: VR UNITARIO | G5: VALOR DIRECTO ACTIVIDAD | H5: Cantidad | I5: % avance | J5: Valor Total
A6: 1.0 | C6: PRELIMINARES | G6: =+G7+G8 -> 1800000 | J6: =+J7+J8 -> 1602000
B7: 1.1 | C7: Campamento | D7: Gl | E7: 1 | F7: 1500000 | G7: =F7*E7 -> 1500000 | H7: 1 | I7: =+H7/E7 -> 1 | J7: =+H7*F7 -> 1500000
B8: 1.2 | C8: Señalizacion y Seguridad | D8: Gl | E8: 1 | F8: 300000 | G8: =F8*E8 -> 300000 | H8: 0.34 | I8: =+H8/E8 -> 0.34 | J8: =+H8*F8 -> 102000
A9: 2 | C9: PREPARACION DE SUPERFICIES | G9: =+G10+G12 -> 61681852 | J9: =+J10+J12 -> 8404871.5
B10: 2.1 | C10: LAVADO Y LIMPIEZA | G10: =+SUM(G11:G11) -> 14562834 | J10: =+SUM(J11:J11) -> 7052797.2
B11: 2.1.1 | C11: Lavado de Fachadas Externas (blanco, gris, negro, color madera) | D11: M2 | E11: 4629 | F11: 3146 | G11: =F11*E11 -> 14562834 | H11: =Lavado!S69 -> 2241.83 | I11: =+H11/E11 -> 0.48430114 | J11: =+F11*H11 -> 7052797.2
B12: 2.2 | C12: REPARACIONES Y TRATAMIENTOS ESPECIALES en Fachada | G12: =SUM(G13:G17) -> 47119018 | J12: =SUM(J13:J17) -> 1352074.4
B13: 2.2.1 | C13: Suministro y Reposicion de mortero quemado o desprendido | D13: M2 | E13: 40 | F13: 39400 | G13: =F13*E13 -> 1576000 | H13: 0 | I13: =+H13/E13 -> 0 | J13: =+F13*H13 -> 0
B14: 2.2.2 | C14: Suministro y Reposición de graniplast - silcoplast deteriorado | D14: M2 | E14: =+SUM(E21:E23)*15% -> 791.8635 | F14: 36500 | G14: =F14*E14 -> 28903018 | H14: =Sicoplast!S50 -> 32.8719 | I14: =+H14/E14 -> 0.041512079 | J14: =+F14*H14 -> 1199824.4
B15: 2.2.3 | C15: Retiro y Sustitucion de laminas de Superboard en mal estado | D15: M2 | E15: 100 | F15: 87000 | G15: =F15*E15 -> 8700000 | H15: 1.75 | I15: =+H15/E15 -> 0.0175 | J15: =+F15*H15 -> 152250
B16: 2.2.4 | C16: Retiro y Sustitucion de laminas de superboard tipo Siding Color Madera | D16: M2 | E16: 60 | F16: 87000 | G16: =F16*E16 -> 5220000 | H16: 0 | I16: =+H16/E16 -> 0 | J16: =+F16*H16 -> 0
B17: 2.2.5 | C17: Retiro y Sustitución de láminas de Drywall en mal estado, interiores y exteriores | D17: M2 | E17: 40 | F17: 68000 | G17: =F17*E17 -> 2720000 | H17: 0 | I17: =+H17/E17 -> 0 | J17: =+F17*H17 -> 0
B18: 2.2.6 | C18: Suministro e Instalacion de Cortagoteras en Balcones y Accesos a los bloques de aptos | D18: ML | E18: 1055.3 | F18: 28877 | G18: =F18*E18 -> 30473898 | H18: =14.5+16.2 -> 30.7 | I18: =+H18/E18 -> 0.029091254 | J18: =+F18*H18 -> 886523.9
A19: 3 | C19: PINTURA | G19: =+G20+G27+G32 -> 182335405 | J19: =+J20+J27+J32 -> 34478535
B20: 3.1 | C20: Pintura Tipo Koraza para Exteriores | G20: =+SUM(G21:G26) -> 107586123 | J20: =+SUM(J21:J26) -> 20579023
B21: 3.1.1 | C21: Suministro y Aplicación de Pintura para exteriores, tipo Koraza, sobre superficies de Fachadas y Muros Externos de los bloques de apartamentos | D21: M2 | E21: 4629 | F21: 16692 | G21: =F21*E21 -> 77267268 | H21: =Pintura!S50 -> 1232.8674 | I21: =+H21/E21 -> 0.26633558 | J21: =+F21*H21 -> 20579023
B22: 3.1.2 | C22: Pintura gris para exteriores tipo Koraza Proteccion Sol y Lluvia Impermeabilizante | D22: M2 | E22: 467.17 | F22: 21000 | G22: =F22*E22 -> 9810570 | H22: 0 | I22: =+H22/E22 -> 0 | J22: =+F22*H22 -> 0
B23: 3.1.3 | C23: Pintura negra para exteriores tipo Koraza Proteccion Sol y Lluvia Impermeabilizante | D23: M2 | E23: 182.92 | F23: 21000 | G23: =F23*E23 -> 3841320 | H23: 0 | I23: =+H23/E23 -> 0 | J23: =+F23*H23 -> 0
B24: 3.1.4 | C24: Pintura Tipo Koraza Proteccion Sol y Lluvia Impermeabilizante sobre lamina tipo siding (color madera cedro) | D24: M2 | E24: 565.54 | F24: 17500 | G24: =F24*E24 -> 9896950 | H24: 0 | I24: =+H24/E24 -> 0 | J24: =+F24*H24 -> 0
B25: 3.1.5 | C25: Pintura gris basalto koraza (parqueaderos) | D25: M2 | E25: 161.75 | F25: 17500 | G25: =F25*E25 -> 2830625 | I25: =+H25/E25 -> 0 | J25: =+F25*H25 -> 0
B26: 3.1.6 | C26: Pintura sobre alfajías Tipo Koraza Proteccion Sol y Lluvia Impermeabilizante | D26: ML | E26: 532.35 | F26: 7400 | G26: =F26*E26 -> 3939390 | H26: 0 | I26: =+H26/E26 -> 0 | J26: =+F26*H26 -> 0
B27: 3.2 | C27: Pintura Tipo Pintulux 3 en 1 sobre Elementos Metalicos | G27: =+SUM(G28:G31) -> 52090282 | J27: =+SUM(J28:J31) -> 8892692.5
B28: 3.2.1 | C28: Pintura Pintulux 3 en 1 estructura metalica parqueaderos | D28: M2 | E28: 1306 | F28: 16717 | G28: =F28*E28 -> 21832402 | H28: =185.5+185.5 -> 371 | I28: =+H28/E28 -> 0.28407351 | J28: =+F28*H28 -> 6202007
B29: 3.2.2 | C29: Suministro y Aplicación de Pintuco Fill sobre las cubiertas de los parqueaderos | D29: M2 | E29: 1306 | F29: 15125 | G29: =F29*E29 -> 19753250 | H29: 124.02 | I29: =+H29/E29 -> 0.094961715 | J29: =+F29*H29 -> 1875802.5
B30: 3.2.3 | C30: Suministro y Aplicación de Pintura para Barandas Metalicas en areas exteriores: gimnasio, pasillos, cuarto de acueducto, piscina | D30: ML | E30: 187 | F30: 19006 | G30: =F30*E30 -> 3554122 | H30: 23 | I30: =+H30/E30 -> 0.12299465 | J30: =+F30*H30 -> 437138
B31: 3.2.4 | C31: Suministro y Aplicación de Pintura tipo 3 en 1, en puertas de los apartamentos (estan incluidas las de los exteriores, porteria motobombas) | D31: UND | E31: 92 | F31: 75549 | G31: =F31*E31 -> 6950508 | H31: =1+1+3 -> 5 | I31: =+H31/E31 -> 0.054347826 | J31: =+F31*H31 -> 377745
B32: 3.3 | C32: Pintura Tipo Viniltex Advanced de Pintuco en Interiores | G32: =+SUM(G33:G33) -> 22659000 | J32: =+SUM(J33:J33) -> 5006820
B33: 3.3.1 | C33: Suministro y Aplicación de Pintura tipo Vinilo en areas comunes internas de los bloques de aptos: paredes y cielos rasos | D33: M2 | E33: 2158 | F33: 10500 | G33: =F33*E33 -> 22659000 | H33: =Pasillos!S22 -> 476.84 | I33: =+H33/E33 -> 0.22096386 | J33: =+F33*H33 -> 5006820
A34: 4 | C34: CARPINTERIA EN ALUMINIO y Vidrio | G34: =+SUM(G35:G35) -> 6020406.4 | J34: =+SUM(J35:J35) -> 6550252.8
B35: 4.1 | C35: Retiro y Reposicion de sello perimetral en elementos vidriados de los bloque de apartamentos (30% DEL TOTAL) | D35: ML | E35: 817.99 | F35: 7360 | G35: =F35*E35 -> 6020406.4 | H35: =Sellos!S50 -> 889.98 | I35: =+H35/E35 -> 1.0880084 | J35: =+F35*H35 -> 6550252.8
A36: 5 | C36: VARIOS | G36: =++G37+G38 -> 5450000 | J36: =++J37+J38 -> 0
B37: 5.1 | C37: Media caña en concreto incluye impermeabilizado | D37: ML | E37: 30 | F37: 55000 | G37: =F37*E37 -> 1650000 | H37: 0 | I37: =+H37/E37 -> 0 | J37: =+F37*H37 -> 0
B38: 5.2 | C38: Acondicionamiento de Acceso a Terraza | D38: Gl | E38: 1 | F38: 3800000 | G38: =F38*E38 -> 3800000 | H38: 0 | I38: =+H38/E38 -> 0 | J38: =+F38*H38 -> 0
A39: 6 | C39: CUBIERTA | G39: =+SUM(G40:G45) -> 33191144 | J39: =+SUM(J40:J45) -> 0
B40: 6.1 | C40: Recorrido General de Cubierta Principal en UPVC | D40: M2 | E40: 312 | F40: 25000 | G40: =+E40*F40 -> 7800000 | H40: 0 | I40: =+H40/E40 -> 0 | J40: =+F40*H40 -> 0
...

Sheet acta 02 dic 15 2025
A1: ACTA 01 DE AVANCE DE OBRA-EDIF PANORAMIKA
A2: Contratante: Edificio Panoramika PH | D2: INTERVENTOR: Ing. Luis Fernando Márquez Jaramillo
A3: Contratista: Freshouse SAS | D3: FECHA: 19/01/2026 | G3: PNK-001-2025 | H3: Acta 01- Periodo del | K3: Acta 02- Periodo del | N3: Acta 03- Periodo del | Q3: Acumulado de actas
A4: Periodo de Ejecucion: | H4: sept 22 a noviembre 5 de 2025 | K4: nov 06 a dic 05 de 2025 | N4: dic 06 a enero 19 de 2025 | Q4: sept 22 a enero 19 de 2026
A5: CAPT | B5: ITEMS | C5: DESCRIPCION | D5: UNIDAD | E5: CANTIDAD | F5: VR UNITARIO | G5: VALOR DIRECTO ACTIVIDAD | H5: Cantidad | I5: % avance | J5: Valor Total | K5: Cantidad | L5: % avance | M5: Valor Total | N5: Cantidad | O5: % avance | P5: Valor Total | Q5: Cantidad | R5: % avance | S5: Valor Total
A6: 1.0 | C6: PRELIMINARES | G6: =+G7+G8 -> 880000 | J6: =+J7+J8 -> 707500 | M6: =+M7+M8 -> 57500 | P6: =+P7+P8 -> 57500 | S6: =+S7+S8 -> 822500
B7: 1.1 | C7: Campamento | D7: Gl | E7: 1 | F7: 650000 | G7: =F7*E7 -> 650000 | H7: 1 | I7: =+H7/E7 -> 1 | J7: =+H7*F7 -> 650000 | K7: 0 | L7: =K7/E7 -> 0 | M7: =+K7*F7 -> 0 | N7: 0 | O7: =N7/E7 -> 0 | P7: =+N7*F7 -> 0 | Q7: =H7+K7+N7 -> 1 | R7: =Q7/E7 -> 1 | S7: =+Q7*F7 -> 650000
B8: 1.2 | C8: Señalizacion y Seguridad | D8: Gl | E8: 1 | F8: 230000 | G8: =F8*E8 -> 230000 | H8: 0.25 | I8: =+H8/E8 -> 0.25 | J8: =+H8*F8 -> 57500 | K8: 0.25 | L8: =K8/E8 -> 0.25 | M8: =+K8*F8 -> 57500 | N8: 0.25 | O8: =N8/E8 -> 0.25 | P8: =+N8*F8 -> 57500 | Q8: =H8+K8+N8 -> 0.75 | R8: =Q8/E8 -> 0.75 | S8: =+Q8*F8 -> 172500
A9: 2 | C9: PREPARACION DE SUPERFICIES | G9: =+G10+G14 -> 56542255 | J9: =+J10+J14 -> 10058452 | M9: =+M10+M14 -> #REF! | P9: =+P10+P14 -> 0 | S9: =+S10+S14 -> #REF!
B10: 2.1 | C10: LAVADO Y LIMPIEZA | G10: =+SUM(G11:G13) -> 22197398 | J10: =+SUM(J11:J13) -> 9529202.1 | M10: =+SUM(M11:M13) -> #REF! | P10: =+SUM(P11:P13) -> 0 | S10: =+SUM(S11:S13) -> #REF!
B11: 2.1.1 | C11: Lavado de Fachadas Externas (blanco, gris, negro, color madera) | D11: M2 | E11: 2535.74 | F11: 3300 | G11: =F11*E11 -> 8367942 | H11: 988.22935 | I11: =+H11/E11 -> 0.3897203 | J11: =+F11*H11 -> 3261156.9 | K11: =Lavado!#REF! -> #REF! | L11: =K11/E11 -> #REF! | M11: =+K11*F11 -> #REF! | N11: =Lavado!X72 -> 0 | O11: =N11/E11 -> 0 | P11: =+N11*F11 -> 0 | Q11: =H11+K11+N11 -> #REF! | R11: =Q11/E11 -> #REF! | S11: =+Q11*F11 -> #REF!
B12: 2.1.2 | C12: Limpieza de carpinteria en aluminio (Ventanas, marcos, pasamanos y balcones) | D12: M2 | E12: 1970.54 | F12: 3400 | G12: =F12*E12 -> 6699836 | H12: 686.73565 | I12: =+H12/E12 -> 0.34850125 | J12: =+F12*H12 -> 2334901.2 | K12: =Lavado!#REF! -> #REF! | L12: =K12/E12 -> #REF! | M12: =+K12*F12 -> #REF! | N12: =Lavado!X73 -> 0 | O12: =N12/E12 -> 0 | P12: =+N12*F12 -> 0 | Q12: =H12+K12+N12 -> #REF! | R12: =Q12/E12 -> #REF! | S12: =+Q12*F12 -> #REF!
B13: 2.1.3 | C13: Limpieza de fachadas internas | D13: M2 | E13: 2640.6 | F13: 2700 | G13: =F13*E13 -> 7129620 | H13: 1456.72 | I13: =+H13/E13 -> 0.5516625 | J13: =+F13*H13 -> 3933144 | K13: =2640*0.4 -> 1056 | L13: =K13/E13 -> 0.39990911 | M13: =+K13*F13 -> 2851200 | N13: 0 | O13: =N13/E13 -> 0 | P13: =+N13*F13 -> 0 | Q13: =H13+K13+N13 -> 2512.72 | R13: =Q13/E13 -> 0.95157161 | S13: =+Q13*F13 -> 6784344
B14: 2.2 | C14: REPARACIONES Y TRATAMIENTOS ESPECIALES en Fachada | G14: =SUM(G15:G19) -> 34344857 | J14: =SUM(J15:J19) -> 529250 | M14: =SUM(M15:M19) -> 0 | P14: =SUM(P15:P19) -> 0 | S14: =SUM(S15:S19) -> 529250
B15: 2.2.1 | C15: Suministro y Reposicion de mortero quemado o desprendido | D15: M2 | E15: 40 | F15: 39400 | G15: =F15*E15 -> 1576000 | H15: 0 | I15: =+H15/E15 -> 0 | J15: =+F15*H15 -> 0 | K15: 0 | L15: =K15/E15 -> 0 | M15: =+K15*F15 -> 0 | N15: 0 | O15: =N15/E15 -> 0 | P15: =+N15*F15 -> 0 | Q15: =H15+K15+N15 -> 0 | R15: =Q15/E15 -> 0 | S15: =+Q15*F15 -> 0
B16: 2.2.2 | C16: Suministro y Reposición de graniplast - silcoplast deteriorado | D16: M2 | E16: =+SUM(E22:E24)*15% -> 441.8865 | F16: 36500 | G16: =F16*E16 -> 16128857 | H16: 14.5 | I16: =+H16/E16 -> 0.032813856 | J16: =+F16*H16 -> 529250 | K16: =Sicoplast!AA22 -> 0 | L16: =K16/E16 -> 0 | M16: =+K16*F16 -> 0 | N16: =Sicoplast!AF22 -> 0 | O16: =N16/E16 -> 0 | P16: =+N16*F16 -> 0 | Q16: =H16+K16+N16 -> 14.5 | R16: =Q16/E16 -> 0.032813856 | S16: =+Q16*F16 -> 529250
B17: 2.2.3 | C17: Retiro y Sustitucion de laminas de Superboard en mal estado | D17: M2 | E17: 100 | F17: 87000 | G17: =F17*E17 -> 8700000 | H17: 0 | I17: =+H17/E17 -> 0 | J17: =+F17*H17 -> 0 | K17: 0 | L17: =K17/E17 -> 0 | M17: =+K17*F17 -> 0 | N17: 0 | O17: =N17/E17 -> 0 | P17: =+N17*F17 -> 0 | Q17: =H17+K17+N17 -> 0 | R17: =Q17/E17 -> 0 | S17: =+Q17*F17 -> 0
B18: 2.2.4 | C18: Retiro y Sustitucion de laminas de superboard tipo Siding Color Madera | D18: M2 | E18: 60 | F18: 87000 | G18: =F18*E18 -> 5220000 | H18: 0 | I18: =+H18/E18 -> 0 | J18: =+F18*H18 -> 0 | K18: 0 | L18: =K18/E18 -> 0 | M18: =+K18*F18 -> 0 | N18: 0 | O18: =N18/E18 -> 0 | P18: =+N18*F18 -> 0 | Q18: =H18+K18+N18 -> 0 | R18: =Q18/E18 -> 0 | S18: =+Q18*F18 -> 0
B19: 2.2.5 | C19: Retiro y Sustitución de láminas de Drywall en mal estado, interiores y exteriores | D19: M2 | E19: 40 | F19: 68000 | G19: =F19*E19 -> 2720000 | H19: 0 | I19: =+H19/E19 -> 0 | J19: =+F19*H19 -> 0 | K19: 0 | L19: =K19/E19 -> 0 | M19: =+K19*F19 -> 0 | N19: 0 | O19: =N19/E19 -> 0 | P19: =+N19*F19 -> 0 | Q19: =H19+K19+N19 -> 0 | R19: =Q19/E19 -> 0 | S19: =+Q19*F19 -> 0
A20: 3 | C20: PINTURA | G20: =+G21+G28+G31 -> 130602942 | J20: =+J21+J28+J31 -> 33667857 | M20: =+M21+M28+M31 -> #REF! | P20: =+P21+P28+P31 -> #REF! | S20: =+S21+S28+S31 -> #REF!
B21: 3.1 | C21: Pintura Tipo Koraza para Exteriores | G21: =+SUM(G22:G27) -> 78531075 | J21: =+SUM(J22:J27) -> 16187217 | M21: =+SUM(M22:M27) -> #REF! | P21: =+SUM(P22:P27) -> #REF! | S21: =+SUM(S22:S27) -> #REF!
B22: 3.1.1 | C22: Pintura blanca para exteriores tipo Koraza Proteccion Sol y Lluvia Impermeabilizante | D22: M2 | E22: 2295.82 | F22: 21000 | G22: =F22*E22 -> 48212220 | H22: 471.33018 | I22: =+H22/E22 -> 0.20529928 | J22: =+F22*H22 -> 9897933.8 | K22: =Pintura!#REF! -> #REF! | L22: =K22/E22 -> #REF! | M22: =+K22*F22 -> #REF! | N22: =Pintura!#REF! -> #REF! | O22: =N22/E22 -> #REF! | P22: =+N22*F22 -> #REF! | Q22: =H22+K22+N22 -> #REF! | R22: =Q22/E22 -> #REF! | S22: =+Q22*F22 -> #REF!
B23: 3.1.2 | C23: Pintura gris para exteriores tipo Koraza Proteccion Sol y Lluvia Impermeabilizante | D23: M2 | E23: 467.17 | F23: 21000 | G23: =F23*E23 -> 9810570 | H23: 181.28084 | I23: =+H23/E23 -> 0.38804041 | J23: =+F23*H23 -> 3806897.6 | K23: =Pintura!#REF! -> #REF! | L23: =K23/E23 -> #REF! | M23: =+K23*F23 -> #REF! | N23: =Pintura!#REF! -> #REF! | O23: =N23/E23 -> #REF! | P23: =+N23*F23 -> #REF! | Q23: =H23+K23+N23 -> #REF! | R23: =Q23/E23 -> #REF! | S23: =+Q23*F23 -> #REF!
B24: 3.1.3 | C24: Pintura negra para exteriores tipo Koraza Proteccion Sol y Lluvia Impermeabilizante | D24: M2 | E24: 182.92 | F24: 21000 | G24: =F24*E24 -> 3841320 | H24: 14.502467 | I24: =+H24/E24 -> 0.079283114 | J24: =+F24*H24 -> 304551.81 | K24: =Pintura!#REF! -> #REF! | L24: =K24/E24 -> #REF! | M24: =+K24*F24 -> #REF! | N24: =Pintura!#REF! -> #REF! | O24: =N24/E24 -> #REF! | P24: =+N24*F24 -> #REF! | Q24: =H24+K24+N24 -> #REF! | R24: =Q24/E24 -> #REF! | S24: =+Q24*F24 -> #REF!
B25: 3.1.4 | C25: Pintura Tipo Koraza Proteccion Sol y Lluvia Impermeabilizante sobre lamina tipo siding (color madera cedro) | D25: M2 | E25: 565.54 | F25: 17500 | G25: =F25*E25 -> 9896950 | H25: 72.512336 | I25: =+H25/E25 -> 0.12821787 | J25: =+F25*H25 -> 1268965.9 | K25: =Pintura!#REF! -> #REF! | L25: =K25/E25 -> #REF! | M25: =+K25*F25 -> #REF! | N25: =Pintura!#REF! -> #REF! | O25: =N25/E25 -> #REF! | P25: =+N25*F25 -> #REF! | Q25: =H25+K25+N25 -> #REF! | R25: =Q25/E25 -> #REF! | S25: =+Q25*F25 -> #REF!
B26: 3.1.5 | C26: Pintura gris basalto koraza (parqueaderos) | D26: M2 | E26: 161.75 | F26: 17500 | G26: =F26*E26 -> 2830625 | H26: 0 | I26: =+H26/E26 -> 0 | J26: =+F26*H26 -> 0 | K26: 0 | L26: =K26/E26 -> 0 | M26: =+K26*F26 -> 0 | N26: 0 | O26: =N26/E26 -> 0 | P26: =+N26*F26 -> 0 | Q26: =H26+K26+N26 -> 0 | R26: =Q26/E26 -> 0 | S26: =+Q26*F26 -> 0
B27: 3.1.6 | C27: Pintura sobre alfajías Tipo Koraza Proteccion Sol y Lluvia Impermeabilizante | D27: ML | E27: 532.35 | F27: 7400 | G27: =F27*E27 -> 3939390 | H27: 122.82 | I27: =+H27/E27 -> 0.23071288 | J27: =+F27*H27 -> 908868 | K27: =Pintura!#REF! -> #REF! | L27: =K27/E27 -> #REF! | M27: =+K27*F27 -> #REF! | N27: =Pintura!#REF! -> #REF! | O27: =N27/E27 -> #REF! | P27: =+N27*F27 -> #REF! | Q27: =H27+K27+N27 -> #REF! | R27: =Q27/E27 -> #REF! | S27: =+Q27*F27 -> #REF!
B28: 3.2 | C28: Pintura Tipo Pintulux 3 en 1 sobre Elementos Metalicos | G28: =+SUM(G29:G30) -> 8043387 | J28: =+SUM(J29:J30) -> 0 | M28: =+SUM(M29:M30) -> 0 | P28: =+SUM(P29:P30) -> 0 | S28: =+SUM(S29:S30) -> 0
B29: 3.2.1 | C29: Pintura Pintulux 3 en 1 (carpinteria metalica parqueaderos) | D29: M2 | E29: 245.69 | F29: 22300 | G29: =F29*E29 -> 5478887 | H29: 0 | I29: =+H29/E29 -> 0 | J29: =+F29*H29 -> 0 | K29: 0 | L29: =K29/E29 -> 0 | M29: =+K29*F29 -> 0 | N29: 0 | O29: =N29/E29 -> 0 | P29: =+N29*F29 -> 0 | Q29: =H29+K29+N29 -> 0 | R29: =Q29/E29 -> 0 | S29: =+Q29*F29 -> 0
B30: 3.2.2 | C30: Pintura Pintulux 3 en 1 en carpinteria metalica de soporte y de guia de teja translucida | D30: M2 | E30: 115 | F30: 22300 | G30: =F30*E30 -> 2564500 | H30: 0 | I30: =+H30/E30 -> 0 | J30: =+F30*H30 -> 0 | K30: 0 | L30: =K30/E30 -> 0 | M30: =+K30*F30 -> 0 | N30: 0 | O30: =N30/E30 -> 0 | P30: =+N30*F30 -> 0 | Q30: =H30+K30+N30 -> 0 | R30: =Q30/E30 -> 0 | S30: =+Q30*F30 -> 0
B31: 3.3 | C31: Pintura Tipo Viniltex Advanced de Pintuco en Interiores | G31: =+SUM(G32:G33) -> 44028480 | J31: =+SUM(J32:J33) -> 17480640 | M31: =+SUM(M32:M33) -> 8169600 | P31: =+SUM(P32:P33) -> 0 | S31: =+SUM(S32:S33) -> 25650240
B32: 3.3.1 | C32: Pintura para Muros Interiores tipo 1 viniltex advanced de pintuco color blanco | D32: M2 | E32: 2640.6 | F32: 12000 | G32: =F32*E32 -> 31687200 | H32: 874.032 | I32: =+H32/E32 -> 0.3309975 | J32: =+F32*H32 -> 10488384 | K32: 680.8 | L32: =K32/E32 -> 0.25782019 | M32: =+K32*F32 -> 8169600 | N32: 0 | O32: =N32/E32 -> 0 | P32: =+N32*F32 -> 0 | Q32: =H32+K32+N32 -> 1554.832 | R32: =Q32/E32 -> 0.58881769 | S32: =+Q32*F32 -> 18657984
B33: 3.3.2 | C33: Pintura para Cielorrasos Interiores Tipo Viniltex Advanced de Pintuco Color Blanco | D33: M2 | E33: 1028.44 | F33: 12000 | G33: =F33*E33 -> 12341280 | H33: 582.688 | I33: =+H33/E33 -> 0.56657462 | J33: =+F33*H33 -> 6992256 | K33: 0 | L33: =K33/E33 -> 0 | M33: =+K33*F33 -> 0 | N33: 0 | O33: =N33/E33 -> 0 | P33: =+N33*F33 -> 0 | Q33: =H33+K33+N33 -> 582.688 | R33: =Q33/E33 -> 0.56657462 | S33: =+Q33*F33 -> 6992256
A34: 4 | C34: CARPINTERIA EN ALUMINIO y Vidrio | G34: =+SUM(G35:G37) -> 13115377 | J34: =+SUM(J35:J37) -> 1869038 | M34: =+SUM(M35:M37) -> #REF! | P34: =+SUM(P35:P37) -> #REF! | S34: =+SUM(S35:S37) -> #REF!
B35: 4.1 | C35: Resellado Perimetral de Elementos Vidriados en Fachada | D35: ML | E35: 1610.82 | F35: 5700 | G35: =F35*E35 -> 9181674 | H35: 214.4 | I35: =+H35/E35 -> 0.13309991 | J35: =+F35*H35 -> 1222080 | K35: =Sellos!#REF! -> #REF! | L35: =K35/E35 -> #REF! | M35: =+K35*F35 -> #REF! | N35: =Sellos!#REF! -> #REF! | O35: =N35/E35 -> #REF! | P35: =+N35*F35 -> #REF! | Q35: =H35+K35 -> #REF! | R35: =Q35/E35 -> #REF! | S35: =+Q35*F35 -> #REF!
B36: 4.2 | C36: Desmonte y vuelta a instalar de vidrio templado de cerramiento en terraza y Jacuzzi | D36: M2 | E36: 86.09 | F36: 16700 | G36: =F36*E36 -> 1437703 | H36: 38.74 | I36: =+H36/E36 -> 0.44999419 | J36: =+F36*H36 -> 646958 | K36: 0 | L36: =K36/E36 -> 0 | M36: =+K36*F36 -> 0 | N36: 0 | O36: =N36/E36 -> 0 | P36: =+N36*F36 -> 0 | Q36: =H36+K36 -> 38.74 | R36: =Q36/E36 -> 0.44999419 | S36: =+Q36*F36 -> 646958
B37: 4.3 | C37: Suministro e instalación de cortagoteras en aluminio | D37: ML | E37: 48 | F37: 52000 | G37: =F37*E37 -> 2496000 | H37: 0 | I37: =+H37/E37 -> 0 | J37: =+F37*H37 -> 0 | K37: 0 | L37: =K37/E37 -> 0 | M37: =+K37*F37 -> 0 | N37: 0 | O37: =N37/E37 -> 0 | P37: =+N37*F37 -> 0 | Q37: =H37+K37 -> 0 | R37: =Q37/E37 -> 0 | S37: =+Q37*F37 -> 0
A38: 5 | C38: VARIOS | G38: =++G39+G40 -> 5450000 | J38: =++J39+J40 -> 0 | M38: =++M39+M40 -> 0 | P38: =++P39+P40 -> 0 | S38: =++S39+S40 -> 0
B39: 5.1 | C39: Media caña en concreto incluye impermeabilizado | D39: ML | E39: 30 | F39: 55000 | G39: =F39*E39 -> 1650000 | H39: 0 | I39: =+H39/E39 -> 0 | J39: =+F39*H39 -> 0 | K39: 0 | L39: =K39/E39 -> 0 | M39: =+K39*F39 -> 0 | N39: 0 | O39: =N39/E39 -> 0 | P39: =+N39*F39 -> 0 | Q39: =H39+K39 -> 0 | R39: =Q39/E39 -> 0 | S39: =+Q39*F39 -> 0
B40: 5.2 | C40: Acondicionamiento de Acceso a Terraza | D40: Gl | E40: 1 | F40: 3800000 | G40: =F40*E40 -> 3800000 | H40: 0 | I40: =+H40/E40 -> 0 | J40: =+F40*H40 -> 0 | K40: 0 | L40: =K40/E40 -> 0 | M40: =+K40*F40 -> 0 | N40: 0 | O40: =N40/E40 -> 0 | P40: =+N40*F40 -> 0 | Q40: =H40+K40 -> 0 | R40: =Q40/E40 -> 0 | S40: =+Q40*F40 -> 0
...

Sheet acta 03 enero 21 2026
A1: ACTA 03 DE AVANCE DE OBRA-EDIF PANORAMIKA
A2: Contratante: Edificio Panoramika PH | D2: INTERVENTOR: Ing. Luis Fernando Márquez Jaramillo
A3: Contratista: Freshouse SAS | D3: FECHA: 21/01/2026 | G3: PNK-001-2025 | H3: Acta 01- Periodo del | K3: Acta 02- Periodo del | N3: Acta 03- Periodo del | Q3: Acumulado de actas
A4: Periodo de Ejecucion: | H4: sept 22 a noviembre 5 de 2025 | K4: nov 06 a dic 05 de 2025 | N4: dic 06 a enero 19 de 2025 | Q4: sept 22 a enero 19 de 2026
A5: CAPT | B5: ITEMS | C5: DESCRIPCION | D5: UNIDAD | E5: CANTIDAD | F5: VR UNITARIO | G5: VALOR DIRECTO ACTIVIDAD | H5: Cantidad | I5: % avance | J5: Valor Total | K5: Cantidad | L5: % avance | M5: Valor Total | N5: Cantidad | O5: % avance | P5: Valor Total | Q5: Cantidad | R5: % avance | S5: Valor Total
A6: 1.0 | C6: PRELIMINARES | G6: =+G7+G8 -> 880000 | J6: =+J7+J8 -> 707500 | M6: =+M7+M8 -> 57500 | P6: =+P7+P8 -> 57500 | S6: =+S7+S8 -> 822500
B7: 1.1 | C7: Campamento | D7: Gl | E7: 1 | F7: 650000 | G7: =F7*E7 -> 650000 | H7: 1 | I7: =+H7/E7 -> 1 | J7: =+H7*F7 -> 650000 | K7: 0 | L7: =K7/E7 -> 0 | M7: =+K7*F7 -> 0 | N7: 0 | O7: =N7/E7 -> 0 | P7: =+N7*F7 -> 0 | Q7: =H7+K7+N7 -> 1 | R7: =Q7/E7 -> 1 | S7: =+Q7*F7 -> 650000
B8: 1.2 | C8: Señalizacion y Seguridad | D8: Gl | E8: 1 | F8: 230000 | G8: =F8*E8 -> 230000 | H8: 0.25 | I8: =+H8/E8 -> 0.25 | J8: =+H8*F8 -> 57500 | K8: 0.25 | L8: =K8/E8 -> 0.25 | M8: =+K8*F8 -> 57500 | N8: 0.25 | O8: =N8/E8 -> 0.25 | P8: =+N8*F8 -> 57500 | Q8: =H8+K8+N8 -> 0.75 | R8: =Q8/E8 -> 0.75 | S8: =+Q8*F8 -> 172500
A9: 2 | C9: PREPARACION DE SUPERFICIES | G9: =+G10+G14 -> 56542255 | J9: =+J10+J14 -> 10058452 | M9: =+M10+M14 -> #REF! | P9: =+P10+P14 -> #REF! | S9: =+S10+S14 -> #REF!
B10: 2.1 | C10: LAVADO Y LIMPIEZA | G10: =+SUM(G11:G13) -> 22197398 | J10: =+SUM(J11:J13) -> 9529202.1 | M10: =+SUM(M11:M13) -> #REF! | P10: =+SUM(P11:P13) -> #REF! | S10: =+SUM(S11:S13) -> #REF!
B11: 2.1.1 | C11: Lavado de Fachadas Externas (blanco, gris, negro, color madera) | D11: M2 | E11: 2535.74 | F11: 3300 | G11: =F11*E11 -> 8367942 | H11: 988.22935 | I11: =+H11/E11 -> 0.3897203 | J11: =+F11*H11 -> 3261156.9 | K11: =Lavado!#REF! -> #REF! | L11: =K11/E11 -> #REF! | M11: =+K11*F11 -> #REF! | N11: =Lavado!#REF! -> #REF! | O11: =N11/E11 -> #REF! | P11: =+N11*F11 -> #REF! | Q11: =H11+K11+N11 -> #REF! | R11: =Q11/E11 -> #REF! | S11: =+Q11*F11 -> #REF!
B12: 2.1.2 | C12: Limpieza de carpinteria en aluminio (Ventanas, marcos, pasamanos y balcones) | D12: M2 | E12: 1970.54 | F12: 3400 | G12: =F12*E12 -> 6699836 | H12: 686.73565 | I12: =+H12/E12 -> 0.34850125 | J12: =+F12*H12 -> 2334901.2 | K12: =Lavado!#REF! -> #REF! | L12: =K12/E12 -> #REF! | M12: =+K12*F12 -> #REF! | N12: =Lavado!#REF! -> #REF! | O12: =N12/E12 -> #REF! | P12: =+N12*F12 -> #REF! | Q12: =H12+K12+N12 -> #REF! | R12: =Q12/E12 -> #REF! | S12: =+Q12*F12 -> #REF!
B13: 2.1.3 | C13: Limpieza de fachadas internas | D13: M2 | E13: 2640.6 | F13: 2700 | G13: =F13*E13 -> 7129620 | H13: 1456.72 | I13: =+H13/E13 -> 0.5516625 | J13: =+F13*H13 -> 3933144 | K13: =2640*0.4 -> 1056 | L13: =K13/E13 -> 0.39990911 | M13: =+K13*F13 -> 2851200 | N13: 0 | O13: =N13/E13 -> 0 | P13: =+N13*F13 -> 0 | Q13: =H13+K13+N13 -> 2512.72 | R13: =Q13/E13 -> 0.95157161 | S13: =+Q13*F13 -> 6784344
B14: 2.2 | C14: REPARACIONES Y TRATAMIENTOS ESPECIALES en Fachada | G14: =SUM(G15:G19) -> 34344857 | J14: =SUM(J15:J19) -> 529250 | M14: =SUM(M15:M19) -> 0 | P14: =SUM(P15:P19) -> 0 | S14: =SUM(S15:S19) -> 529250
B15: 2.2.1 | C15: Suministro y Reposicion de mortero quemado o desprendido | D15: M2 | E15: 40 | F15: 39400 | G15: =F15*E15 -> 1576000 | H15: 0 | I15: =+H15/E15 -> 0 | J15: =+F15*H15 -> 0 | K15: 0 | L15: =K15/E15 -> 0 | M15: =+K15*F15 -> 0 | N15: 0 | O15: =N15/E15 -> 0 | P15: =+N15*F15 -> 0 | Q15: =H15+K15+N15 -> 0 | R15: =Q15/E15 -> 0 | S15: =+Q15*F15 -> 0
B16: 2.2.2 | C16: Suministro y Reposición de graniplast - silcoplast deteriorado | D16: M2 | E16: =+SUM(E22:E24)*15% -> 441.8865 | F16: 36500 | G16: =F16*E16 -> 16128857 | H16: 14.5 | I16: =+H16/E16 -> 0.032813856 | J16: =+F16*H16 -> 529250 | K16: =Sicoplast!AA22 -> 0 | L16: =K16/E16 -> 0 | M16: =+K16*F16 -> 0 | N16: =Sicoplast!AC36 -> 0 | O16: =N16/E16 -> 0 | P16: =+N16*F16 -> 0 | Q16: =H16+K16+N16 -> 14.5 | R16: =Q16/E16 -> 0.032813856 | S16: =+Q16*F16 -> 529250
B17: 2.2.3 | C17: Retiro y Sustitucion de laminas de Superboard en mal estado | D17: M2 | E17: 100 | F17: 87000 | G17: =F17*E17 -> 8700000 | H17: 0 | I17: =+H17/E17 -> 0 | J17: =+F17*H17 -> 0 | K17: 0 | L17: =K17/E17 -> 0 | M17: =+K17*F17 -> 0 | N17: 0 | O17: =N17/E17 -> 0 | P17: =+N17*F17 -> 0 | Q17: =H17+K17+N17 -> 0 | R17: =Q17/E17 -> 0 | S17: =+Q17*F17 -> 0
B18: 2.2.4 | C18: Retiro y Sustitucion de laminas de superboard tipo Siding Color Madera | D18: M2 | E18: 60 | F18: 87000 | G18: =F18*E18 -> 5220000 | H18: 0 | I18: =+H18/E18 -> 0 | J18: =+F18*H18 -> 0 | K18: 0 | L18: =K18/E18 -> 0 | M18: =+K18*F18 -> 0 | N18: 0 | O18: =N18/E18 -> 0 | P18: =+N18*F18 -> 0 | Q18: =H18+K18+N18 -> 0 | R18: =Q18/E18 -> 0 | S18: =+Q18*F18 -> 0
B19: 2.2.5 | C19: Retiro y Sustitución de láminas de Drywall en mal estado, interiores y exteriores | D19: M2 | E19: 40 | F19: 68000 | G19: =F19*E19 -> 2720000 | H19: 0 | I19: =+H19/E19 -> 0 | J19: =+F19*H19 -> 0 | K19: 0 | L19: =K19/E19 -> 0 | M19: =+K19*F19 -> 0 | N19: 0 | O19: =N19/E19 -> 0 | P19: =+N19*F19 -> 0 | Q19: =H19+K19+N19 -> 0 | R19: =Q19/E19 -> 0 | S19: =+Q19*F19 -> 0
A20: 3 | C20: PINTURA | G20: =+G21+G28+G31 -> 130602942 | J20: =+J21+J28+J31 -> 33667857 | M20: =+M21+M28+M31 -> #REF! | P20: =+P21+P28+P31 -> #REF! | S20: =+S21+S28+S31 -> #REF!
B21: 3.1 | C21: Pintura Tipo Koraza para Exteriores | G21: =+SUM(G22:G27) -> 78531075 | J21: =+SUM(J22:J27) -> 16187217 | M21: =+SUM(M22:M27) -> #REF! | P21: =+SUM(P22:P27) -> #REF! | S21: =+SUM(S22:S27) -> #REF!
B22: 3.1.1 | C22: Pintura blanca para exteriores tipo Koraza Proteccion Sol y Lluvia Impermeabilizante | D22: M2 | E22: 2295.82 | F22: 21000 | G22: =F22*E22 -> 48212220 | H22: 471.33018 | I22: =+H22/E22 -> 0.20529928 | J22: =+F22*H22 -> 9897933.8 | K22: =Pintura!#REF! -> #REF! | L22: =K22/E22 -> #REF! | M22: =+K22*F22 -> #REF! | N22: =Pintura!#REF! -> #REF! | O22: =N22/E22 -> #REF! | P22: =+N22*F22 -> #REF! | Q22: =H22+K22+N22 -> #REF! | R22: =Q22/E22 -> #REF! | S22: =+Q22*F22 -> #REF!
B23: 3.1.2 | C23: Pintura gris para exteriores tipo Koraza Proteccion Sol y Lluvia Impermeabilizante | D23: M2 | E23: 467.17 | F23: 21000 | G23: =F23*E23 -> 9810570 | H23: 181.28084 | I23: =+H23/E23 -> 0.38804041 | J23: =+F23*H23 -> 3806897.6 | K23: =Pintura!#REF! -> #REF! | L23: =K23/E23 -> #REF! | M23: =+K23*F23 -> #REF! | N23: =Pintura!#REF! -> #REF! | O23: =N23/E23 -> #REF! | P23: =+N23*F23 -> #REF! | Q23: =H23+K23+N23 -> #REF! | R23: =Q23/E23 -> #REF! | S23: =+Q23*F23 -> #REF!
B24: 3.1.3 | C24: Pintura negra para exteriores tipo Koraza Proteccion Sol y Lluvia Impermeabilizante | D24: M2 | E24: 182.92 | F24: 21000 | G24: =F24*E24 -> 3841320 | H24: 14.502467 | I24: =+H24/E24 -> 0.079283114 | J24: =+F24*H24 -> 304551.81 | K24: =Pintura!#REF! -> #REF! | L24: =K24/E24 -> #REF! | M24: =+K24*F24 -> #REF! | N24: =Pintura!#REF! -> #REF! | O24: =N24/E24 -> #REF! | P24: =+N24*F24 -> #REF! | Q24: =H24+K24+N24 -> #REF! | R24: =Q24/E24 -> #REF! | S24: =+Q24*F24 -> #REF!
B25: 3.1.4 | C25: Pintura Tipo Koraza Proteccion Sol y Lluvia Impermeabilizante sobre lamina tipo siding (color madera cedro) | D25: M2 | E25: 565.54 | F25: 17500 | G25: =F25*E25 -> 9896950 | H25: 72.512336 | I25: =+H25/E25 -> 0.12821787 | J25: =+F25*H25 -> 1268965.9 | K25: =Pintura!#REF! -> #REF! | L25: =K25/E25 -> #REF! | M25: =+K25*F25 -> #REF! | N25: =Pintura!#REF! -> #REF! | O25: =N25/E25 -> #REF! | P25: =+N25*F25 -> #REF! | Q25: =H25+K25+N25 -> #REF! | R25: =Q25/E25 -> #REF! | S25: =+Q25*F25 -> #REF!
B26: 3.1.5 | C26: Pintura gris basalto koraza (parqueaderos) | D26: M2 | E26: 161.75 | F26: 17500 | G26: =F26*E26 -> 2830625 | H26: 0 | I26: =+H26/E26 -> 0 | J26: =+F26*H26 -> 0 | K26: 0 | L26: =K26/E26 -> 0 | M26: =+K26*F26 -> 0 | N26: 0 | O26: =N26/E26 -> 0 | P26: =+N26*F26 -> 0 | Q26: =H26+K26+N26 -> 0 | R26: =Q26/E26 -> 0 | S26: =+Q26*F26 -> 0
B27: 3.1.6 | C27: Pintura sobre alfajías Tipo Koraza Proteccion Sol y Lluvia Impermeabilizante | D27: ML | E27: 532.35 | F27: 7400 | G27: =F27*E27 -> 3939390 | H27: 122.82 | I27: =+H27/E27 -> 0.23071288 | J27: =+F27*H27 -> 908868 | K27: =Pintura!#REF! -> #REF! | L27: =K27/E27 -> #REF! | M27: =+K27*F27 -> #REF! | N27: =Pintura!#REF! -> #REF! | O27: =N27/E27 -> #REF! | P27: =+N27*F27 -> #REF! | Q27: =H27+K27+N27 -> #REF! | R27: =Q27/E27 -> #REF! | S27: =+Q27*F27 -> #REF!
B28: 3.2 | C28: Pintura Tipo Pintulux 3 en 1 sobre Elementos Metalicos | G28: =+SUM(G29:G30) -> 8043387 | J28: =+SUM(J29:J30) -> 0 | M28: =+SUM(M29:M30) -> 0 | P28: =+SUM(P29:P30) -> 0 | S28: =+SUM(S29:S30) -> 0
B29: 3.2.1 | C29: Pintura Pintulux 3 en 1 (carpinteria metalica parqueaderos) | D29: M2 | E29: 245.69 | F29: 22300 | G29: =F29*E29 -> 5478887 | H29: 0 | I29: =+H29/E29 -> 0 | J29: =+F29*H29 -> 0 | K29: 0 | L29: =K29/E29 -> 0 | M29: =+K29*F29 -> 0 | N29: 0 | O29: =N29/E29 -> 0 | P29: =+N29*F29 -> 0 | Q29: =H29+K29+N29 -> 0 | R29: =Q29/E29 -> 0 | S29: =+Q29*F29 -> 0
B30: 3.2.2 | C30: Pintura Pintulux 3 en 1 en carpinteria metalica de soporte y de guia de teja translucida | D30: M2 | E30: 115 | F30: 22300 | G30: =F30*E30 -> 2564500 | H30: 0 | I30: =+H30/E30 -> 0 | J30: =+F30*H30 -> 0 | K30: 0 | L30: =K30/E30 -> 0 | M30: =+K30*F30 -> 0 | N30: 0 | O30: =N30/E30 -> 0 | P30: =+N30*F30 -> 0 | Q30: =H30+K30+N30 -> 0 | R30: =Q30/E30 -> 0 | S30: =+Q30*F30 -> 0
B31: 3.3 | C31: Pintura Tipo Viniltex Advanced de Pintuco en Interiores | G31: =+SUM(G32:G33) -> 44028480 | J31: =+SUM(J32:J33) -> 17480640 | M31: =+SUM(M32:M33) -> 8169600 | P31: =+SUM(P32:P33) -> 0 | S31: =+SUM(S32:S33) -> 25650240
B32: 3.3.1 | C32: Pintura para Muros Interiores tipo 1 viniltex advanced de pintuco color blanco | D32: M2 | E32: 2640.6 | F32: 12000 | G32: =F32*E32 -> 31687200 | H32: 874.032 | I32: =+H32/E32 -> 0.3309975 | J32: =+F32*H32 -> 10488384 | K32: 680.8 | L32: =K32/E32 -> 0.25782019 | M32: =+K32*F32 -> 8169600 | N32: 0 | O32: =N32/E32 -> 0 | P32: =+N32*F32 -> 0 | Q32: =H32+K32+N32 -> 1554.832 | R32: =Q32/E32 -> 0.58881769 | S32: =+Q32*F32 -> 18657984
B33: 3.3.2 | C33: Pintura para Cielorrasos Interiores Tipo Viniltex Advanced de Pintuco Color Blanco | D33: M2 | E33: 1028.44 | F33: 12000 | G33: =F33*E33 -> 12341280 | H33: 582.688 | I33: =+H33/E33 -> 0.56657462 | J33: =+F33*H33 -> 6992256 | K33: 0 | L33: =K33/E33 -> 0 | M33: =+K33*F33 -> 0 | N33: 0 | O33: =N33/E33 -> 0 | P33: =+N33*F33 -> 0 | Q33: =H33+K33+N33 -> 582.688 | R33: =Q33/E33 -> 0.56657462 | S33: =+Q33*F33 -> 6992256
A34: 4 | C34: CARPINTERIA EN ALUMINIO y Vidrio | G34: =+SUM(G35:G37) -> 13115377 | J34: =+SUM(J35:J37) -> 1869038 | M34: =+SUM(M35:M37) -> #REF! | P34: =+SUM(P35:P37) -> #REF! | S34: =+SUM(S35:S37) -> #REF!
B35: 4.1 | C35: Resellado Perimetral de Elementos Vidriados en Fachada | D35: ML | E35: 1610.82 | F35: 5700 | G35: =F35*E35 -> 9181674 | H35: 214.4 | I35: =+H35/E35 -> 0.13309991 | J35: =+F35*H35 -> 1222080 | K35: =Sellos!#REF! -> #REF! | L35: =K35/E35 -> #REF! | M35: =+K35*F35 -> #REF! | N35: =Sellos!#REF! -> #REF! | O35: =N35/E35 -> #REF! | P35: =+N35*F35 -> #REF! | Q35: =H35+K35+N35 -> #REF! | R35: =Q35/E35 -> #REF! | S35: =+Q35*F35 -> #REF!
B36: 4.2 | C36: Desmonte y vuelta a instalar de vidrio templado de cerramiento en terraza y Jacuzzi | D36: M2 | E36: 86.09 | F36: 16700 | G36: =F36*E36 -> 1437703 | H36: 38.74 | I36: =+H36/E36 -> 0.44999419 | J36: =+F36*H36 -> 646958 | K36: 0 | L36: =K36/E36 -> 0 | M36: =+K36*F36 -> 0 | N36: 0 | O36: =N36/E36 -> 0 | P36: =+N36*F36 -> 0 | Q36: =H36+K36+N36 -> 38.74 | R36: =Q36/E36 -> 0.44999419 | S36: =+Q36*F36 -> 646958
B37: 4.3 | C37: Suministro e instalación de cortagoteras en aluminio | D37: ML | E37: 48 | F37: 52000 | G37: =F37*E37 -> 2496000 | H37: 0 | I37: =+H37/E37 -> 0 | J37: =+F37*H37 -> 0 | K37: 0 | L37: =K37/E37 -> 0 | M37: =+K37*F37 -> 0 | N37: 0 | O37: =N37/E37 -> 0 | P37: =+N37*F37 -> 0 | Q37: =H37+K37+N37 -> 0 | R37: =Q37/E37 -> 0 | S37: =+Q37*F37 -> 0
A38: 5 | C38: VARIOS | G38: =++G39+G40 -> 5450000 | J38: =++J39+J40 -> 0 | M38: =++M39+M40 -> 0 | P38: =++P39+P40 -> 0 | S38: =++S39+S40 -> 0
B39: 5.1 | C39: Media caña en concreto incluye impermeabilizado | D39: ML | E39: 30 | F39: 55000 | G39: =F39*E39 -> 1650000 | H39: 0 | I39: =+H39/E39 -> 0 | J39: =+F39*H39 -> 0 | K39: 0 | L39: =K39/E39 -> 0 | M39: =+K39*F39 -> 0 | N39: 0 | O39: =N39/E39 -> 0 | P39: =+N39*F39 -> 0 | Q39: =H39+K39+N39 -> 0 | R39: =Q39/E39 -> 0 | S39: =+Q39*F39 -> 0
B40: 5.2 | C40: Acondicionamiento de Acceso a Terraza | D40: Gl | E40: 1 | F40: 3800000 | G40: =F40*E40 -> 3800000 | H40: 0 | I40: =+H40/E40 -> 0 | J40: =+F40*H40 -> 0 | K40: 0 | L40: =K40/E40 -> 0 | M40: =+K40*F40 -> 0 | N40: 0 | O40: =N40/E40 -> 0 | P40: =+N40*F40 -> 0 | Q40: =H40+K40+N40 -> 0 | R40: =Q40/E40 -> 0 | S40: =+Q40*F40 -> 0
...

Sheet Estado de la Obra
A6: Estado de obra - Actividades ejecutadas | D6: Semana # | E6: 14 | F6: 45677
A7: Edificio Panoramika
B9: Descripción | C9: UM | D9: Cantidad | E9: Cantidas Ejecutada | F9: Cantidad Restante | G9: Porcentaje restante | H9: %
B11: Lavado de superficie de fachada | C11: M2 | D11: 4506.28 | E11: =Lavado!S69 -> 2241.83 | F11: =D11-E11 -> 2264.45 | G11: =1-(E11/D11) -> 0.50250983 | H11: =E11/D11 -> 0.49749017 | I11: 0.15 | J11: =H11*I11 -> 0.074623525 | L11: =I11+I17+I15+I19 -> 0.65
B13: Aplicación de sicoplast en superficie de fachada | C13: M2 | D13: =441.8865*0.35 -> 154.66027 | E13: =Sicoplast!Y36+45 -> 45 | F13: =D13-E13 -> 109.66027 | G13: =1-(E13/D13) -> 0.7090397 | H13: =E13/D13 -> 0.2909603 | I13: 0.075 | J13: =H13*I13 -> 0.021822022 | L13: =I21 -> 0.15
B15: Aplicación de sello en ventanas, volumenes y dilataciones | C15: M2 | D15: =1610.82*0.6 -> 966.492 | E15: =Sellos!#REF!+Sellos!#REF! -> #REF! | F15: =D15-E15 -> #REF! | G15: =1-(E15/D15) -> #REF! | H15: =E15/D15 -> #REF! | I15: 0.1 | J15: =H15*I15 -> #REF! | L15: =L11+L13 -> 0.8
B17: Aplicación de pintura en superficie de fachada | C17: Und | D17: 3673.2 | E17: =Pintura!#REF! -> #REF! | F17: =D17-E17 -> #REF! | G17: =1-(E17/D17) -> #REF! | H17: =E17/D17 -> #REF! | I17: 0.3 | J17: =H17*I17 -> #REF!
B19: Aplicación de pintura en alfajías | C19: ML | D19: 532.35 | E19: =Pintura!#REF! -> #REF! | F19: =D19-E19 -> #REF! | G19: =1-(E19/D19) -> #REF! | H19: =E19/D19 -> #REF! | I19: 0.1 | J19: =H19*I19 -> #REF!
B21: Aplicación de pintura en pasillos | C21: M2 | D21: 3669.04 | E21: =Pasillos!S22 -> 476.84 | F21: =D21-E21 -> 3192.2 | G21: =1-(E21/D21) -> 0.87003685 | H21: =E21/D21 -> 0.12996315 | I21: 0.15 | J21: =H21*I21 -> 0.019494473
B23: Puntos de anclaje | C23: UND | D23: 28 | E23: 20 | F23: =D23-E23 -> 8 | G23: =1-(E23/D23) -> 0.28571429 | H23: =E23/D23 -> 0.71428571 | I23: 0.025 | J23: =H23*I23 -> 0.017857143
B25: Mantenimiento de cubiertas | C25: GLB | D25: 1 | E25: 0 | F25: =D25-E25 -> 1 | G25: =1-(E25/D25) -> 1 | H25: =E25/D25 -> 0 | I25: 0.1 | J25: =H25*I25 -> 0
B27: Estado General de la Obra | C27: GLB | D27: 1 | E27: =J27 -> #REF! | F27: =D27-E27 -> #REF! | G27: =1-(E27/D27) -> #REF! | H27: =E27/D27 -> #REF! | I27: =SUM(I11:I26) -> 1 | J27: =SUM(J11:J26) -> #REF!
B29: Plantilla | C29: UND | D29: 1 | E29: 1 | F29: =D29-E29 -> 0 | G29: 1 | H29: =E29/D29 -> 1

Sheet CO
A2: EDIFICIO PANORAMIKA
E3: DIMENSIONES | H3: DESCUENTOS
A4: FACHADA | B4: SECCIÓN | C4: PISO | D4: DESCRIPCIÓN | E4: ALTO | F4: ANCHO | G4: TOTAL (M2) | H4: ALTO | I4: ANCHO | J4: CANTIDAD | K4: TOTAL (M2) | L4: CARTERAS (ML) | M4: DILATACIÓN (ML) | N4: ÁREA TOTAL (BLANCA) | O4: ÁREA TOTAL (GRIS) | P4: ÁREA TOTAL (SIGIND) | Q4: ÁREA TOTAL (NEGRO) | R4: ÁREA TOTAL
A5: SUR | B5: 1 | C5: 10 | D5: Muro Blanco doble altura | E5: 6.2 | F5: 21.71 | G5: =E5*F5 -> 134.602 | H5: 4.02 | J5: 2 | K5: =(H5)*J5 -> 8.04 | N5: =G5-(K5+K6+K7+K8+K9) -> 112.852 | R5: =SUM(N5:Q5) -> 112.852
H6: 5.88 | J6: 1 | K6: =(H6)*J6 -> 5.88
H7: 2.16 | J7: 2 | K7: =(H7)*J7 -> 4.32
H8: 2.15 | J8: 1 | K8: =(H8)*J8 -> 2.15
H9: 1.36 | J9: 1 | K9: =(H9)*J9 -> 1.36
C10: 9 | D10: Muro gris | G10: 6.88 | O10: =G10 -> 6.88 | R10: =SUM(N10:Q10) -> 6.88
C11: 8 | D11: Lámina siding | G11: 12.6 | K11: 8.1 | N11: =G11-K11 -> 4.5 | R11: =SUM(N11:Q11) -> 4.5
C12: 7 | D12: Muro gris | G12: 6.88 | O12: =G12 -> 6.88 | R12: =SUM(N12:Q12) -> 6.88
C13: 6 | D13: Muro blanco | G13: 12.6 | P13: =G13 -> 12.6 | R13: =SUM(N13:Q13) -> 12.6
C14: 5 | D14: Muro gris | G14: 6.88 | O14: =G14 -> 6.88 | R14: =SUM(N14:Q14) -> 6.88
C15: 4 | D15: Muro blanco | G15: 12.6 | N15: =G15 -> 12.6 | R15: =SUM(N15:Q15) -> 12.6
C16: 3 | D16: Muro gris | G16: 6.88 | O16: =G16 -> 6.88 | R16: =SUM(N16:Q16) -> 6.88
C17: 2 | D17: Muro blanco | G17: 12.6 | N17: =G17 -> 12.6 | R17: =SUM(N17:Q17) -> 12.6
C18: 1 | D18: Muro blanco | G18: 7.5 | N18: =G18 -> 7.5 | R18: =SUM(N18:Q18) -> 7.5
B19: 2 | C19: 9 | D19: Muro blanco | G19: 26.97 | K19: 10.5 | N19: =G19-K19 -> 16.47 | R19: =SUM(N19:Q19) -> 16.47
C20: 8 | D20: Muro balcón blanco | G20: 6.87 | N20: =G20-K20 -> 6.87 | R20: =SUM(N20:Q20) -> 6.87
C21: 7 | D21: Lámina siding | G21: 26.97 | K21: 10.5 | P21: =G21-K21 -> 16.47 | R21: =SUM(N21:Q21) -> 16.47
C22: 6 | D22: Muro balcón blanco | G22: 6.87 | N22: =G22-K22 -> 6.87 | R22: =SUM(N22:Q22) -> 6.87
C23: 5 | D23: Muro blanco | G23: 26.97 | K23: 10.5 | N23: =G23-K23 -> 16.47 | R23: =SUM(N23:Q23) -> 16.47
C24: 4 | D24: Muro balcón blanco | G24: 6.87 | N24: =G24-K24 -> 6.87 | R24: =SUM(N24:Q24) -> 6.87
C25: 3 | D25: Muro blanco | G25: 26.97 | K25: 10.5 | N25: =G25-K25 -> 16.47 | R25: =SUM(N25:Q25) -> 16.47
C26: 2 | D26: Muro balcón blanco | G26: 6.87 | N26: =G26-K26 -> 6.87 | R26: =SUM(N26:Q26) -> 6.87
C27: 1 | D27: Muro blanco | G27: 26.97 | K27: 10.5 | N27: =G27-K27 -> 16.47 | R27: =SUM(N27:Q27) -> 16.47
B28: 3 | C28: 9 | D28: Muro gris | G28: 3.85 | M28: =F28*10 -> 0 | O28: =G28-K28 -> 3.85 | R28: =SUM(N28:Q28) -> 3.85
D29: Volumen blanco | G29: 65.71 | K29: 29 | N29: =G29-K29 -> 36.71 | R29: =SUM(N29:Q29) -> 36.71
D30: Muro gris | G30: 2.4 | O30: =G30-K30 -> 2.4 | R30: =SUM(N30:Q30) -> 2.4
C31: 8 | D31: Muros grises | G31: 5 | O31: =G31 -> 5 | R31: =SUM(N31:Q31) -> 5
C32: 7 | D32: Lámina siding | G32: 3.85 | M32: =F32*10 -> 0 | P32: =G32-K32 -> 3.85 | R32: =SUM(N32:Q32) -> 3.85
D33: Volumen siding | G33: 65.71 | K33: 29 | P33: =G33-K33 -> 36.71 | R33: =SUM(N33:Q33) -> 36.71
D34: Muro internos balcón siding | E34: 2.55 | F34: 2 | G34: =E34*F34 -> 5.1 | P34: =G34-K34 -> 5.1 | R34: =SUM(N34:Q34) -> 5.1
D35: Muro gris | G35: 2.4 | O35: =G35-K35 -> 2.4 | R35: =SUM(N35:Q35) -> 2.4
D36: Muro internos balcón gris | E36: 2.55 | F36: 2 | G36: =E36*F36 -> 5.1 | O36: =G36-K36 -> 5.1 | R36: =SUM(N36:Q36) -> 5.1
C37: 6 | D37: Muros grises | G37: 5 | O37: =G37 -> 5 | R37: =SUM(N37:Q37) -> 5
C38: 5 | D38: Muro gris | G38: 3.85 | M38: =F38*10 -> 0 | O38: =G38-K38 -> 3.85 | R38: =SUM(N38:Q38) -> 3.85
D39: Volumen blanco | G39: 65.71 | K39: 29 | N39: =G39-K39 -> 36.71 | R39: =SUM(N39:Q39) -> 36.71
D40: Muro internos balcón blanco | E40: 2.55 | F40: 2 | G40: =E40*F40 -> 5.1 | P40: =G40-K40 -> 5.1 | R40: =SUM(N40:Q40) -> 5.1
D41: Muro gris | G41: 2.4 | O41: =G41-K41 -> 2.4 | R41: =SUM(N41:Q41) -> 2.4
...

Sheet CO SIF
A1: 45969
A2: EDIFICIO PANORAMIKA | F2: 1.03 | G2: =F152 -> 3.82663
A4: FACHADA | B4: SECCIÓN | C4: PISO | D4: DESCRIPCIÓN | E4: ÁREA TOTAL
D5: FACHADA OESTE
A6: SUR | B6: 1 | C6: 10 | D6: Muro Blanco doble altura | E6: =CO!R5 -> 112.852 | F6: =E6*$F$2 -> 116.23756
C7: 8 | D7: Lámina siding | E7: 12.6 | F7: =E7*$F$2 -> 12.978
C8: 6 | D8: Muro blanco | E8: =CO!R13 -> 12.6 | F8: =E8*$F$2 -> 12.978
C9: 4 | D9: Muro blanco | E9: =CO!R15 -> 12.6 | F9: =E9*$F$2 -> 12.978
C10: 2 | D10: Muro blanco | E10: =CO!R17 -> 12.6 | F10: =E10*$F$2 -> 12.978
C11: 1 | D11: Muro blanco | E11: =CO!R18 -> 7.5 | F11: =E11*$F$2 -> 7.725
B12: 2 | C12: 9 | D12: Muro blanco | E12: =CO!R19 -> 16.47 | F12: =E12*$F$2 -> 16.9641
C13: 8 | D13: Muro balcón blanco | E13: =CO!R20 -> 6.87 | F13: =E13*$F$2 -> 7.0761
C14: 7 | D14: Lámina siding | E14: =CO!R21 -> 16.47 | F14: =E14*$F$2 -> 16.9641
C15: 6 | D15: Muro balcón blanco | E15: =CO!R22 -> 6.87 | F15: =E15*$F$2 -> 7.0761
C16: 5 | D16: Muro blanco | E16: =CO!R23 -> 16.47 | F16: =E16*$F$2 -> 16.9641
C17: 4 | D17: Muro balcón blanco | E17: =CO!R24 -> 6.87 | F17: =E17*$F$2 -> 7.0761
C18: 3 | D18: Muro blanco | E18: =CO!R25 -> 16.47 | F18: =E18*$F$2 -> 16.9641
C19: 2 | D19: Muro balcón blanco | E19: =CO!R26 -> 6.87 | F19: =E19*$F$2 -> 7.0761
C20: 1 | D20: Muro blanco | E20: =CO!R27 -> 16.47 | F20: =E20*$F$2 -> 16.9641
B21: 3 | C21: 9 | D21: Muro gris | E21: 6.25 | F21: =E21*$F$2 -> 6.4375
D22: Volumen blanco | E22: =CO!R29 -> 36.71 | F22: =E22*$F$2 -> 37.8113
C23: 8 | D23: Muros grises | E23: =CO!R31 -> 5 | F23: =E23*$F$2 -> 5.15
C24: 7 | D24: Lámina siding | E24: 45.66 | F24: =E24*$F$2 -> 47.0298
D25: Muros gris | E25: 7.5 | F25: =E25*$F$2 -> 7.725
C26: 6 | D26: Muros grises | E26: =CO!R34 -> 5.1 | F26: =E26*$F$2 -> 5.253
C27: 5 | D27: Muro blanco | E27: 45.66 | F27: =E27*$F$2 -> 47.0298
D28: Muros gris | E28: 7.5 | F28: =E28*$F$2 -> 7.725
C29: 4 | D29: Muros grises | E29: =CO!R37 -> 5 | F29: =E29*$F$2 -> 5.15
C30: 3 | D30: Muro blanco | E30: 45.66 | F30: =E30*$F$2 -> 47.0298
D31: Muros gris | E31: 7.5 | F31: =E31*$F$2 -> 7.725
C32: 2 | D32: Muros grises | E32: =CO!R49 -> 5 | F32: =E32*$F$2 -> 5.15
C33: 1 | D33: Muro blanco | E33: 45.66 | F33: =E33*$F$2 -> 47.0298
D34: Muros gris | E34: 7.5 | F34: =E34*$F$2 -> 7.725
C35: Sotanos | D35: Muro negro | E35: =CO!R54 -> 34 | F35: =E35*$F$2 -> 35.02
B36: 4 | C36: 9 | D36: Muro blanco | E36: 30.93 | F36: =E36*$F$2 -> 31.8579
C37: 8 | D37: Muro gris | E37: =CO!R57 -> 5.62 | F37: =E37*$F$2 -> 5.7886
C38: 7 | D38: Lámina siding | E38: 30.93 | F38: =E38*$F$2 -> 31.8579
C39: 6 | D39: Muro gris | E39: =CO!R60 -> 5.62 | F39: =E39*$F$2 -> 5.7886
C40: 5 | D40: Muro blanco | E40: 30.93 | F40: =E40*$F$2 -> 31.8579
C41: 4 | D41: Muro gris | E41: =CO!R63 -> 5.62 | F41: =E41*$F$2 -> 5.7886
...

Sheet CO SIF 2
A1: 45969
A2: EDIFICIO PANORAMIKA | F2: 1.03 | H2: EDIFICIO PANORAMIKA | L2: 1.03
F3: =F152 -> 3.82663
A4: FACHADA | B4: SECCIÓN | C4: PISO | D4: DESCRIPCIÓN | E4: ÁREA TOTAL | H4: FACHADA | I4: SECCIÓN | J4: DESCRIPCIÓN | K4: ÁREA TOTAL
D5: FACHADA OESTE | J5: FACHADA OESTE
A6: SUR | B6: 1 | C6: 10 | D6: Muro Blanco doble altura | E6: =CO!R5 -> 112.852 | F6: =E6*$F$2 -> 116.23756 | G6: =SUM(F6:F11) -> 175.87456 | H6: SUR | I6: 1 | J6: Muro Blanco doble altura | K6: =E6 -> 112.852 | L6: =K6*$F$2 -> 116.23756 | M6: =SUM(L6:L8) -> 175.87456
C7: 8 | D7: Lámina siding | E7: 12.6 | F7: =E7*$F$2 -> 12.978 | J7: Lámina siding | K7: 12.6 | L7: =K7*$F$2 -> 12.978
C8: 6 | D8: Muro blanco | E8: =CO!R13 -> 12.6 | F8: =E8*$F$2 -> 12.978 | J8: Muro blanco | K8: =SUM(E8:E11) -> 45.3 | L8: =K8*$F$2 -> 46.659
C9: 4 | D9: Muro blanco | E9: =CO!R15 -> 12.6 | F9: =E9*$F$2 -> 12.978
C10: 2 | D10: Muro blanco | E10: =CO!R17 -> 12.6 | F10: =E10*$F$2 -> 12.978
C11: 1 | D11: Muro blanco | E11: =CO!R18 -> 7.5 | F11: =E11*$F$2 -> 7.725
B12: 2 | C12: 9 | D12: Muro blanco | E12: =CO!R19 -> 16.47 | F12: =E12*$F$2 -> 16.9641 | G12: =SUM(F12:F20) -> 113.1249 | I12: 2 | J12: Muro blanco | K12: =E12+E16+E18+E20 -> 65.88 | L12: =K12*$F$2 -> 67.8564 | M12: =SUM(L12:L14) -> 113.1249
C13: 8 | D13: Muro balcón blanco | E13: =CO!R20 -> 6.87 | F13: =E13*$F$2 -> 7.0761 | J13: Muro balcón blanco | K13: =E13+E15+E17+E19 -> 27.48 | L13: =K13*$F$2 -> 28.3044
C14: 7 | D14: Lámina siding | E14: =CO!R21 -> 16.47 | F14: =E14*$F$2 -> 16.9641 | J14: Lámina siding | K14: =E14 -> 16.47 | L14: =K14*$F$2 -> 16.9641
C15: 6 | D15: Muro balcón blanco | E15: =CO!R22 -> 6.87 | F15: =E15*$F$2 -> 7.0761
C16: 5 | D16: Muro blanco | E16: =CO!R23 -> 16.47 | F16: =E16*$F$2 -> 16.9641
C17: 4 | D17: Muro balcón blanco | E17: =CO!R24 -> 6.87 | F17: =E17*$F$2 -> 7.0761
C18: 3 | D18: Muro blanco | E18: =CO!R25 -> 16.47 | F18: =E18*$F$2 -> 16.9641
C19: 2 | D19: Muro balcón blanco | E19: =CO!R26 -> 6.87 | F19: =E19*$F$2 -> 7.0761
C20: 1 | D20: Muro blanco | E20: =CO!R27 -> 16.47 | F20: =E20*$F$2 -> 16.9641
B21: 3 | C21: 9 | D21: Muro gris | E21: 6.25 | F21: =E21*$F$2 -> 6.4375 | G21: =SUM(F21:F35) -> 318.991 | I21: 3 | J21: Muro gris | K21: =E21+E23+E25+E28+E29+E31+E32+E34+E26 -> 56.35 | L21: =K21*$F$2 -> 58.0405 | M21: =SUM(L21:L24) -> 318.991
D22: Volumen blanco | E22: =CO!R29 -> 36.71 | F22: =E22*$F$2 -> 37.8113 | J22: Volumen blanco | K22: =E22++E27+E30+E33 -> 173.69 | L22: =K22*$F$2 -> 178.9007
C23: 8 | D23: Muros grises | E23: =CO!R31 -> 5 | F23: =E23*$F$2 -> 5.15 | J23: Lámina siding | K23: =E24 -> 45.66 | L23: =K23*$F$2 -> 47.0298
C24: 7 | D24: Lámina siding | E24: 45.66 | F24: =E24*$F$2 -> 47.0298 | J24: Muro negro | K24: =E35 -> 34 | L24: =K24*$F$2 -> 35.02
D25: Muros gris | E25: 7.5 | F25: =E25*$F$2 -> 7.725
C26: 6 | D26: Muros grises | E26: =CO!R34 -> 5.1 | F26: =E26*$F$2 -> 5.253
C27: 5 | D27: Muro blanco | E27: 45.66 | F27: =E27*$F$2 -> 47.0298
D28: Muros gris | E28: 7.5 | F28: =E28*$F$2 -> 7.725
C29: 4 | D29: Muros grises | E29: =CO!R37 -> 5 | F29: =E29*$F$2 -> 5.15
C30: 3 | D30: Muro blanco | E30: 45.66 | F30: =E30*$F$2 -> 47.0298
D31: Muros gris | E31: 7.5 | F31: =E31*$F$2 -> 7.725
C32: 2 | D32: Muros grises | E32: =CO!R49 -> 5 | F32: =E32*$F$2 -> 5.15
C33: 1 | D33: Muro blanco | E33: 45.66 | F33: =E33*$F$2 -> 47.0298
D34: Muros gris | E34: 7.5 | F34: =E34*$F$2 -> 7.725
C35: Sotanos | D35: Muro negro | E35: =CO!R54 -> 34 | F35: =E35*$F$2 -> 35.02
B36: 4 | C36: 9 | D36: Muro blanco | E36: 30.93 | F36: =E36*$F$2 -> 31.8579 | G36: =SUM(F36:F46) -> 308.0833 | I36: 4 | J36: Muro blanco | K36: =E36+E40+E42+E44 -> 123.72 | L36: =K36*$F$2 -> 127.4316 | M36: =SUM(L36:L40) -> 308.0833
C37: 8 | D37: Muro gris | E37: =CO!R57 -> 5.62 | F37: =E37*$F$2 -> 5.7886 | J37: Muro gris | K37: =E37+E39+E41+E43 -> 22.48 | L37: =K37*$F$2 -> 23.1544
C38: 7 | D38: Lámina siding | E38: 30.93 | F38: =E38*$F$2 -> 31.8579 | J38: Lámina siding | K38: =E38 -> 30.93 | L38: =K38*$F$2 -> 31.8579
C39: 6 | D39: Muro gris | E39: =CO!R60 -> 5.62 | F39: =E39*$F$2 -> 5.7886 | J39: Muro negro | K39: =E45 -> 42.78 | L39: =K39*$F$2 -> 44.0634
C40: 5 | D40: Muro blanco | E40: 30.93 | F40: =E40*$F$2 -> 31.8579 | J40: Cieloraso en fachada | K40: =17.6*4.5 -> 79.2 | L40: =K40*$F$2 -> 81.576
...

Sheet Lavado
A1: CEDROS - LAVADO DE FACHADA
E2: ENE 15 - 17 | G2: ENE 19 - 24 | I2: ENE 26 - 31 | K2: FEB 02-07 | M2: FEB 09-14 | O2: FEB 16 - 21 | Q2: FEB 23 - 28
A3: Fachada | B3: Sección | C3: Descripción | D3: M2 | E3: Semana 01 | G3: Semana 02 | I3: Semana 03 | K3: Semana 04 | M3: Semana 05 | O3: Semana 06 | Q3: Semana 07 | S3: Total Ejecutado | U3: Total Ejecutado Acta 01
E4: M2 | F4: % | G4: M2 | H4: % | I4: M2 | J4: % | K4: M2 | L4: % | M4: M2 | N4: % | O4: M2 | P4: % | Q4: M2 | R4: % | S4: M2 | T4: % | U4: M2 | V4: %
A5: A | B5: 1 | C5: Lavado de fachada | D5: 68.2 | E5: =D5*F5 -> 0 | F5: 0 | G5: =D5*H5 -> 0 | H5: 0 | I5: =D5*J5 -> 0 | J5: 0 | K5: =D5*L5 -> 0 | L5: 0 | M5: =N5*D5 -> 0 | N5: 0 | O5: =P5*D5 -> 68.2 | P5: 1 | Q5: =R5*D5 -> 0 | R5: 0 | S5: =E5+G5+I5+K5+M5+O5+Q5 -> 68.2 | T5: =S5/D5 -> 1 | U5: =E5+G5+I5+K5+M5 -> 0 | V5: =U5/D5 -> 0
C6: Lavado de vidrios | D6: 6 | E6: =D6*F6 -> 0 | F6: 0 | G6: =D6*H6 -> 0 | H6: 0 | I6: =D6*J6 -> 0 | J6: 0 | K6: =D6*L6 -> 0 | L6: 0 | M6: =N6*D6 -> 0 | N6: 0 | O6: =P6*D6 -> 6 | P6: 1 | Q6: =R6*D6 -> 0 | R6: 0 | S6: =E6+G6+I6+K6+M6+O6+Q6 -> 6 | T6: =S6/D6 -> 1 | U6: =E6+G6+I6+K6+M6 -> 0 | V6: =U6/D6 -> 0
B7: 2 | C7: Lavado de fachada | D7: 33.8 | E7: =D7*F7 -> 0 | F7: 0 | G7: =D7*H7 -> 0 | H7: 0 | I7: =D7*J7 -> 0 | J7: 0 | K7: =D7*L7 -> 0 | L7: 0 | M7: =N7*D7 -> 0 | N7: 0 | O7: =P7*D7 -> 33.8 | P7: 1 | Q7: =R7*D7 -> 0 | R7: 0 | S7: =E7+G7+I7+K7+M7+O7+Q7 -> 33.8 | T7: =S7/D7 -> 1 | U7: =E7+G7+I7+K7+M7 -> 0 | V7: =U7/D7 -> 0
C8: Lavado de vidrios | D8: 8.64 | E8: =D8*F8 -> 0 | F8: 0 | G8: =D8*H8 -> 0 | H8: 0 | I8: =D8*J8 -> 0 | J8: 0 | K8: =D8*L8 -> 0 | L8: 0 | M8: =N8*D8 -> 0 | N8: 0 | O8: =P8*D8 -> 0 | P8: 0 | Q8: =R8*D8 -> 8.64 | R8: 1 | S8: =E8+G8+I8+K8+M8+O8+Q8 -> 8.64 | T8: =S8/D8 -> 1 | U8: =E8+G8+I8+K8+M8 -> 0 | V8: =U8/D8 -> 0
B9: 3 | C9: Lavado de fachada | D9: 60.9 | E9: =D9*F9 -> 0 | F9: 0 | G9: =D9*H9 -> 0 | H9: 0 | I9: =D9*J9 -> 45.675 | J9: 0.75 | K9: =D9*L9 -> 60.9 | L9: 1 | M9: =N9*D9 -> 0 | N9: 0 | O9: =P9*D9 -> 0 | P9: 0 | Q9: =R9*D9 -> 0 | R9: 0 | S9: =E9+G9+I9+K9+M9+O9+Q9 -> 106.575 | T9: =S9/D9 -> 1.75 | U9: =E9+G9+I9+K9+M9 -> 106.575 | V9: =U9/D9 -> 1.75
C10: Lavado de vidrios | D10: 1 | E10: =D10*F10 -> 0 | F10: 0 | G10: =D10*H10 -> 0 | H10: 0 | I10: =D10*J10 -> 1 | J10: 1 | K10: =D10*L10 -> 0 | L10: 0 | M10: =N10*D10 -> 0 | N10: 0 | O10: =P10*D10 -> 0 | P10: 0 | Q10: =R10*D10 -> 0 | R10: 0 | S10: =E10+G10+I10+K10+M10+O10+Q10 -> 1 | T10: =S10/D10 -> 1 | U10: =E10+G10+I10+K10+M10 -> 1 | V10: =U10/D10 -> 1
B11: 4 | C11: Lavado de fachada | D11: 33.8 | E11: =D11*F11 -> 0 | F11: 0 | G11: =D11*H11 -> 16.9 | H11: 0.5 | I11: =D11*J11 -> 16.9 | J11: 0.5 | K11: =D11*L11 -> 33.8 | L11: 1 | M11: =N11*D11 -> 0 | N11: 0 | O11: =P11*D11 -> 0 | P11: 0 | Q11: =R11*D11 -> 0 | R11: 0 | S11: =E11+G11+I11+K11+M11+O11+Q11 -> 67.6 | T11: =S11/D11 -> 2 | U11: =E11+G11+I11+K11+M11 -> 67.6 | V11: =U11/D11 -> 2
C12: Lavado de vidrios | D12: 8.64 | E12: =D12*F12 -> 0 | F12: 0 | G12: =D12*H12 -> 4.32 | H12: 0.5 | I12: =D12*J12 -> 4.32 | J12: 0.5 | K12: =D12*L12 -> 0 | L12: 0 | M12: =N12*D12 -> 0 | N12: 0 | O12: =P12*D12 -> 0 | P12: 0 | Q12: =R12*D12 -> 0 | R12: 0 | S12: =E12+G12+I12+K12+M12+O12+Q12 -> 8.64 | T12: =S12/D12 -> 1 | U12: =E12+G12+I12+K12+M12 -> 8.64 | V12: =U12/D12 -> 1
B13: 5 | C13: Lavado de fachada | D13: 106.45 | E13: =D13*F13 -> 0 | F13: 0 | G13: =D13*H13 -> 106.45 | H13: 1 | I13: =D13*J13 -> 0 | J13: 0 | K13: =D13*L13 -> 106.45 | L13: 1 | M13: =N13*D13 -> 0 | N13: 0 | O13: =P13*D13 -> 0 | P13: 0 | Q13: =R13*D13 -> 0 | R13: 0 | S13: =E13+G13+I13+K13+M13+O13+Q13 -> 212.9 | T13: =S13/D13 -> 2 | U13: =E13+G13+I13+K13+M13 -> 212.9 | V13: =U13/D13 -> 2
C14: Lavado de vidrios | D14: 6 | E14: =D14*F14 -> 0 | F14: 0 | G14: =D14*H14 -> 6 | H14: 1 | I14: =D14*J14 -> 0 | J14: 0 | K14: =D14*L14 -> 0 | L14: 0 | M14: =N14*D14 -> 0 | N14: 0 | O14: =P14*D14 -> 0 | P14: 0 | Q14: =R14*D14 -> 0 | R14: 0 | S14: =E14+G14+I14+K14+M14+O14+Q14 -> 6 | T14: =S14/D14 -> 1 | U14: =E14+G14+I14+K14+M14 -> 6 | V14: =U14/D14 -> 1
C16: Total M2 de Fachada | D16: =SUM(D5:D14) -> 333.43 | E16: =SUM(E5:E14) -> 0 | F16: =E16/$D$16 -> 0 | G16: =SUM(G5:G14) -> 133.67 | H16: =G16/$D$16 -> 0.40089374 | I16: =SUM(I5:I14) -> 67.895 | J16: =I16/$D$16 -> 0.20362595 | K16: =SUM(K5:K14) -> 201.15 | L16: =K16/$D$16 -> 0.60327505 | M16: =SUM(M5:M14) -> 0 | N16: =M16/$D$16 -> 0 | O16: =SUM(O5:O14) -> 108 | P16: =O16/$D$16 -> 0.32390607 | Q16: =SUM(Q5:Q14) -> 8.64 | R16: =Q16/$D$16 -> 0.025912485 | S16: =SUM(S5:S14) -> 519.355 | T16: =S16/D16 -> 1.5576133 | U16: =SUM(U5:U14) -> 402.715 | V16: =U16/$D$16 -> 1.2077947
S17: =D16-S16 -> -185.925 | T17: =S17/D16 -> -0.55761329
A19: B | B19: 6 | C19: Lavado de fachada | D19: 193.3 | E19: =D19*F19 -> 0 | F19: 0 | G19: =D19*H19 -> 193.3 | H19: 1 | I19: =D19*J19 -> 0 | J19: 0 | K19: =D19*L19 -> 0 | L19: 0 | M19: =D19*N19 -> 121.3924 | N19: 0.628 | O19: =P19*D19 -> 0 | P19: 0 | Q19: =R19*D19 -> 71.9076 | R19: 0.372 | S19: =E19+G19+I19+K19+M19+O19+Q19 -> 386.6 | T19: =S19/D19 -> 2 | U19: =E19+G19+I19+K19+M19 -> 314.6924 | V19: =U19/D19 -> 1.628
C20: Lavado de vidrios | D20: 106.45 | E20: =D20*F20 -> 0 | F20: 0 | G20: =D20*H20 -> 0 | H20: 0 | I20: =D20*J20 -> 0 | J20: 0 | K20: =D20*L20 -> 0 | L20: 0 | M20: =D20*N20 -> 66.8506 | N20: 0.628 | O20: =P20*D20 -> 106.45 | P20: 1 | Q20: =R20*D20 -> 39.5994 | R20: 0.372 | S20: =E20+G20+I20+K20+M20+O20+Q20 -> 212.9 | T20: =S20/D20 -> 2 | U20: =E20+G20+I20+K20+M20 -> 66.8506 | V20: =U20/D20 -> 0.628
C22: Total M2 de Fachada | D22: =SUM(D19:D20) -> 299.75 | E22: =SUM(E19:E20) -> 0 | F22: =E22/$D$22 -> 0 | G22: =SUM(G19:G20) -> 193.3 | H22: =G22/$D$22 -> 0.64487073 | I22: =SUM(I19:I20) -> 0 | J22: =I22/$D$22 -> 0 | K22: =SUM(K19:K20) -> 0 | L22: =K22/$D$22 -> 0 | M22: =SUM(M19:M20) -> 188.243 | N22: =M22/$D$22 -> 0.628 | O22: =SUM(O19:O20) -> 106.45 | P22: =O22/$D$22 -> 0.35512927 | Q22: =SUM(Q19:Q20) -> 111.507 | R22: =Q22/$D$22 -> 0.372 | S22: =SUM(S19:S20) -> 599.5 | T22: =S22/$D$22 -> 2 | U22: =SUM(U19:U20) -> 381.543 | V22: =U22/D22 -> 1.2728707
S23: =D22-S22 -> -299.75 | T23: =S23/D22 -> -1
A25: C | B25: 1 | C25: Lavado de fachada | D25: 76.2 | E25: =D25*F25 -> 0 | F25: 0 | G25: =D25*H25 -> 0 | H25: 0 | I25: =D25*J25 -> 0 | J25: 0 | K25: =D25*L25 -> 0 | L25: 0 | M25: =F25*N25 -> 0 | N25: 0 | O25: =P25*D25 -> 0 | P25: 0 | Q25: =R25*D25 -> 0 | R25: 0 | S25: =E25+G25+I25+K25+M25+O25+Q25 -> 0 | T25: =S25/D25 -> 0 | U25: =E25+G25+I25+K25+M25 -> 0 | V25: =U25/D25 -> 0
C26: Lavado de vidrios | D26: 0 | E26: =D26*F26 -> 0 | F26: 0 | G26: =D26*H26 -> 0 | H26: 0 | I26: =D26*J26 -> 0 | J26: 0 | K26: =D26*L26 -> 0 | L26: 0 | M26: =F26*N26 -> 0 | N26: 0 | O26: =H26*P26 -> 0 | P26: 0 | Q26: =J26*R26 -> 0 | R26: 0 | S26: =E26+G26+I26+K26+M26+O26+Q26 -> 0 | T26: =S26/D26 -> #DIV/0! | U26: =E26+G26+I26+K26+M26 -> 0 | V26: =U26/D26 -> #DIV/0!
B27: 7 | C27: Lavado de fachada | D27: 194.2 | E27: =D27*F27 -> 0 | F27: 0 | G27: =D27*H27 -> 0 | H27: 0 | I27: =D27*J27 -> 0 | J27: 0 | K27: =D27*L27 -> 0 | L27: 0 | M27: =F27*N27 -> 0 | N27: 0 | O27: =H27*P27 -> 0 | P27: 0 | Q27: =J27*R27 -> 0 | R27: 0 | S27: =E27+G27+I27+K27+M27+O27+Q27 -> 0 | T27: =S27/D27 -> 0 | U27: =E27+G27+I27+K27+M27 -> 0 | V27: =U27/D27 -> 0
C28: Lavado de vidrios | D28: 117.83 | E28: =D28*F28 -> 0 | F28: 0 | G28: =D28*H28 -> 0 | H28: 0 | I28: =D28*J28 -> 0 | J28: 0 | K28: =D28*L28 -> 117.83 | L28: 1 | M28: =F28*N28 -> 0 | N28: 0 | O28: =H28*P28 -> 0 | P28: 0 | Q28: =J28*R28 -> 0 | R28: 0 | S28: =E28+G28+I28+K28+M28+O28+Q28 -> 117.83 | T28: =S28/D28 -> 1 | U28: =E28+G28+I28+K28+M28 -> 117.83 | V28: =U28/D28 -> 1
C30: Total M2 de Fachada | D30: =SUM(D25:D28) -> 388.23 | E30: =SUM(E25:E28) -> 0 | F30: =E30/$D$30 -> 0 | G30: =SUM(G25:G28) -> 0 | H30: =G30/$D$30 -> 0 | I30: =SUM(I25:I28) -> 0 | J30: =I30/$D$30 -> 0 | K30: =SUM(K25:K28) -> 117.83 | L30: =K30/$D$30 -> 0.30350565 | M30: =SUM(M25:M28) -> 0 | N30: =M30/$D$30 -> 0 | O30: =SUM(O25:O28) -> 0 | P30: =O30/$D$30 -> 0 | Q30: =SUM(Q25:Q28) -> 0 | R30: =Q30/$D$30 -> 0 | S30: =SUM(S25:S28) -> 117.83 | T30: =S30/D30 -> 0.30350565 | U30: =SUM(U25:U28) -> 117.83 | V30: =U30/D30 -> 0.30350565
S31: =D30-S30 -> 270.4 | T31: =S31/D30 -> 0.69649435
A33: D | B33: 8 | C33: Lavado de fachada | D33: 68.8 | E33: =D33*F33 -> 68.8 | F33: 1 | G33: =D33*H33 -> 0 | H33: 0 | I33: =D33*J33 -> 0 | J33: 0 | K33: =D33*L33 -> 0 | L33: 0 | M33: =D33*N33 -> 0 | N33: 0 | O33: =P33*D33 -> 0 | P33: 0 | Q33: =R33*D33 -> 0 | R33: 0 | S33: =E33+G33+I33+K33+M33+O33+Q33 -> 68.8 | T33: =S33/D33 -> 1 | U33: =E33+G33+I33+K33+M33 -> 68.8 | V33: =U33/D33 -> 1
C34: Lavado de vidrios | D34: 0 | E34: =D34*F34 -> 0 | F34: 0 | G34: =D34*H34 -> 0 | H34: 0 | I34: =D34*J34 -> 0 | J34: 0 | K34: =D34*L34 -> 0 | L34: 0 | M34: =D34*N34 -> 0 | N34: 0 | O34: =F34*P34 -> 0 | P34: 0 | Q34: =H34*R34 -> 0 | R34: 0 | S34: =E34+G34+I34+K34+M34+O34+Q34 -> 0 | T34: =S34/D34 -> #DIV/0! | U34: =E34+G34+I34+K34+M34 -> 0 | V34: =U34/D34 -> #DIV/0!
B35: 9 | C35: Lavado de fachada | D35: 33.8 | E35: =D35*F35 -> 33.8 | F35: 1 | G35: =D35*H35 -> 0 | H35: 0 | I35: =D35*J35 -> 0 | J35: 0 | K35: =D35*L35 -> 0 | L35: 0 | M35: =D35*N35 -> 0 | N35: 0 | O35: =P35*D35 -> 0 | P35: 0 | Q35: =R35*D35 -> 0 | R35: 0 | S35: =E35+G35+I35+K35+M35+O35+Q35 -> 33.8 | T35: =S35/D35 -> 1 | U35: =E35+G35+I35+K35+M35 -> 33.8 | V35: =U35/D35 -> 1
C36: Lavado de vidrios | D36: 2.1 | E36: =D36*F36 -> 0 | F36: 0 | G36: =D36*H36 -> 0 | H36: 0 | I36: =D36*J36 -> 0 | J36: 0 | K36: =D36*L36 -> 0 | L36: 0 | M36: =D36*N36 -> 2.1 | N36: 1 | O36: =F36*P36 -> 0 | P36: 0 | Q36: =H36*R36 -> 0 | R36: 0 | S36: =E36+G36+I36+K36+M36+O36+Q36 -> 2.1 | T36: =S36/D36 -> 1 | U36: =E36+G36+I36+K36+M36 -> 2.1 | V36: =U36/D36 -> 1
B37: 10 | C37: Lavado de fachada | D37: 60.9 | E37: =D37*F37 -> 60.9 | F37: 1 | G37: =D37*H37 -> 0 | H37: 0 | I37: =D37*J37 -> 0 | J37: 0 | K37: =D37*L37 -> 0 | L37: 0 | M37: =D37*N37 -> 0 | N37: 0 | O37: =P37*D37 -> 0 | P37: 0 | Q37: =R37*D37 -> 0 | R37: 0 | S37: =E37+G37+I37+K37+M37+O37+Q37 -> 60.9 | T37: =S37/D37 -> 1 | U37: =E37+G37+I37+K37+M37 -> 60.9 | V37: =U37/D37 -> 1
C38: Lavado de vidrios | D38: =0 -> 0 | E38: =D38*F38 -> 0 | F38: 0 | G38: =D38*H38 -> 0 | H38: 0 | I38: =D38*J38 -> 0 | J38: 0 | K38: =D38*L38 -> 0 | L38: 0 | M38: =D38*N38 -> 0 | N38: 0 | O38: =F38*P38 -> 0 | P38: 0 | Q38: =H38*R38 -> 0 | R38: 0 | S38: =E38+G38+I38+K38+M38+O38+Q38 -> 0 | T38: =S38/D38 -> #DIV/0! | U38: =E38+G38+I38+K38+M38 -> 0 | V38: =U38/D38 -> #DIV/0!
B39: 11 | C39: Lavado de fachada | D39: 33.8 | E39: =D39*F39 -> 33.8 | F39: 1 | G39: =D39*H39 -> 0 | H39: 0 | I39: =D39*J39 -> 0 | J39: 0 | K39: =D39*L39 -> 0 | L39: 0 | M39: =D39*N39 -> 0 | N39: 0 | O39: =P39*D39 -> 0 | P39: 0 | Q39: =R39*D39 -> 0 | R39: 0 | S39: =E39+G39+I39+K39+M39+O39+Q39 -> 33.8 | T39: =S39/D39 -> 1 | U39: =E39+G39+I39+K39+M39 -> 33.8 | V39: =U39/D39 -> 1
C40: Lavado de vidrios | D40: 2.1 | E40: =D40*F40 -> 0 | F40: 0 | G40: =D40*H40 -> 0 | H40: 0 | I40: =D40*J40 -> 0 | J40: 0 | K40: =D40*L40 -> 0 | L40: 0 | M40: =D40*N40 -> 2.1 | N40: 1 | O40: =F40*P40 -> 0 | P40: 0 | Q40: =H40*R40 -> 0 | R40: 0 | S40: =E40+G40+I40+K40+M40+O40+Q40 -> 2.1 | T40: =S40/D40 -> 1 | U40: =E40+G40+I40+K40+M40 -> 2.1 | V40: =U40/D40 -> 1
B41: 12 | C41: Lavado de fachada | D41: 69.1 | E41: =D41*F41 -> 69.1 | F41: 1 | G41: =D41*H41 -> 0 | H41: 0 | I41: =D41*J41 -> 0 | J41: 0 | K41: =D41*L41 -> 0 | L41: 0 | M41: =D41*N41 -> 0 | N41: 0 | O41: =P41*D41 -> 0 | P41: 0 | Q41: =R41*D41 -> 0 | R41: 0 | S41: =E41+G41+I41+K41+M41+O41+Q41 -> 69.1 | T41: =S41/D41 -> 1 | U41: =E41+G41+I41+K41+M41 -> 69.1 | V41: =U41/D41 -> 1
C42: Lavado de vidrios | D42: 1.24 | E42: =D42*F42 -> 0 | F42: 0 | G42: =D42*H42 -> 0 | H42: 0 | I42: =D42*J42 -> 0 | J42: 0 | K42: =D42*L42 -> 0 | L42: 0 | M42: =D42*N42 -> 0 | N42: 0 | O42: =F42*P42 -> 0 | P42: 0 | Q42: =H42*R42 -> 0 | R42: 0 | S42: =E42+G42+I42+K42+M42+O42+Q42 -> 0 | T42: =S42/D42 -> 0 | U42: =E42+G42+I42+K42+M42 -> 0 | V42: =U42/D42 -> 0
C44: Total M2 de Fachada | D44: =SUM(D33:D42) -> 271.84 | E44: =SUM(E33:E42) -> 266.4 | F44: =E44/$D$44 -> 0.97998823 | G44: =SUM(G33:G42) -> 0 | H44: =G44/$D$44 -> 0 | I44: =SUM(I33:I42) -> 0 | J44: =I44/$D$44 -> 0 | K44: =SUM(K33:K42) -> 0 | L44: =K44/$D$44 -> 0 | M44: =SUM(M33:M42) -> 4.2 | N44: =M44/$D$44 -> 0.015450265 | O44: =SUM(O33:O42) -> 0 | P44: =O44/$D$44 -> 0 | Q44: =SUM(Q33:Q42) -> 0 | R44: =Q44/$D$44 -> 0 | S44: =SUM(S33:S42) -> 270.6 | T44: =S44/$D$44 -> 0.99543849 | U44: =SUM(U33:U42) -> 270.6 | V44: =U44/$D$44 -> 0.99543849
S45: =D44-S44 -> 1.24 | T45: =S45/D44 -> 0.0045615068
A47: E | B47: 13 | C47: Lavado de fachada | D47: 181.8 | E47: =D47*F47 -> 0 | F47: 0 | G47: 100 | H47: 0 | I47: =D47*J47 -> 0 | J47: 0 | K47: =D47*L47 -> 0 | L47: 0 | M47: =D47*N47 -> 0 | N47: 0 | O47: =P47*D47 -> 0 | P47: 0 | Q47: =R47*D47 -> 0 | R47: 0 | S47: =E47+G47+I47+K47+M47+O47+Q47 -> 100 | T47: =S47/D47 -> 0.55005501 | U47: =E47+G47+I47+K47+M47 -> 100 | V47: =U47/D47 -> 0.55005501
C48: Lavado de vidrios | D48: 100.38 | E48: =D48*F48 -> 0 | F48: 0 | G48: =D48*H48 -> 0 | H48: 0 | I48: =D48*J48 -> 0 | J48: 0 | K48: =D48*L48 -> 0 | L48: 0 | M48: =D48*N48 -> 0 | N48: 0 | O48: =F48*P48 -> 0 | P48: 0 | Q48: =H48*R48 -> 0 | R48: 0 | S48: =E48+G48+I48+K48+M48+O48+Q48 -> 0 | T48: =S48/D48 -> 0 | U48: =E48+G48+I48+K48+M48 -> 0 | V48: =U48/D48 -> 0
...

Sheet Sellos
A1: CEDROS - SELLO PERIMETRAL
E2: ENE 15 - 17 | G2: ENE 19 - 24 | I2: ENE 26 - 31 | K2: FEB 02-07 | M2: FEB 09-14 | O2: FEB 16 - 21 | Q2: FEB 23 - 28
