Workbook

Sheet APU I
A1: CONDOMINIO PARQUE RESIDENCIAL LOS CEDROS
A3: PRELIMINARES
A5: ACTIVIDAD: Desmontaje de piso tipo Deck | D5: ITEM | E5: 1.0
D6: UNIDAD | E6: M2
A7: I. EQUIPOS
A8: DESCRIPCIÓN | B8: UNIDAD | C8: RENDIMIENTO | D8: TARIFA | E8: VALOR - PARCIAL
A9: Herramienta menor | B9: %MO | C9: 0.1 | D9: =E27 -> 2600 | E9: =C9*D9 -> 260
A11: SUB - TOTAL | E11: =SUM(E9:E9) -> 260
A12: II. MATERIALES
A13: DESCRIPCIÓN | B13: UNIDAD | C13: CANTIDAD | D13: PRECIO - UNIT | E13: VALOR - PARCIAL
A15: Desperdicio 2% | E15: =SUM(E14:E14)*0.02 -> 0
A17: SUB - TOTAL | E17: =SUM(E14:E15) -> 0
A18: III. TRANSPORTE
A19: DESCRIPCIÓN | B19: UNIDAD | C19: RENDIMIENTO | D19: TARIFA | E19: VALOR - PARCIAL
A20: Acarreo LUV | B20: Día | C20: 0 | D20: 0 | E20: 0
A22: SUB - TOTAL | E22: =SUM(E20) -> 0
A23: IV. MANO DE OBRA
A24: DESCRIPCIÓN | B24: UNIDAD | C24: RENDIMIENTO | D24: JORNAL | E24: VALOR - PARCIAL
A25: Oficial | B25: Día | C25: 50 | D25: 130000 | E25: =D25/C25 -> 2600
A27: SUB - TOTAL | E27: =SUM(E25) -> 2600
A29: TOTAL UNITARIO | E29: =SUM(E11,E17,E22,E27) -> 2860
A32: ACTIVIDAD: Restructuración e instalación de lámina de fibrocemento | D32: ITEM | E32: 2
D33: UNIDAD | E33: M2
A34: I. EQUIPOS
A35: DESCRIPCIÓN | B35: UNIDAD | C35: RENDIMIENTO | D35: TARIFA | E35: VALOR - PARCIAL
A36: Herramienta menor | B36: %MO | C36: 0.05 | D36: =E58 -> 7000 | E36: =C36*D36 -> 350
A38: SUB - TOTAL | E38: =SUM(E36:E36) -> 350
A39: II. MATERIALES
A40: DESCRIPCIÓN | B40: UNIDAD | C40: CANTIDAD | D40: PRECIO - UNIT | E40: VALOR - PARCIAL
A41: Lamina fibrocemento de 10mm | B41: Und | C41: 0.35 | D41: 96000 | E41: =C41*D41 -> 33600
A42: Paral Estructural | B42: Und | C42: 1 | D42: 9500 | E42: =C42*D42 -> 9500
A43: Canal Estructural | B43: Und | C43: 1 | D43: 9000 | E43: =C43*D43 -> 9000
A44: Tornillos | B44: Und | C44: 50 | D44: 40 | E44: =C44*D44 -> 2000
A46: Desperdicio 2% | E46: 0
A48: SUB - TOTAL | E48: =SUM(E41:E46) -> 54100
A49: III. TRANSPORTE
A50: DESCRIPCIÓN | B50: UNIDAD | C50: RENDIMIENTO | D50: TARIFA | E50: VALOR - PARCIAL
A51: Acarreo LUV | B51: Día | C51: 0.025 | D51: 60000 | E51: =D51*C51 -> 1500
A53: SUB - TOTAL | E53: =SUM(E51) -> 1500
A54: IV. MANO DE OBRA
...

Sheet APU II
A1: CONDOMINIO PARQUE RESIDENCIAL LOS CEDROS
A3: PREPARACIÓN DE SUPERFICIES | G3: TIEMPO ESTIMADO
A5: ACTIVIDAD: Lavado General de Superficies | D5: ITEM | E5: 1.0
D6: UNIDAD | E6: M2
A7: I. EQUIPOS
A8: DESCRIPCIÓN | B8: UNIDAD | C8: RENDIMIENTO | D8: TARIFA | E8: VALOR - PARCIAL
A9: Herramienta menor | B9: %MO | C9: 0.1 | D9: =E31 -> 633.33333 | E9: =C9*D9 -> 63.333333
A10: Equipos Freshouse | B10: Día | C10: 0.015 | D10: 25000 | E10: =C10*D10 -> 375
A11: Equipo Hidrolavadora | B11: Día | C11: 0.01 | D11: 15000 | E11: =C11*D11 -> 150
A13: SUB - TOTAL | E13: =SUM(E9:E11) -> 588.33333
A14: II. MATERIALES
A15: DESCRIPCIÓN | B15: UNIDAD | C15: CANTIDAD | D15: PRECIO - UNIT | E15: VALOR - PARCIAL
A16: Hipoclorito | B16: GL | C16: 0.05 | D16: 35000 | E16: =C16*D16 -> 1750
A17: Agua | B17: Und | C17: 0.1 | D17: 500 | E17: =C17*D17 -> 50
A19: Desperdicio 2% | E19: 0
A21: SUB - TOTAL | E21: =SUM(E16:E19) -> 1800
A22: III. TRANSPORTE
A23: DESCRIPCIÓN | B23: UNIDAD | C23: RENDIMIENTO | D23: TARIFA | E23: VALOR - PARCIAL
A24: Acarreo LUV | B24: Día | C24: 0 | D24: 0 | E24: 0
A26: SUB - TOTAL | E26: =SUM(E24) -> 0
A27: IV. MANO DE OBRA
A28: DESCRIPCIÓN | B28: UNIDAD | C28: RENDIMIENTO | D28: JORNAL | E28: VALOR - PARCIAL
A29: Práctico | B29: Día | C29: 150 | D29: 95000 | E29: =D29/C29 -> 633.33333 | G29: =480/C29 -> 3.2
A31: SUB - TOTAL | E31: =SUM(E29) -> 633.33333
A33: TOTAL UNITARIO | E33: =SUM(E13,E21,E26,E31) -> 3021.6667
A35: Retiro y Reemplazo de Graniplast Deteriorado | E35: 2.2
A37: ACTIVIDAD: Inspección de superficie incluye rasqueteado | D37: ITEM
D38: UNIDAD | E38: M2
A39: I. EQUIPOS
A40: DESCRIPCIÓN | B40: UNIDAD | C40: RENDIMIENTO | D40: TARIFA | E40: VALOR - PARCIAL
A41: Herramienta menor | B41: %MO | C41: 0.05 | D41: =E60 -> 730.76923 | E41: =C41*D41 -> 36.538462
A42: Equipos Freshouse | B42: Día | C42: 0.015 | D42: 25000 | E42: =C42*D42 -> 375
A44: SUB - TOTAL | E44: =SUM(E41:E42) -> 411.53846
A45: II. MATERIALES
A46: DESCRIPCIÓN | B46: UNIDAD | C46: CANTIDAD | D46: PRECIO - UNIT | E46: VALOR - PARCIAL
A48: Desperdicio 2% | E48: 0
A50: SUB - TOTAL | E50: =SUM(E47:E48) -> 0
A51: III. TRANSPORTE
A52: DESCRIPCIÓN | B52: UNIDAD | C52: RENDIMIENTO | D52: TARIFA | E52: VALOR - PARCIAL
A53: Acarreo LUV | B53: Día | C53: 0 | D53: 60000 | E53: =D53*C53 -> 0
...

Sheet APU III
A1: CONDOMINIO PARQUE RESIDENCIAL LOS CEDROS
A3: ACABADO DE PINTURA | G3: TIEMPO ESTIMADO
A5: ACTIVIDAD: Suministro y Aplicación de Pintura para exteriores | D5: ITEM | E5: 1.0
D6: UNIDAD | E6: M2
A7: I. EQUIPOS
A8: DESCRIPCIÓN | B8: UNIDAD | C8: RENDIMIENTO | D8: TARIFA | E8: VALOR - PARCIAL
A9: Herramienta menor | B9: %MO | C9: 0.1 | D9: =E32 -> 2166.6667 | E9: =C9*D9 -> 216.66667
A10: Equipos Freshouse | B10: Día | C10: 0.015 | D10: 25000 | E10: =C10*D10 -> 375
A12: SUB - TOTAL | E12: =SUM(E9:E10) -> 591.66667
A13: II. MATERIALES
A14: DESCRIPCIÓN | B14: UNIDAD | C14: CANTIDAD | D14: PRECIO - UNIT | E14: VALOR - PARCIAL
A15: Koraza Pro 550 | B15: CÑ | C15: 0.02 | D15: 450000 | E15: =C15*D15 -> 9000
A16: Rodillo 9" | B16: Und | C16: 0.001 | D16: 38000 | E16: =C16*D16 -> 38
A17: Brocha | B17: Und | C17: 0.001 | D17: 10000 | E17: =C17*D17 -> 10
A20: Desperdicio 2% | E20: =SUM(E15:E19)*0.05 -> 452.4
A22: SUB - TOTAL | E22: =SUM(E15:E20) -> 9500.4
A23: III. TRANSPORTE
A24: DESCRIPCIÓN | B24: UNIDAD | C24: RENDIMIENTO | D24: TARIFA | E24: VALOR - PARCIAL
A25: Acarreo | B25: Día | C25: 0.025 | D25: 25000 | E25: =D25*C25 -> 625
A27: SUB - TOTAL | E27: =SUM(E25) -> 625
A28: IV. MANO DE OBRA
A29: DESCRIPCIÓN | B29: UNIDAD | C29: RENDIMIENTO | D29: JORNAL | E29: VALOR - PARCIAL
A30: Oficial | B30: Día | C30: 60 | D30: 130000 | E30: =D30/C30 -> 2166.6667 | G30: =480/C30 -> 8
A32: SUB - TOTAL | E32: =SUM(E30) -> 2166.6667
A34: TOTAL UNITARIO | E34: =SUM(E12,E22,E27,E32) -> 12883.733
A36: Retiro y Reemplazo de Graniplast Deteriorado | E36: 2.2
A38: ACTIVIDAD: Inspección de superficie incluye rasqueteado | D38: ITEM
D39: UNIDAD | E39: M2
A40: I. EQUIPOS
A41: DESCRIPCIÓN | B41: UNIDAD | C41: RENDIMIENTO | D41: TARIFA | E41: VALOR - PARCIAL
A42: Herramienta menor | B42: %MO | C42: 0.05 | D42: =E61 -> 730.76923 | E42: =C42*D42 -> 36.538462
A43: Equipos Freshouse | B43: Día | C43: 0.015 | D43: 25000 | E43: =C43*D43 -> 375
A45: SUB - TOTAL | E45: =SUM(E42:E43) -> 411.53846
A46: II. MATERIALES
A47: DESCRIPCIÓN | B47: UNIDAD | C47: CANTIDAD | D47: PRECIO - UNIT | E47: VALOR - PARCIAL
A49: Desperdicio 2% | E49: 0
A51: SUB - TOTAL | E51: =SUM(E48:E49) -> 0
A52: III. TRANSPORTE
A53: DESCRIPCIÓN | B53: UNIDAD | C53: RENDIMIENTO | D53: TARIFA | E53: VALOR - PARCIAL
A54: Acarreo LUV | B54: Día | C54: 0 | D54: 60000 | E54: =D54*C54 -> 0
...

Sheet APU IV
A1: CONDOMINIO PARQUE RESIDENCIAL LOS CEDROS
A3: ACABADO DE PINTURA | G3: TIEMPO ESTIMADO
A5: ACTIVIDAD: Suministro y Aplicación de Pintura para exteriores | D5: ITEM | E5: 1.0
D6: UNIDAD | E6: M2
A7: I. EQUIPOS
A8: DESCRIPCIÓN | B8: UNIDAD | C8: RENDIMIENTO | D8: TARIFA | E8: VALOR - PARCIAL
A9: Herramienta menor | B9: %MO | C9: 0.1 | D9: =E32 -> 2166.6667 | E9: =C9*D9 -> 216.66667
A10: Equipos Freshouse | B10: Día | C10: 0.015 | D10: 25000 | E10: =C10*D10 -> 375
A12: SUB - TOTAL | E12: =SUM(E9:E10) -> 591.66667
A13: II. MATERIALES
A14: DESCRIPCIÓN | B14: UNIDAD | C14: CANTIDAD | D14: PRECIO - UNIT | E14: VALOR - PARCIAL
A15: Koraza Pro 550 | B15: CÑ | C15: 0.04 | D15: 450000 | E15: =C15*D15 -> 18000
A16: Rodillo 9" | B16: Und | C16: 0.001 | D16: 38000 | E16: =C16*D16 -> 38
A17: Brocha | B17: Und | C17: 0.001 | D17: 10000 | E17: =C17*D17 -> 10
A20: Desperdicio 2% | E20: =SUM(E15:E19)*0.05 -> 902.4
A22: SUB - TOTAL | E22: =SUM(E15:E20) -> 18950.4
A23: III. TRANSPORTE
A24: DESCRIPCIÓN | B24: UNIDAD | C24: RENDIMIENTO | D24: TARIFA | E24: VALOR - PARCIAL
A25: Acarreo | B25: Día | C25: 0.025 | D25: 25000 | E25: =D25*C25 -> 625
A27: SUB - TOTAL | E27: =SUM(E25) -> 625
A28: IV. MANO DE OBRA
A29: DESCRIPCIÓN | B29: UNIDAD | C29: RENDIMIENTO | D29: JORNAL | E29: VALOR - PARCIAL
A30: Oficial | B30: Día | C30: 60 | D30: 130000 | E30: =D30/C30 -> 2166.6667 | G30: =480/C30 -> 8
A32: SUB - TOTAL | E32: =SUM(E30) -> 2166.6667
A34: TOTAL UNITARIO | E34: =SUM(E12,E22,E27,E32) -> 22333.733
A37: Reparación de antepechos y jardineras | E37: 2.2
A39: ACTIVIDAD: Aplicación de Aqua Block | D39: ITEM
D40: UNIDAD | E40: M2
A41: I. EQUIPOS
A42: DESCRIPCIÓN | B42: UNIDAD | C42: RENDIMIENTO | D42: TARIFA | E42: VALOR - PARCIAL
A43: Herramienta menor | B43: %MO | C43: 0.05 | D43: =E63 -> 2000 | E43: =C43*D43 -> 100
A44: Equipos Freshouse | B44: Día | C44: 0.015 | D44: 25000 | E44: =C44*D44 -> 375
A46: SUB - TOTAL | E46: =SUM(E43:E44) -> 475
A47: II. MATERIALES
A48: DESCRIPCIÓN | B48: UNIDAD | C48: CANTIDAD | D48: PRECIO - UNIT | E48: VALOR - PARCIAL
A49: AquaBlock | B49: CÑ | C49: 0.016 | D49: 574900 | E49: =C49*D49 -> 9198.4 | G49: =D49/32 -> 17965.625 | H49: =19/32 -> 0.59375
A51: Desperdicio 2% | E51: 0
A53: SUB - TOTAL | E53: =SUM(E49:E51) -> 9198.4
A54: III. TRANSPORTE
A55: DESCRIPCIÓN | B55: UNIDAD | C55: RENDIMIENTO | D55: TARIFA | E55: VALOR - PARCIAL
...

Sheet APU V
A1: CONDOMINIO PARQUE RESIDENCIAL LOS CEDROS
A3: Recorrido General de Cubiertas existentes sobre los tres bloques de apartamentos. Se estima una reposicion total de al menos el 25% de la cubierta existente.
A5: ACTIVIDAD: Suministro e instalación de teja de fibrocemento | D5: ITEM | E5: 4.1
D6: UNIDAD | E6: M2
A7: I. EQUIPOS
A8: DESCRIPCIÓN | B8: UNIDAD | C8: RENDIMIENTO | D8: TARIFA | E8: VALOR - PARCIAL
A9: Herramienta menor | B9: %MO | C9: 0.1 | D9: =E30 -> 7333.3333 | E9: =C9*D9 -> 733.33333
A11: SUB - TOTAL | E11: =SUM(E9:E9) -> 733.33333
A12: II. MATERIALES
A13: DESCRIPCIÓN | B13: UNIDAD | C13: CANTIDAD | D13: PRECIO - UNIT | E13: VALOR - PARCIAL
A14: Teja de fibrocemento | B14: Und | C14: 0.5 | D14: 35000 | E14: =C14*D14 -> 17500
A15: Amarras | B15: Und | C15: 4 | D15: 800 | E15: =C15*D15 -> 3200
A16: Ganchos | B16: Und | C16: 2 | D16: 1500 | E16: =C16*D16 -> 3000
A18: Desperdicio 2% | E18: =SUM(E14:E14)*0.02 -> 350
A20: SUB - TOTAL | E20: =SUM(E14:E18) -> 24050
A21: III. TRANSPORTE
A22: DESCRIPCIÓN | B22: UNIDAD | C22: RENDIMIENTO | D22: TARIFA | E22: VALOR - PARCIAL
A23: Acarreo LUV | B23: Día | C23: 0.025 | D23: 60000 | E23: =D23*C23 -> 1500
A25: SUB - TOTAL | E25: =SUM(E23) -> 1500
A26: IV. MANO DE OBRA
A27: DESCRIPCIÓN | B27: UNIDAD | C27: RENDIMIENTO | D27: JORNAL | E27: VALOR - PARCIAL
A28: CUADRILLA 1: 1 Oficial y 1 ayudante | B28: Día | C28: 30 | D28: 220000 | E28: =D28/C28 -> 7333.3333
A30: SUB - TOTAL | E30: =SUM(E28) -> 7333.3333
A32: TOTAL UNITARIO | E32: =SUM(E11,E20,E25,E30) -> 33616.667
A35: ACTIVIDAD: Desmonte de teja de fibrocemento | D35: ITEM | E35: 4.1
D36: UNIDAD | E36: M2
A37: I. EQUIPOS
A38: DESCRIPCIÓN | B38: UNIDAD | C38: RENDIMIENTO | D38: TARIFA | E38: VALOR - PARCIAL
A39: Herramienta menor | B39: %MO | C39: 0.05 | D39: =E57 -> 7333.3333 | E39: =C39*D39 -> 366.66667
A41: SUB - TOTAL | E41: =SUM(E39:E39) -> 366.66667
A42: II. MATERIALES
A43: DESCRIPCIÓN | B43: UNIDAD | C43: CANTIDAD | D43: PRECIO - UNIT | E43: VALOR - PARCIAL
A45: Desperdicio 2% | E45: 0
A47: SUB - TOTAL | E47: =SUM(E44:E45) -> 0
A48: III. TRANSPORTE
A49: DESCRIPCIÓN | B49: UNIDAD | C49: RENDIMIENTO | D49: TARIFA | E49: VALOR - PARCIAL
A50: Acarreo LUV | B50: Día | C50: 0 | D50: 60000 | E50: =D50*C50 -> 0
A52: SUB - TOTAL | E52: =SUM(E50) -> 0
A53: IV. MANO DE OBRA
A54: DESCRIPCIÓN | B54: UNIDAD | C54: RENDIMIENTO | D54: JORNAL | E54: VALOR - PARCIAL
...

Sheet RESUMEN APU
A1: CONDOMINIO PARQUE RESIDENCIAL LOS CEDROS
A3: ITEM | B3: DESCRIPCIÓN | D3: 0.05 | E3: 0.1
A4: 1.1 | B4: Campamento de Obra | C4: 4900000 | D4: =C4*1.05 -> 5145000 | E4: =C4*1.1 -> 5390000
A6: 1.2 | B6: Señalización de Obra | C6: 550000 | D6: =C6*1.05 -> 577500 | E6: =C6*1.1 -> 605000
A8: ITEM | B8: DESCRIPCIÓN | C8: VALOR | D8: 0.05 | E8: 0.1
A9: 2.1 | B9: Lavado de superficie | C9: ='APU II'!E33 -> 3021.6667 | D9: =C9*1.05 -> 3172.75 | E9: =C9*1.1 -> 3323.8333
A11: 2.2 | B11: Retiro y Reemplazo de Graniplast Deteriorado | C11: =SUM(C12:C15) -> 53794.451 | D11: =SUM(D12:D14) -> 56484.173 | E11: =SUM(E12:E14) -> 62132.59
A12: 2.1.1 | B12: Inspección de superficie incluye rasqueteado | C12: ='APU II'!E62 -> 1142.3077 | D12: =C12*1.05 -> 1199.4231 | E12: =D12*1.1 -> 1319.3654
A13: 2.1.2 | B13: Nivelación de superficie con Mortero Listo | C13: ='APU II'!E92 -> 16508.143 | D13: =C13*1.05 -> 17333.55 | E13: =D13*1.1 -> 19066.905
A14: 2.1.3 | B14: Aplicación de Graniplast | C14: ='APU II'!E122 -> 36144 | D14: =C14*1.05 -> 37951.2 | E14: =D14*1.1 -> 41746.32
C15: 0
A16: 2.3 | B16: Reposicion de Mortero en mal estado | C16: ='APU II'!E154 -> 34908.75 | D16: =C16*1.05 -> 36654.188 | E16: =C16*1.1 -> 38399.625
B17: Aplicación de revoque impermeabilizado | C17: 0 | D17: =C17*1.05 -> 0 | E17: =C17*1.1 -> 0
A19: 2.4 | B19: Retiro y Reemplazo de Superboard | C19: =SUM(C20:C21) -> 88306.944 | D19: =SUM(D20:D21) -> 92722.292 | E19: =SUM(E20:E21) -> 97137.639
A20: 2.3.1 | B20: Remoción de lámina superboard | C20: ='APU II'!E185 -> 13944.444 | D20: =C20*1.05 -> 14641.667 | E20: =C20*1.1 -> 15338.889
A21: 2.3.2 | B21: Restructuración e Instalación de lámina de fibrocemento | C21: ='APU II'!E218 -> 74362.5 | D21: =C21*1.05 -> 78080.625 | E21: =C21*1.1 -> 81798.75
A23: 2.5 | B23: Retiro y Reemplazo de lamina Drywall | C23: =SUM(C24:C25) -> 54400 | D23: =SUM(D24:D25) -> 57120 | E23: =SUM(E24:E25) -> 59840
A24: 2.3.1 | B24: Remoción de lámina de panel yeso | C24: 7200 | D24: =C24*1.05 -> 7560 | E24: =C24*1.1 -> 7920
A25: 2.3.2 | B25: Restructuración e Instalación de lámina de fibrocemento | C25: ='APU II'!E249 -> 47200 | D25: =C25*1.05 -> 49560 | E25: =C25*1.1 -> 51920
A27: ITEM | B27: DESCRIPCIÓN | D27: 0.05 | E27: 0.1
A28: 3.1 | B28: Suministro y Aplicación de Pintura para exteriores | C28: =SUM(C29:C29) -> 12883.733 | D28: =SUM(D29:D29) -> 13527.92 | E28: =SUM(E29:E29) -> 14172.107
B29: Suministro y Aplicación de Pintura para exteriores | C29: ='APU III'!E34 -> 12883.733 | D29: =C29*1.05 -> 13527.92 | E29: =C29*1.1 -> 14172.107
A31: 3.2 | B31: Suministro y Aplicación de Pintura incluye tratamiento con Aqua Block | C31: =SUM(C32:C33) -> 37867.933 | D31: =SUM(D32:D33) -> 39761.33 | E31: =SUM(E32:E33) -> 41654.727
B32: Reparación de antepechos y aplicación de Aqua Block | C32: ='APU IV'!E65+'APU IV'!E95 -> 24984.2 | D32: =C32*1.05 -> 26233.41 | E32: =C32*1.1 -> 27482.62
B33: Suministro y Aplicación de Pintura para exteriores | C33: =C29 -> 12883.733 | D33: =C33*1.05 -> 13527.92 | E33: =C33*1.1 -> 14172.107
A35: 3.3 | B35: Suministro y Aplicación de Pintura incluye reconstrucción de pendiente | C35: =SUM(C36:C37) -> 26069.533 | D35: =SUM(D36:D37) -> 27373.01 | E35: =SUM(E36:E37) -> 28676.487
B36: Reconstrucción de pendiente en volumenes | C36: ='APU IV'!E95 -> 13185.8 | D36: =C36*1.05 -> 13845.09 | E36: =C36*1.1 -> 14504.38
B37: Suministro y Aplicación de Pintura para exteriores | C37: =C29 -> 12883.733 | D37: =C37*1.05 -> 13527.92 | E37: =C37*1.1 -> 14172.107
A39: 3.4 | B39: Suministro y Aplicación de Pintura para exteriores alfajías | C39: ='APU IV'!E125 -> 5894.1429 | D39: =C39*1.05 -> 6188.85 | E39: =C39*1.1 -> 6483.5571
A41: 3.5 | B41: Suministro y Aplicación de Pintura para interiores | C41: =SUM(C42:C42) -> 10414.567 | D41: =SUM(D42:D42) -> 10935.295 | E41: =SUM(E42:E42) -> 11456.023
B42: Suministro y Aplicación de Pintura para interiores | C42: ='APU IV'!E156 -> 10414.567 | D42: =C42*1.05 -> 10935.295 | E42: =C42*1.1 -> 11456.023
A44: 3.6 | B44: Suministro y Aplicación de Pintura para puertas | C44: =SUM(C45:C45) -> 80998.75 | D44: =SUM(D45:D45) -> 85048.688 | E44: =SUM(E45:E45) -> 89098.625
B45: Suministro y Aplicación de Pintura para puertas | C45: ='APU IV'!E188 -> 80998.75 | D45: =C45*1.05 -> 85048.688 | E45: =C45*1.1 -> 89098.625
A47: 3.7 | B47: Suministro y Aplicación de Pintura en barandas | C47: =SUM(C48:C48) -> 10066.964 | D47: =SUM(D48:D48) -> 10570.313 | E47: =SUM(E48:E48) -> 11073.661
B48: Suministro y Aplicación de Pintura en barandas | C48: ='APU IV'!E220 -> 10066.964 | D48: =C48*1.05 -> 10570.313 | E48: =C48*1.1 -> 11073.661
A50: 3.8 | B50: Suministro y Aplicación de Pintura estructuras de parqueadero | C50: =SUM(C51:C51) -> 18001.25 | D50: =SUM(D51:D51) -> 18901.312 | E50: =SUM(E51:E51) -> 19801.375
B51: Suministro y Aplicación de Pintura estructuras de parqueadero | C51: ='APU IV'!E252 -> 18001.25 | D51: =C51*1.05 -> 18901.312 | E51: =C51*1.1 -> 19801.375
A53: 3.9 | B53: Suministro y Aplicación de Pintucofill | C53: =SUM(C54:C54) -> 21726.428 | D53: =SUM(D54:D54) -> 22812.749 | E53: =SUM(E54:E54) -> 23899.071
B54: Suministro y Aplicación de Pintura en barandas | C54: ='APU IV'!E284 -> 21726.428 | D54: =C54*1.05 -> 22812.749 | E54: =C54*1.1 -> 23899.071
A56: ITEM | B56: DESCRIPCIÓN | C56: VALOR | D56: 0.05 | E56: 0.1
...

Sheet COTIZACIÓN
A1: CONDOMINIO PARQUE RESIDENCIAL LOS CEDROS-ARMENIA-Quindío
A2: Cuadro General de Actividades, Unidades de Medida, Cantidades y Precios Unitarios
A3: ANEXO 01-OPCION 2
A4: Proponente: | D4: Levanto Informacion: | F4: Ing. Carlos Alberto Agudelo Restrepo
A5: Interventor: Ing. Luis Fernando Márquez Jaramillo | F5: Arq. Maria Fernanda Morales Palacio
A6: Ubicación Proyecto: Calle 50 Norte # 15-01 | D6: Fecha: Febrero de 2025 | F6: Sra Maria del Pilar Rubio L. Administradora
A7: ACTIVIDADES EN LOS BLOQUES DE APARTAMENTOS y AREAS COMUNES DE LOS MISMOS
A8: Capitulo | B8: Items | C8: Descripcion de Actividad | D8: Unidad | E8: Cantidad | F8: Vr Unitario | G8: Vr Total
A9: 1 | C9: PRELIMINARES | G9: =+G10+G11 -> 5722500
B10: 1.1 | C10: Campamento de Obra | D10: Gbl | E10: 1 | F10: ='RESUMEN APU'!D4 -> 5145000 | G10: =+E10*F10 -> 5145000
B11: 1.2 | C11: Señalizacion y Seguridad de la Obra | D11: Gbl | E11: 1 | F11: ='RESUMEN APU'!D6 -> 577500 | G11: =+E11*F11 -> 577500
A12: 2 | C12: PREPARACION DE SUPERFICIES | G12: =+G13+G14+G15+G16+G17 -> 1.1184701e+08
B13: 2.1 | C13: Lavado General de Superficies a Intervenir | D13: M2 | E13: 7304.6725 | F13: ='RESUMEN APU'!D9 -> 3172.75 | G13: =+E13*F13 -> 23175900
B14: 2.2 | C14: Retiro y Reemplazo de Graniplast Deteriorado en fachadas de las tres torres (26% DEL TOTAL APROX) | D14: M2 | E14: 1205.1154 | F14: ='RESUMEN APU'!D11 -> 56484.173 | G14: =+E14*F14 -> 68069946
B15: 2.3 | C15: Reposicion de Mortero en mal estado en fachadas de las tres torres | D15: M2 | E15: 90 | F15: ='RESUMEN APU'!D16 -> 36654.188 | G15: =+E15*F15 -> 3298876.9
B16: 2.4 | C16: Retiro y Reemplazo de Superboard en mal estado en fachadas de las tres torres | D16: M2 | E16: 125 | F16: ='RESUMEN APU'!D19 -> 92722.292 | G16: =+E16*F16 -> 11590286
B17: 2.5 | C17: Retiro y Reemplazo de Drywall en mal estado en cielos rasos de fachadas | D17: M2 | E17: 100 | F17: ='RESUMEN APU'!D23 -> 57120 | G17: =+E17*F17 -> 5712000
A18: 3 | C18: ACABADO Y PINTURA | G18: =+G19+G24+G26 -> 1.7124465e+08
B19: PINTURA PARA EXTERIORES-TIPO KORAZA | G19: =+G20+G21+G22+G23 -> 81697917
B20: 3.1 | C20: Suministro y Aplicación de Pintura para exteriores, tipo Koraza, sobre superficies de Fachadas y Muros Externos de los bloques de apartamentos | D20: M2 | E20: 4629.4765 | F20: ='RESUMEN APU'!D28 -> 13527.92 | G20: =+E20*F20 -> 62627188
B21: 3.2 | C21: Suministro y Aplicación de Pintura para exteriores tipo Koraza, en antepechos de terrazas en los primeros pisos de los bloques y en jardineras | D21: M2 | E21: 107.975 | F21: ='RESUMEN APU'!D31 -> 39761.33 | G21: =+E21*F21 -> 4293229.6
B22: 3.3 | C22: Suministro y Aplicación de Pintura para exteriores, tipo Koraza, en elementos volumetricos de superboard en las fachadas | D22: M2 | E22: 455.3 | F22: ='RESUMEN APU'!D35 -> 27373.01 | G22: =+E22*F22 -> 12462931
B23: 3.4 | C23: Suministro y Aplicación de Pintura para exteriores, tipo koraza, color gris basalto, sobre alfajias de escaleras de acceso a los bloques y de areas comunes externas. | D23: ML | E23: 373.99 | F23: ='RESUMEN APU'!D39 -> 6188.85 | G23: =+E23*F23 -> 2314568
B24: PINTURA PARA INTERIORES TIPO VINILO | G24: =+G25 -> 23594430
B25: 3.5 | C25: Suministro y Aplicación de Pintura tipo Vinilo en areas comunes internas de los bloques de aptos: paredes y cielos rasos | D25: M2 | E25: 2157.64 | F25: ='RESUMEN APU'!D41 -> 10935.295 | G25: =+E25*F25 -> 23594430
B26: PINTURA ESMALTE TIPO 3 EN 1 | G26: =+G27+G28+G29+G30 -> 65952302
B27: 3.6 | C27: Suministro y Aplicación de Pintura tipo 3 en 1, en puertas de los apartamentos (estan incluidas las de los exteriores, porteria-motobombas) | D27: UN | E27: 92 | F27: ='RESUMEN APU'!D44 -> 85048.688 | G27: =+E27*F27 -> 7824479.2
B28: 3.7 | C28: Suministro y Aplicación de Pintura para Barandas Metalicas en areas exteriores: gimnasio, pasillos, cuarto de acueducto, piscina, circulacion entre bloques, etc. | D28: ML | E28: 344.25 | F28: ='RESUMEN APU'!D47 -> 10570.313 | G28: =+E28*F28 -> 3638830.1
B29: 3.8 | C29: Suministro y Aplicación de Pintura tipo 3 en 1 en la totalidad de las estructuras metalicas de los parqueaderos externos | D29: M2 | E29: 1306.25 | F29: ='RESUMEN APU'!D50 -> 18901.312 | G29: =+E29*F29 -> 24689839
B30: 3.9 | C30: Suministro y Aplicación de Pintuco Fill sobre las cubiertas de los parqueaderos | D30: M2 | E30: 1306.25 | F30: ='RESUMEN APU'!D53 -> 22812.749 | G30: =+E30*F30 -> 29799154
A31: 4 | C31: TRATAMIENTOS ESPECIALES CONTRA HUMEDADES | G31: =+G32+G33+G34+G35+G36+G37 -> 2.5331236e+08
B32: 4.1 | C32: Cambio Total de Cubiertas | D32: M2 | E32: 1678.12 | F32: ='RESUMEN APU'!D57 -> 87334.337 | G32: =+E32*F32 -> 1.465575e+08
B33: 4.2 | C33: Sellado Perimetral de enchape en terraza del gimnasio | D33: ML | E33: 0 | F33: ='RESUMEN APU'!D65 -> 19547.7 | G33: =+E33*F33 -> 0
B34: 4.3 | C34: Retiro y Reposicion de sello perimetral en elementos vidriados de los bloque de apartamentos (30% DEL TOTAL) | D34: ML | E34: 817.994 | F34: ='RESUMEN APU'!D69 -> 7920.5 | G34: =+E34*F34 -> 6478921.5
B35: 4.4 | C35: Suministro e Instalacion de Cortagoteras en Balcones y Accesos a los bloques de aptos | D35: ML | E35: 1055.3 | F35: ='RESUMEN APU'!D72 -> 42131.25 | G35: =+E35*F35 -> 44461108
B36: 4.5 | C36: Reparacion de morteros en cuchillas de cubierta-(30% DEL TOTAL) | D36: M2 | E36: 290.8665 | F36: ='RESUMEN APU'!D76 -> 36654.188 | G36: =+E36*F36 -> 10661475
B37: 4.6 | C37: Suministro e Instalacion de Alfajias en lamina sobre muros perimetrales y medianeros en las cubiertas | D37: ML | E37: 372 | F37: ='RESUMEN APU'!D79 -> 121380 | G37: =+E37*F37 -> 45153360
A38: 5 | C38: ASEO GENERAL DE OBRA Y RETIRO DE ESCOMBROS | G38: =+G39 -> 0
B39: 5.1 | C39: Aseo General y Retiro de Escombros y Sobrantes | D39: GBL | E39: 0.8 | G39: =+E39*F39 -> 0
D40: TOTAL COSTO DIRECTO | G40: =+G9+G12+G18+G31+G38 -> 5.4212652e+08
...

Sheet COTIZACIÓN valores actualizados
A1: CONDOMINIO PARQUE RESIDENCIAL LOS CEDROS-ARMENIA-Quindío
A2: Cuadro General de Actividades, Unidades de Medida, Cantidades y Precios Unitarios
A3: ANEXO 01-OPCION 2
A4: Proponente: | D4: Levanto Informacion: | F4: Ing. Carlos Alberto Agudelo Restrepo
A5: Interventor: Ing. Luis Fernando Márquez Jaramillo | F5: Arq. Maria Fernanda Morales Palacio
A6: Ubicación Proyecto: Calle 50 Norte # 15-01 | D6: Fecha: Febrero de 2025 | F6: Sra Maria del Pilar Rubio L. Administradora
A7: ACTIVIDADES EN LOS BLOQUES DE APARTAMENTOS Y AREAS COMUNES DE LOS MISMOS
A8: Capitulo | B8: Items | C8: Descripcion de Actividad | D8: Unidad | E8: Cantidad | F8: Vr Unitario | G8: Vr Total
A9: 1 | C9: PRELIMINARES | G9: =+G10+G11 -> 1800000
B10: 1.1 | C10: Campamento de Obra | D10: Gbl | E10: 1 | F10: 1500000 | G10: =+E10*F10 -> 1500000 | H10: X
B11: 1.2 | C11: Señalizacion y Seguridad de la Obra | D11: Gbl | E11: 1 | F11: 300000 | G11: =+E11*F11 -> 300000 | H11: X
A12: 2 | C12: PREPARACION DE SUPERFICIES | G12: =+G13+G14+G15+G16+G17 -> 95735145
B13: 2.1 | C13: Lavado General de Superficies a Intervenir | D13: M2 | E13: 7304.6725 | F13: 3200 | G13: =+E13*F13 -> 23374952 | H13: X
B14: 2.2 | C14: Retiro y Reemplazo de Graniplast Deteriorado en fachadas de las tres torres (26% DEL TOTAL APROX) | D14: M2 | E14: 1205.1154 | F14: 45000 | G14: =+E14*F14 -> 54230193 | H14: X
B15: 2.3 | C15: Reposicion de Mortero en mal estado en fachadas de las tres torres | D15: M2 | E15: 90 | F15: 52000 | G15: =+E15*F15 -> 4680000
B16: 2.4 | C16: Retiro y Reemplazo de Superboard en mal estado en fachadas de las tres torres | D16: M2 | E16: 125 | F16: 74000 | G16: =+E16*F16 -> 9250000 | I16: 5000000
B17: 2.5 | C17: Retiro y Reemplazo de Drywall en mal estado en cielos rasos de fachadas | D17: M2 | E17: 100 | F17: 42000 | G17: =+E17*F17 -> 4200000
A18: 3 | C18: ACABADO Y PINTURA | G18: =+G19+G24+G26 -> 2.1459437e+08
B19: PINTURA PARA EXTERIORES-TIPO KORAZA | G19: =+G20+G21+G22+G23 -> 99452618
B20: 3.1 | C20: Suministro y Aplicación de Pintura para exteriores, tipo Koraza, sobre superficies de Fachadas y Muros Externos de los bloques de apartamentos | D20: M2 | E20: 4629.4765 | F20: 17500 | G20: =+E20*F20 -> 81015839
B21: 3.2 | C21: Suministro y Aplicación de Pintura para exteriores tipo Koraza, en antepechos de terrazas en los primeros pisos de los bloques y en jardineras | D21: M2 | E21: 107.975 | F21: 28000 | G21: =+E21*F21 -> 3023300
B22: 3.3 | C22: Suministro y Aplicación de Pintura para exteriores, tipo Koraza, en elementos volumetricos de superboard en las fachadas | D22: M2 | E22: 455.3 | F22: 27200 | G22: =+E22*F22 -> 12384160
B23: 3.4 | C23: Suministro y Aplicación de Pintura para exteriores, tipo koraza, color gris basalto, sobre alfajias de escaleras de acceso a los bloques y de areas comunes externas. | D23: ML | E23: 373.99 | F23: 8100 | G23: =+E23*F23 -> 3029319
B24: PINTURA PARA INTERIORES TIPO VINILO | G24: =+G25 -> 25891680
B25: 3.5 | C25: Suministro y Aplicación de Pintura tipo Vinilo en areas comunes internas de los bloques de aptos: paredes y cielos rasos | D25: M2 | E25: 2157.64 | F25: 12000 | G25: =+E25*F25 -> 25891680
B26: PINTURA ESMALTE TIPO 3 EN 1 | G26: =+G27+G28+G29+G30 -> 89250075
B27: 3.6 | C27: Suministro y Aplicación de Pintura tipo 3 en 1, en puertas de los apartamentos (estan incluidas las de los exteriores, porteria-motobombas) | D27: UN | E27: 92 | F27: 121000 | G27: =+E27*F27 -> 11132000
B28: 3.7 | C28: Suministro y Aplicación de Pintura para Barandas Metalicas en areas exteriores: gimnasio, pasillos, cuarto de acueducto, piscina, circulacion entre bloques, etc. | D28: ML | E28: 344.25 | F28: 22400 | G28: =+E28*F28 -> 7711200
B29: 3.8 | C29: Suministro y Aplicación de Pintura tipo 3 en 1 en la totalidad de las estructuras metalicas de los parqueaderos externos | D29: M2 | E29: 1306.25 | F29: 24300 | G29: =+E29*F29 -> 31741875
B30: 3.9 | C30: Suministro y Aplicación de Pintuco Fill sobre las cubiertas de los parqueaderos | D30: M2 | E30: 1306.25 | F30: 29600 | G30: =+E30*F30 -> 38665000
A31: 4 | C31: TRATAMIENTOS ESPECIALES CONTRA HUMEDADES | G31: =+G32+G33+G34+G35+G36+G37 -> 2.8155701e+08
B32: 4.1 | C32: Cambio Total de Cubiertas | D32: M2 | E32: 1678.12 | F32: 119000 | G32: =+E32*F32 -> 199696280
B33: 4.2 | C33: Sellado Perimetral de enchape en terraza del gimnasio | D33: ML | E33: 0 | F33: 11300 | G33: =+E33*F33 -> 0
B34: 4.3 | C34: Retiro y Reposicion de sello perimetral en elementos vidriados de los bloque de apartamentos (30% DEL TOTAL) | D34: ML | E34: 817.994 | F34: 5200 | G34: =+E34*F34 -> 4253568.8
B35: 4.4 | C35: Suministro e Instalacion de Cortagoteras en Balcones y Accesos a los bloques de aptos | D35: ML | E35: 1055.3 | F35: 37000 | G35: =+E35*F35 -> 39046100
B36: 4.5 | C36: Reparacion de morteros en cuchillas de cubierta-(30% DEL TOTAL) | D36: M2 | E36: 290.8665 | F36: 52000 | G36: =+E36*F36 -> 15125058
B37: 4.6 | C37: Suministro e Instalacion de Alfajias en lamina sobre muros perimetrales y medianeros en las cubiertas | D37: ML | E37: 372 | F37: 63000 | G37: =+E37*F37 -> 23436000
A38: 5 | C38: ASEO GENERAL DE OBRA Y RETIRO DE ESCOMBROS | G38: =+G39 -> 2300000
B39: 5.1 | C39: Aseo General y Retiro de Escombros y Sobrantes | D39: GBL | E39: 1 | F39: 2300000 | G39: =+E39*F39 -> 2300000
D40: TOTAL COSTO DIRECTO | G40: =+G9+G12+G18+G31+G38 -> 5.9598652e+08
...
