Workbook

Sheet BASE DATOS
A1: CONDOMINIO PARQUE RESIDENCIAL LOS CEDROS
A2: Cuadro General de Actividades, Unidades de Medida, Cantidades y Precios Unitarios
A3: ANEXO 01-OPCION 2
A4: Proponente: | D4: Levanto Informacion: | F4: Ing. Carlos Alberto Agudelo Restrepo
A5: Interventor: Ing. Luis Fernando Márquez Jaramillo | F5: Arq. Maria Fernanda Morales Palacio
A6: Ubicación Proyecto: Calle 50 Norte # 15-01 | D6: Fecha: Febrero de 2025 | F6: Sra Maria del Pilar Rubio L. Administradora
A7: ACTIVIDADES EN LOS BLOQUES DE APARTAMENTOS y AREAS COMUNES DE LOS MISMOS
A8: Capitulo | B8: Items | C8: Descripcion de Actividad | D8: Unidad | E8: Cantidad | F8: Vr Unitario | G8: Vr Total
A9: 1 | C9: PRELIMINARES | G9: =+G10+G11 -> 3132000
B10: 1.1 | C10: Campamento de Obra | D10: Gbl | E10: 1 | F10: 2300000 | G10: 2668000
B11: 1.2 | C11: Señalizacion y Seguridad de la Obra | D11: Gbl | E11: 1 | F11: 400000 | G11: 464000
A12: 2 | C12: PREPARACION DE SUPERFICIES | G12: =+G13+G14+G15+G16+G17 -> 97812522
B13: 2.1 | C13: Lavado General de Superficies a Intervenir | D13: M2 | E13: 7304.6725 | F13: ='RESUMEN APU'!C9 -> 3145.8333 | G13: 26655967
B14: 2.2 | C14: Retiro y Reemplazo de Graniplast Deteriorado en fachadas de las tres torres (26% DEL TOTAL APROX) | D14: M2 | E14: 1205.1154 | F14: ='RESUMEN APU'!C11 -> 36531 | G14: 51067922
B15: 2.3 | C15: Reposicion de Mortero en mal estado en fachadas de las tres torres | D15: M2 | E15: 90 | F15: ='RESUMEN APU'!C16 -> 42975.417 | G15: 4486633.5
B16: 2.4 | C16: Retiro y Reemplazo de Superboard en mal estado en fachadas de las tres torres | D16: M2 | E16: 125 | F16: 74000 | G16: 10730000
B17: 2.5 | C17: Retiro y Reemplazo de Drywall en mal estado en cielos rasos de fachadas | D17: M2 | E17: 100 | F17: 42000 | G17: 4872000
A18: 3 | C18: ACABADO Y PINTURA | G18: =+G19+G24+G26 -> 2.2280263e+08
B19: PINTURA PARA EXTERIORES-TIPO KORAZA | G19: =+G20+G21+G22+G23 -> 1.1155442e+08
B20: 3.1 | C20: Suministro y Aplicación de Pintura para exteriores, tipo Koraza, sobre superficies de Fachadas y Muros Externos de los bloques de apartamentos | D20: M2 | E20: 4629.4765 | F20: ='RESUMEN APU'!C28 -> 16964.1 | G20: 91100487
B21: 3.2 | C21: Suministro y Aplicación de Pintura para exteriores tipo Koraza, en antepechos de terrazas en los primeros pisos de los bloques y en jardineras | D21: M2 | E21: 107.975 | F21: ='RESUMEN APU'!C31 -> 28312.6 | G21: 3546181.5
B22: 3.3 | C22: Suministro y Aplicación de Pintura para exteriores, tipo Koraza, en elementos volumetricos de superboard en las fachadas | D22: M2 | E22: 455.3 | F22: ='RESUMEN APU'!C35 -> 26279.9 | G22: 13879677
B23: 3.4 | C23: Suministro y Aplicación de Pintura para exteriores, tipo koraza, color gris basalto, sobre alfajias de escaleras de acceso a los bloques y de areas comunes externas. | D23: ML | E23: 373.99 | F23: ='APU III'!E125 -> 6979.8889 | G23: 3028074
B24: PINTURA PARA INTERIORES TIPO VINILO | G24: =+G25 -> 30034349
B25: 3.5 | C25: Suministro y Aplicación de Pintura tipo Vinilo en areas comunes internas de los bloques de aptos: paredes y cielos rasos | D25: M2 | E25: 2157.64 | F25: 12000 | G25: 30034349
B26: PINTURA ESMALTE TIPO 3 EN 1 | G26: =+G27+G28+G29+G30+G31 -> 81213860
B27: 3.6 | C27: Suministro y Aplicación de Pintura tipo 3 en 1, en puertas de los apartamentos (estan incluidas las de los exteriores, porteria-motobombas) | D27: UN | E27: 92 | F27: ='APU III'!E188 -> 75548.75 | G27: 8062562.6
B28: 3.7 | C28: Suministro y Aplicación de Pintura para Barandas Metalicas en areas exteriores: gimnasio, pasillos, cuarto de acueducto, piscina, circulacion entre bloques, etc. | D28: ML | E28: 344.25 | F28: 22400 | G28: 8944992
B29: 3.8 | C29: Suministro y Aplicación de Pintura tipo 3 en 1 en la totalidad de las estructuras metalicas de los parqueaderos externos | D29: M2 | E29: 1306.25 | F29: 24300 | G29: 36820575
B30: 3.9 | C30: Suministro y Aplicación de Pintuco Fill sobre las cubiertas de los parqueaderos | D30: M2 | E30: 1306.25 | F30: ='RESUMEN APU'!C53 -> 17353.178 | G30: 26294403
B31: 3.10 | C31: Suministro y Aplicacion de Pintura tipo 3 en 1 sobre rejas metalicas en las terrazas del primer piso | D31: M2 | E31: 42 | F31: 22400 | G31: 1091328
A32: 4 | C32: TRATAMIENTOS ESPECIALES CONTRA HUMEDADES | G32: =SUM(G33:G39) -> 2.345602e+08
B33: 4.1 | C33: Cambio Total de Cubiertas | D33: M2 | E33: 1678.12 | F33: ='RESUMEN APU'!C57 -> 77516.114 | G33: 1.5089436e+08
B34: 4.2 | C34: Sellado Perimetral de enchape en terraza del gimnasio | D34: ML | E34: 0 | F34: ='opc 2 cambio total cubierta (2)'!F34 -> 11300 | G34: 0
B35: 4.3 | C35: Retiro y Reposicion de sello perimetral en elementos vidriados de los bloque de apartamentos (30% DEL TOTAL) | D35: ML | E35: 817.994 | F35: ='opc 2 cambio total cubierta (2)'!F35 -> 5200 | G35: 4934139.8
B36: 4.4 | C36: Suministro e Instalacion de Cortagoteras en Balcones y Accesos a los bloques de aptos | D36: ML | E36: 1055.3 | F36: ='RESUMEN APU'!C73 -> 28876.667 | G36: 35349314
B37: 4.5 | C37: Reparacion de morteros en cuchillas de cubierta-(30% DEL TOTAL) | D37: M2 | E37: 290.8665 | F37: =F15 -> 42975.417 | G37: 14500126
B38: 4.6 | C38: Suministro e Instalacion de Alfajias en lamina sobre muros perimetrales y medianeros en las cubiertas | D38: ML | E38: 372 | F38: ='opc 2 cambio total cubierta (2)'!F38 -> 63000 | G38: 27185760
B39: 4.7 | C39: Impermeabilizacion de tres terrazas sobre los puntos fijos de las escaleras de los bloques | D39: M2 | E39: 65 | F39: 22500 | G39: 1696500
A40: 5 | C40: ASEO GENERAL DE OBRA Y RETIRO DE ESCOMBROS | G40: =+G41 -> 5095985
...

Sheet APU II
A1: CONDOMINIO PARQUE RESIDENCIAL LOS CEDROS
A3: PREPARACIÓN DE SUPERFICIES
A5: ACTIVIDAD: Lavado General de Superficies | D5: ITEM | E5: 1.0
D6: UNIDAD | E6: M2
A7: I. EQUIPOS
A8: DESCRIPCIÓN | B8: UNIDAD | C8: RENDIMIENTO | D8: TARIFA | E8: VALOR - PARCIAL
A9: Herramienta menor | B9: %MO
A10: Equipos Freshouse | B10: Día
A11: Equipo Hidrolavadora | B11: Día
A13: SUB - TOTAL | E13: 854.16667
A14: II. MATERIALES
A15: DESCRIPCIÓN | B15: UNIDAD | C15: CANTIDAD | D15: PRECIO - UNIT | E15: VALOR - PARCIAL
A16: Hipoclorito | B16: GL
A18: Desperdicio 2% | E18: 0
A20: SUB - TOTAL | E20: 500
A21: III. TRANSPORTE
A22: DESCRIPCIÓN | B22: UNIDAD | C22: RENDIMIENTO | D22: TARIFA | E22: VALOR - PARCIAL
A23: Acarreo LUV | B23: Día | C23: 0 | D23: 0 | E23: 0
A25: SUB - TOTAL | E25: =SUM(E23) -> 0
A26: IV. MANO DE OBRA
A27: DESCRIPCIÓN | B27: UNIDAD | C27: RENDIMIENTO | D27: JORNAL | E27: VALOR - PARCIAL
A28: CUADRILLA 1: 1 Oficial y 1 ayudante | B28: Día
A30: SUB - TOTAL | E30: 1791.6667
A32: TOTAL UNITARIO | E32: =SUM(E13,E20,E25,E30) -> 3145.8333
A35: Retiro y Reemplazo de Graniplast Deteriorado | E35: 2.2
A37: ACTIVIDAD: Inspección de superficie incluye rasqueteado | D37: ITEM
D38: UNIDAD | E38: M2
A39: I. EQUIPOS
A40: DESCRIPCIÓN | B40: UNIDAD | C40: RENDIMIENTO | D40: TARIFA | E40: VALOR - PARCIAL
A41: Herramienta menor | B41: %MO
A42: Equipos Freshouse | B42: Día
A44: SUB - TOTAL | E44: 411.11111
A45: II. MATERIALES
A46: DESCRIPCIÓN | B46: UNIDAD | C46: CANTIDAD | D46: PRECIO - UNIT | E46: VALOR - PARCIAL
A48: Desperdicio 2% | E48: 0
A50: SUB - TOTAL | E50: =SUM(E47:E48) -> 0
A51: III. TRANSPORTE
A52: DESCRIPCIÓN | B52: UNIDAD | C52: RENDIMIENTO | D52: TARIFA | E52: VALOR - PARCIAL
A53: Acarreo LUV | B53: Día | C53: 0 | D53: 0 | E53: =D53*C53 -> 0
A55: SUB - TOTAL | E55: =SUM(E53) -> 0
...

Sheet APU III
A1: CONDOMINIO PARQUE RESIDENCIAL LOS CEDROS
A3: ACABADO DE PINTURA
A5: ACTIVIDAD: Suministro y Aplicación de Pintura para exteriores | D5: ITEM | E5: 1.0
D6: UNIDAD | E6: M2
A7: I. EQUIPOS
A8: DESCRIPCIÓN | B8: UNIDAD | C8: RENDIMIENTO | D8: TARIFA | E8: VALOR - PARCIAL
A9: Herramienta menor | B9: %MO
A10: Equipos Freshouse | B10: Día
A12: SUB - TOTAL | E12: 1062.5
A13: II. MATERIALES
A14: DESCRIPCIÓN | B14: UNIDAD | C14: CANTIDAD | D14: PRECIO - UNIT | E14: VALOR - PARCIAL
A15: Koraza Pro 550 | B15: CÑ
A16: Rodillo 9" | B16: Und
A17: Brocha | B17: Und
A18: Protecciones de piso | B18: M2
A20: Desperdicio 2%
A22: SUB - TOTAL | E22: 9651.6
A23: III. TRANSPORTE
A24: DESCRIPCIÓN | B24: UNIDAD | C24: RENDIMIENTO | D24: TARIFA | E24: VALOR - PARCIAL
A25: Acarreo | B25: Día
A27: SUB - TOTAL | E27: 625
A28: IV. MANO DE OBRA
A29: DESCRIPCIÓN | B29: UNIDAD | C29: RENDIMIENTO | D29: JORNAL | E29: VALOR - PARCIAL
A30: CUADRILLA 1: 1 Oficial y 1 ayudante | B30: Día
A32: SUB - TOTAL | E32: 5625
A34: TOTAL UNITARIO | E34: =SUM(E12,E22,E27,E32) -> 16964.1
A37: Reparación de antepechos y jardineras | E37: 2.2
A39: ACTIVIDAD: Aplicación de Aqua Block | D39: ITEM
D40: UNIDAD | E40: M2
A41: I. EQUIPOS
A42: DESCRIPCIÓN | B42: UNIDAD | C42: RENDIMIENTO | D42: TARIFA | E42: VALOR - PARCIAL
A43: Herramienta menor | B43: %MO
A44: Equipos Freshouse | B44: Día
A46: SUB - TOTAL | E46: 600
A47: II. MATERIALES
A48: DESCRIPCIÓN | B48: UNIDAD | C48: CANTIDAD | D48: PRECIO - UNIT | E48: VALOR - PARCIAL
A49: AquaBlock | B49: CÑ | H49: =19/32 -> 0.59375
A51: Desperdicio 2% | E51: 0
A53: SUB - TOTAL | E53: 8623.5
A54: III. TRANSPORTE
...

Sheet APU IV
A1: CONDOMINIO PARQUE RESIDENCIAL LOS CEDROS
A3: Recorrido General de Cubiertas existentes sobre los tres bloques de apartamentos. Se estima una reposicion total de al menos el 25% de la cubierta existente.
A5: ACTIVIDAD: Suministro e instalación de teja de fibrocemento | D5: ITEM | E5: 4.1
D6: UNIDAD | E6: M2
A7: I. EQUIPOS
A8: DESCRIPCIÓN | B8: UNIDAD | C8: RENDIMIENTO | D8: TARIFA | E8: VALOR - PARCIAL
A9: Herramienta menor | B9: %MO | C9: 0.1 | D9: =E30 -> 8800 | E9: =C9*D9 -> 880
A11: SUB - TOTAL | E11: =SUM(E9:E9) -> 880
A12: II. MATERIALES
A13: DESCRIPCIÓN | B13: UNIDAD | C13: CANTIDAD | D13: PRECIO - UNIT | E13: VALOR - PARCIAL
A14: Teja de fibrocemento | B14: Und | C14: 0.4 | D14: 35000 | E14: =C14*D14 -> 14000
A15: Amarras | B15: Und | C15: 4 | D15: 800 | E15: =C15*D15 -> 3200
A16: Ganchos | B16: Und | C16: 2 | D16: 1500 | E16: =C16*D16 -> 3000
A18: Desperdicio 2% | E18: =SUM(E14:E14)*0.02 -> 280
A20: SUB - TOTAL | E20: =SUM(E14:E18) -> 20480
A21: III. TRANSPORTE
A22: DESCRIPCIÓN | B22: UNIDAD | C22: RENDIMIENTO | D22: TARIFA | E22: VALOR - PARCIAL
A23: Acarreo LUV | B23: Día | C23: 0.025 | D23: 60000 | E23: =D23*C23 -> 1500
A25: SUB - TOTAL | E25: =SUM(E23) -> 1500
A26: IV. MANO DE OBRA
A27: DESCRIPCIÓN | B27: UNIDAD | C27: RENDIMIENTO | D27: JORNAL | E27: VALOR - PARCIAL
A28: CUADRILLA 1: 1 Oficial y 1 ayudante | B28: Día | C28: 25 | D28: 220000 | E28: =D28/C28 -> 8800
A30: SUB - TOTAL | E30: =SUM(E28) -> 8800
A32: TOTAL UNITARIO | E32: =SUM(E11,E20,E25,E30) -> 31660
A35: ACTIVIDAD: Desmonte de teja de fibrocemento | D35: ITEM | E35: 4.1
D36: UNIDAD | E36: M2
A37: I. EQUIPOS
A38: DESCRIPCIÓN | B38: UNIDAD | C38: RENDIMIENTO | D38: TARIFA | E38: VALOR - PARCIAL
A39: Herramienta menor | B39: %MO | C39: 0.05 | D39: =E57 -> 6285.7143 | E39: =C39*D39 -> 314.28571
A41: SUB - TOTAL | E41: =SUM(E39:E39) -> 314.28571
A42: II. MATERIALES
A43: DESCRIPCIÓN | B43: UNIDAD | C43: CANTIDAD | D43: PRECIO - UNIT | E43: VALOR - PARCIAL
A45: Desperdicio 2% | E45: 0
A47: SUB - TOTAL | E47: =SUM(E44:E45) -> 0
A48: III. TRANSPORTE
A49: DESCRIPCIÓN | B49: UNIDAD | C49: RENDIMIENTO | D49: TARIFA | E49: VALOR - PARCIAL
A50: Acarreo LUV | B50: Día | C50: 0 | D50: 60000 | E50: =D50*C50 -> 0
A52: SUB - TOTAL | E52: =SUM(E50) -> 0
A53: IV. MANO DE OBRA
A54: DESCRIPCIÓN | B54: UNIDAD | C54: RENDIMIENTO | D54: JORNAL | E54: VALOR - PARCIAL
...

Sheet 2.4 INST. ALFAJÍA
A1: CONDOMINIO PARQUE RESIDENCIAL LOS CEDROS
A3: Suministro e Instalacion de Alfajias en lamina sobre muros perimetrales y medianeros en las cubiertas
A5: ACTIVIDAD: Suministro e Instalacion de Alfajias en lamina sobre muros perimetrales y medianeros en las cubiertas | D5: ITEM
D6: UNIDAD | E6: ML
A7: I. EQUIPOS
A8: DESCRIPCIÓN | B8: UNIDAD | C8: RENDIMIENTO | D8: TARIFA | E8: VALOR - PARCIAL
A9: Herramienta menor | B9: %MO | C9: 0.1 | D9: =E32 -> 18333.333 | E9: =C9*D9 -> 1833.3333
A10: Taladro percutor | B10: Día | C10: 0.06226 | D10: 40000 | E10: =C10*D10 -> 2490.4
A11: Equipos Freshouse | B11: Día | C11: 0.025 | D11: 25000 | E11: =C11*D11 -> 625
A13: SUB - TOTAL | E13: =SUM(E9:E12) -> 4948.7333
A14: II. MATERIALES
A15: DESCRIPCIÓN | B15: UNIDAD | C15: CANTIDAD | D15: PRECIO - UNIT | E15: VALOR - PARCIAL
A16: Alfajía metálica en lámina | B16: ML | C16: 0.35 | D16: 122500 | E16: =C16*D16 -> 42875
A17: Sikaflex Metalforce | B17: Und | C17: 0.31 | D17: 85300 | E17: =C17*D17 -> 26443
A18: Chazos y Tornilleria | B18: GLB | C18: 1 | D18: 5000 | E18: =C18*D18 -> 5000
A20: Desperdicio 2% | E20: 0
A22: SUB - TOTAL | E22: =SUM(E16:E20) -> 74318
A23: III. TRANSPORTE
A24: DESCRIPCIÓN | B24: UNIDAD | C24: RENDIMIENTO | D24: TARIFA | E24: VALOR - PARCIAL
A25: Acarreo LUV | B25: Día | C25: 0.02 | D25: 45000 | E25: =D25*C25 -> 900
A27: SUB - TOTAL | E27: =SUM(E25) -> 900
A28: IV. MANO DE OBRA
A29: DESCRIPCIÓN | B29: UNIDAD | C29: RENDIMIENTO | D29: JORNAL | E29: VALOR - PARCIAL
A30: CUADRILLA 1: 1 Oficial y 1 ayudante | B30: Día | C30: 12 | D30: 220000 | E30: =D30/C30 -> 18333.333
A32: SUB - TOTAL | E32: =SUM(E30) -> 18333.333
A34: TOTAL UNITARIO | E34: =SUM(E13,E22,E27,E32) -> 98500.067

Sheet RESUMEN APU
A1: CONDOMINIO PARQUE RESIDENCIAL LOS CEDROS
A3: ITEM | B3: DESCRIPCIÓN
A4: 1.1 | B4: Campamento de Obra | C4: 1500000
A6: 1.2 | B6: Señalización de Obra | C6: 300000
A8: ITEM | B8: DESCRIPCIÓN | C8: VALOR
A9: 2.1 | B9: Lavado de superficie | C9: ='APU II'!E32 -> 3145.8333
A11: 2.2 | B11: Retiro y Reemplazo de Graniplast Deteriorado | C11: 36531
A12: 2.1.1 | B12: Inspección de superficie incluye rasqueteado
A13: 2.1.2 | B13: Nivelación de superficie con Mortero Listo
A14: 2.1.3 | B14: Aplicación de Graniplast
A16: 2.3 | B16: Reposicion de Mortero en mal estado | C16: ='APU II'!E154 -> 42975.417
B17: Aplicación de revoque impermeabilizado | C17: 0
A19: 2.4 | B19: Retiro y Reemplazo de Superboard | C19: 82379.167
A20: 2.3.1 | B20: Remoción de lámina superboard
A21: 2.3.2 | B21: Restructuración e Instalación de lámina de fibrocemento
A23: 2.5 | B23: Retiro y Reemplazo de lamina Drywall | C23: 54400
A24: 2.3.1 | B24: Remoción de lámina de panel yeso
A25: 2.3.2 | B25: Restructuración e Instalación de lámina de fibrocemento
A27: ITEM | B27: DESCRIPCIÓN
A28: 3.1 | B28: Suministro y Aplicación de Pintura para exteriores | C28: =SUM(C29:C29) -> 16964.1
B29: Suministro y Aplicación de Pintura para exteriores | C29: ='APU III'!E34 -> 16964.1
A31: 3.2 | B31: Suministro y Aplicación de Pintura incluye tratamiento con Aqua Block | C31: 28312.6
B32: Reparación de antepechos y aplicación de Aqua Block
B33: Suministro y Aplicación de Pintura para exteriores
A35: 3.3 | B35: Suministro y Aplicación de Pintura incluye reconstrucción de pendiente | C35: 26279.9
B36: Reconstrucción de pendiente en volumenes
B37: Suministro y Aplicación de Pintura para exteriores
A39: 3.4 | B39: Suministro y Aplicación de Pintura para exteriores alfajías | C39: ='APU III'!E125 -> 6979.8889
A41: 3.5 | B41: Suministro y Aplicación de Pintura para interiores | C41: ='APU III'!E156 -> 11957.067
B42: Suministro y Aplicación de Pintura para interiores
A44: 3.6 | B44: Suministro y Aplicación de Pintura para puertas | C44: ='APU III'!E188 -> 75548.75
B45: Suministro y Aplicación de Pintura para puertas
A47: 3.7 | B47: Suministro y Aplicación de Pintura en barandas | C47: ='APU III'!E220 -> 22462.284
B48: Suministro y Aplicación de Pintura en barandas
A50: 3.8 | B50: Suministro y Aplicación de Pintura estructuras de parqueadero | C50: ='APU III'!E252 -> 24300.7
B51: Suministro y Aplicación de Pintura estructuras de parqueadero
A53: 3.9 | B53: Suministro y Aplicación de Pintura estructuras de parqueadero | C53: ='APU III'!E284 -> 17353.178
B54: Suministro y Aplicación de Pintura en barandas
A56: ITEM | B56: DESCRIPCIÓN | C56: VALOR
A57: 4.1 | B57: Recorrido General de Cubiertas | C57: 77516.114
...

Sheet FAC COMPLETA
A1: CONDOMINIO PARQUE RESIDENCIAL LOS CEDROS
A2: Cuadro General de Actividades, Unidades de Medida, Cantidades y Precios Unitarios
A3: COTIZACIÓN FACHADAS COMPLETAS
A4: Proponente: FRESHOUSE S.A.S | D4: Levanto Informacion: | F4: Ing. Carlos Alberto Agudelo Restrepo
A5: Interventor: Ing. Luis Fernando Márquez Jaramillo | F5: Arq. Maria Fernanda Morales Palacio
A6: Ubicación Proyecto: Calle 50 Norte # 15-01 | D6: Fecha: Febrero de 2025 | F6: Sra Maria del Pilar Rubio L. Administradora
A7: ACTIVIDADES EN LOS BLOQUES DE APARTAMENTOS y AREAS COMUNES DE LOS MISMOS
A8: Capitulo | B8: Items | C8: Descripcion de Actividad | D8: Unidad | E8: Cantidad | F8: Vr Unitario | G8: Vr Total
A9: 1 | C9: PRELIMINARES | G9: =+G10+G11 -> 0
B10: 1.1 | C10: Campamento de Obra | D10: Gbl | E10: 1 | F10: 0 | G10: =+E10*F10 -> 0
B11: 1.2 | C11: Señalizacion y Seguridad de la Obra | D11: Gbl | E11: 1 | F11: 0 | G11: =+E11*F11 -> 0
A12: 2 | C12: PREPARACION DE SUPERFICIES | G12: =+G13+G14+G15+G16+G17 -> 72216140
B13: 2.1 | C13: Lavado General de Superficies a Intervenir | D13: M2 | E13: 7304.6725 | F13: ='BASE DATOS'!F13 -> 3145.8333 | G13: =+E13*F13 -> 22979282
B14: 2.2 | C14: Retiro y Reemplazo de Graniplast Deteriorado en fachadas de las tres torres (26% DEL TOTAL APROX) | D14: M2 | E14: 1205.1154 | F14: ='BASE DATOS'!F14 -> 36531 | G14: =+E14*F14 -> 44024070 | H14: =200/7 -> 28.571429 | I14: =H14*80000 -> 2285714.3
B15: 2.3 | C15: Reposicion de Mortero en mal estado en fachadas de las tres torres | D15: M2 | E15: 90 | F15: ='BASE DATOS'!F15 -> 42975.417 | G15: =+E15*F15 -> 3867787.5
B16: 2.4 | C16: Retiro y Reemplazo de Superboard en mal estado en fachadas de las tres torres | D16: M2 | E16: =125*0.1 -> 12.5 | F16: ='BASE DATOS'!F16 -> 74000 | G16: =+E16*F16 -> 925000
B17: 2.5 | C17: Retiro y Reemplazo de Drywall en mal estado en cielos rasos de fachadas | D17: M2 | E17: =100*0.1 -> 10 | F17: ='BASE DATOS'!F17 -> 42000 | G17: =+E17*F17 -> 420000
A18: 3 | C18: ACABADO Y PINTURA | G18: =+G19+G24+G26 -> 90500141
B19: PINTURA PARA EXTERIORES-TIPO KORAZA | G19: =SUM(G20:G23) -> 90500141
B20: 3.1 | C20: Suministro y Aplicación de Pintura para exteriores, tipo Koraza, sobre superficies de Fachadas y Muros Externos de los bloques de apartamentos | D20: M2 | E20: 4629.4765 | F20: ='BASE DATOS'!F20 -> 16964.1 | G20: =+E20*F20 -> 78534902
B21: 3.2 | C21: Suministro y Aplicación de Pintura para exteriores tipo Koraza, en antepechos de terrazas en los primeros pisos de los bloques y en jardineras | D21: M2 | E21: 107.975 | F21: 0 | G21: =+E21*F21 -> 0
B22: 3.3 | C22: Suministro y Aplicación de Pintura para exteriores, tipo Koraza, en elementos volumetricos de superboard en las fachadas | D22: M2 | E22: 455.3 | F22: ='BASE DATOS'!F22 -> 26279.9 | G22: =+E22*F22 -> 11965238 | J22: =2412332+194984 -> 2607316
B23: 3.4 | C23: Suministro y Aplicación de Pintura para exteriores, tipo koraza, color gris basalto, sobre alfajias de escaleras de acceso a los bloques y de areas comunes externas. | D23: ML | E23: 373.99 | F23: 0 | G23: =+E23*F23 -> 0
B24: PINTURA PARA INTERIORES TIPO VINILO | G24: =+G25 -> 0
B25: 3.5 | C25: Suministro y Aplicación de Pintura tipo Vinilo en areas comunes internas de los bloques de aptos: paredes y cielos rasos | D25: M2 | E25: 2157.64 | F25: 0 | G25: =+E25*F25 -> 0 | L25: Koraza Pro 550 | N25: 37669720
B26: PINTURA ESMALTE TIPO 3 EN 1 | G26: =SUM(G27:G28) -> 0 | L26: Mortero acrílico | N26: 4557000
B27: 3.6 | C27: Suministro y Aplicación de Pintura tipo 3 en 1, en puertas de los apartamentos (estan incluidas las de los exteriores, porteria-motobombas) | D27: UN | E27: 92 | F27: 0 | G27: =+E27*F27 -> 0 | L27: Lámina galvanizada y alfajías metálicas | N27: 20153100
B28: 3.10 | C28: Suministro y Aplicacion de Pintura tipo 3 en 1 sobre rejas metalicas en las terrazas del primer piso | D28: M2 | E28: 42 | F28: 0 | G28: =+E28*F28 -> 0 | L28: Material cortagoteras de balcones | N28: 13849466
A29: 4 | C29: TRATAMIENTOS ESPECIALES CONTRA HUMEDADES | G29: =SUM(G30:G32) -> 36189615 | L29: Material textura Graniplast | N29: 2285714
B30: 4.3 | C30: Retiro y Reposicion de sello perimetral en elementos vidriados de los bloque de apartamentos (30% DEL TOTAL) | D30: ML | E30: 817.994 | F30: ='BASE DATOS'!F35 -> 5200 | G30: =+E30*F30 -> 4253568.8 | L30: Mano de obra y seguridad social | N30: 22440000
B31: 4.4 | C31: Suministro e Instalacion de Cortagoteras en Balcones y Accesos a los bloques de aptos | D31: ML | E31: 1055.3 | F31: ='BASE DATOS'!F36 -> 28876.667 | G31: =+E31*F31 -> 30473546 | H31: =E31/6 -> 175.88333 | I31: =H31*56000 -> 9849466.7 | L31: Transporte de materiales y campamento | N31: 4000000
B32: 4.7 | C32: Impermeabilizacion de tres terrazas sobre los puntos fijos de las escaleras de los bloques | D32: M2 | E32: 65 | F32: ='BASE DATOS'!F39 -> 22500 | G32: =+E32*F32 -> 1462500 | I32: =13849466/E31 -> 13123.724 | L32: Señalización de obra | N32: 2500000
A33: 5 | C33: ASEO GENERAL DE OBRA Y RETIRO DE ESCOMBROS | G33: =+G34 -> 1550000 | L33: Pago de Polizas | N33: 2607316
B34: 5.1 | C34: Aseo General y Retiro de Escombros y Sobrantes | D34: GBL | E34: 1 | F34: 1550000 | G34: =+E34*F34 -> 1550000 | N34: =SUM(N25:N33) -> 110062316
N35: =N34*0.05 -> 5503115.8
D36: TOTAL COSTO DIRECTO | G36: =+G9+G12+G18+G29+G33 -> 2.004559e+08 | N36: =N35+N34 -> 1.1556543e+08
D37: ADMINISTRACION | F37: 0.08 | G37: =+$G$36*F37 -> 16036472
D38: IMPREVISTOS | F38: 0.03 | G38: =+$G$36*F38 -> 6013676.9
D39: UTILIDAD | F39: 0.05 | G39: =+$G$36*F39 -> 10022795
D40: IVA/U | F40: 0.19 | G40: =+G39*F40 -> 1904331
...

Sheet PROCEDIMIENTO
A1: ACTIVIDAD | B1: DESCRIPCION | C1: MATERIALES | D1: UNIDAD | E1: CANTIDAD
A2: LAVADO | B2: - Lavado con cepillo e hidrolavadora - Aplicación de hipoclorito al 10% - Retiro de material suelto | C2: - hipoclorito - Hidrolavadora (empaques, mangera, pistola, extensión) - Espatula | D2: M2 | E2: 7305
A3: SELLO | B3: - Sello perimetral | C3: - Soudaflex | D3: ML | E3: 818
A4: MORTERO | B4: - Aplicación de mortero o Morterolisto Impadoc | C4: - Morterolisto Impadoc o mortero 3:1 | D4: M2 | E4: 90
A5: GRANIPLAST | B5: - Aplicación de Graniplast (Paños que sean lo mas completos posibles sin ser innecesarios) | C5: - Graniplast premium pintuco o Pannelton | D5: M2 | E5: 1205
A6: SUPERBOARD | B6: - Retiro de superboard en mal estado - Cambio o ajuste de estructura de ser necesario - Reemplazo de superboard 8mm - Tratamiento de juntas - SE DEBE DE REEMPLAZAR LAS LAMINAS DE DRYWALL QUE HAY EXPUESTAS A HUMEDAD EXCESIVA POR SUPERBOARD ( CONCRETAR CON INTERVENTOR) | C6: - Superboard 8mm - Soudaflex - Es posible que se necesiten Omegas y Viguetas | D6: M2 | E6: 125
A7: DRYWALL | B7: - Retiro de drywall en mal estado - Cambio o ajuste de estructura de ser necesario - Reemplazo de drywall 8mm - Tratamiento de juntas | C7: - Drywall 8mm - Soudaflex - Es posible que se necesiten Omegas y Viguetas | D7: M2 | E7: 100
A8: PINTURA FACHADAS | B8: - Aplicación de Pintura Koraza pro 550 | C8: - Koraza pro 550 - Rodillo y brocha | D8: M2 | E8: 4629
A9: RECONTRUCCIÓN DE PENDIENTES VOLUMENES + PINTURA | B9: - Reconstruccion de pendientes en volumenes donde sea necesario con Morterolisto Impadoc y acabado liso - Aplicación de Pintucofill 7 - Aplicación de Pintura Koraza pro 550 | C9: - Mortero Listo - Pintucofill 7 - Koraza pro 550 - Rodillo y brocha | D9: M2 | E9: 455
A10: PINTURA ALFAJIAS CONCRETO | B10: - Tratamiento de alfajias - Aplicación de Pintura koraza pro 550 gris basalto | C10: - Koraza pro 550 gris basalto - Rodillo y brocha | D10: ML | E10: 374
A11: PINTURA INTERIORES | B11: - Resane - Aplicación de viniltex pro 450 | C11: - estuco y mastic - Viniltex pro 450 - Rodillo y brocha | D11: M2 | E11: 2158
A12: PINTURA PUERTAS | B12: - Aplicación de esmalte domestico en marcos y naves de las puertas - Aplicación de Pintulux 3 en 1 en Puertas de porteria y cuarto motobombas | C12: - Esmalte Domestico - Pintulux 3 en 1 | D12: UND | E12: 92
A13: PINTURA BARANDAS | B13: - Lijado y aplicación de corrotec donde sea necesario - Aplicación de Pintulux 3 en 1 | C13: - Pintulux 3 en 1 - Es posible que se necesite Correct y lijas | D13: ML | E13: 344
... A15: PINTURA CUBIERTA PARQUEADEROS | B15: - Limpieza - Revisión y sello de anclajes - Aplicación de Pintucofill 7 | C15: - Soudaflex o tornillos con sello - Pintucofill 7 | D15: M2 | E15: 1306
A16: CAMBIO DE CUBIERTA | D16: M2 | E16: 1678
A17: CORTAGOTERAS BALCONES | B17: - Instalación de angulo aluminio calibre 16 1,5"*1,5" - Sello entre pared y angulo con Soudaflex - Aplicación Pintura koraza Pro 550 | C17: - Angulo y tornillos - taladro percutor - Soudaflex - Pintura Koraza pro 550 | D17: ML | E17: 1055
A18: REPARACIÓN CUCHILLAS DE CUBIERTA | B18: - Retiro de material - Aplicación de morterolisto impadoc o mortero 1:3 - Imprimación - Aplicación Pintura Koraza pro 550 | C18: - Morterolisto Impadoc o mortero 3:1 - Acronal -Koraza pro 550 | D18: M2 | E18: 291
A19: ALFAJIAS METALICAS | B19: - Retiro de alfajias existentes en superboard - Instalacion de alfajia en lamina galvanizada cal 24 con chazos de 3/8" - Sello de traslapo entre alfajias con SIKAFLEX METALFORCE - sello entre muro y alfajia con SIKAFLEX METAL FORCE | C19: - Alfajias en lamina galvanizada - SIKAFLEX METALFORCE (Revisar contratipos) | D19: M2 | E19: 372
A20: PINTURA TERRAZAS Y JARDINERAS | B20: - Resane - Aplicación de Pintura Aquablock Ultra de Pintuco - Aplicación de koraza pro 550 gris basalto | C20: - Graniplast premium pintuco o Pannelton - Aquablock ultra - Koraza pro 550 | D20: M2 | E20: 108

Sheet CUBIERTA
A1: CONDOMINIO PARQUE RESIDENCIAL LOS CEDROS
A2: Cuadro General de Actividades, Unidades de Medida, Cantidades y Precios Unitarios
A3: COTIZACIÓN DE REEMPLAZO DE CUBIERTA
A4: Proponente: FRESHOUSE S.A.S. | D4: Levanto Informacion: | F4: Ing. Carlos Alberto Agudelo Restrepo
A5: Interventor: Ing. Luis Fernando Márquez Jaramillo | F5: Arq. Maria Fernanda Morales Palacio
A6: Ubicación Proyecto: Calle 50 Norte # 15-01 | D6: Fecha: Febrero de 2025 | F6: Sra Maria del Pilar Rubio L. Administradora
A7: ACTIVIDADES EN LOS BLOQUES DE APARTAMENTOS y AREAS COMUNES DE LOS MISMOS
A8: Capitulo | B8: Items | C8: Descripcion de Actividad | D8: Unidad | E8: Cantidad | F8: Vr Unitario | G8: Vr Total
A9: 1 | C9: PRELIMINARES | G9: =SUM(G10:G11) -> 360000
B10: 1.1 | C10: Campamento de Obra | D10: Gbl | E10: 0.2 | F10: 1500000 | G10: =+E10*F10 -> 300000
B11: 1.2 | C11: Señalizacion y Seguridad de la Obra | D11: Gbl | E11: 0.2 | F11: 300000 | G11: =+E11*F11 -> 60000
A12: 2 | C12: MANTENIMIENTO DE CUBIERTAS | G12: =SUM(G13:G15) -> 1.7732139e+08
B13: 2.1 | C13: Cambio Total de Cubiertas | D13: M2 | E13: 1678.12 | F13: 77500 | G13: =+E13*F13 -> 1.300543e+08
B14: 2.3 | C14: Reparacion de morteros en cuchillas de cubierta-(30% DEL TOTAL) | D14: M2 | E14: 290.8665 | F14: ='[1]RESUMEN APU'!C77 -> 36529.104 | G14: =+E14*F14 -> 10625093
B15: 2.4 | C15: Suministro e Instalacion de Alfajias en lamina sobre muros perimetrales y medianeros en las cubiertas | D15: ML | E15: 372 | F15: ='[1]RESUMEN APU'!C80 -> 98500 | G15: =+E15*F15 -> 36642000 | H15: =G15*0.55 -> 20153100 | I15: =H15/E15 -> 54175
A16: 5 | C16: ASEO GENERAL DE OBRA Y RETIRO DE ESCOMBROS | G16: =+G17 -> 500000
B17: 5.1 | C17: Aseo General y Retiro de Escombros y Sobrantes | D17: GBL | E17: 0.2 | F17: 2500000 | G17: =+E17*F17 -> 500000
D19: TOTAL COSTO DIRECTO | G19: =+G9+G12+G16 -> 1.7818139e+08
D20: ADMINISTRACION | F20: 0.08 | G20: =+$G$19*F20 -> 14254511
D21: IMPREVISTOS | F21: 0.03 | G21: =+$G$19*F21 -> 5345441.8
D22: UTILIDAD | F22: 0.05 | G22: =+$G$19*F22 -> 8909069.6
D23: IVA/U | F23: 0.19 | G23: =+G22*F23 -> 1692723.2
D24: COSTO TOTAL | G24: =+G19+G20+G21+G22+G23 -> 2.0838314e+08

Sheet CUBIERTA 2
A1: CONDOMINIO PARQUE RESIDENCIAL LOS CEDROS
A2: Cuadro General de Actividades, Unidades de Medida, Cantidades y Precios Unitarios
A3: COTIZACIÓN DE RECORRIDO DE CUBIERTA
A4: Proponente: FRESHOUSE S.A.S. | D4: Levanto Informacion: | F4: Ing. Carlos Alberto Agudelo Restrepo
A5: Interventor: Ing. Luis Fernando Márquez Jaramillo | F5: Arq. Maria Fernanda Morales Palacio
A6: Ubicación Proyecto: Calle 50 Norte # 15-01 | D6: Fecha: Febrero de 2025 | F6: Sra Maria del Pilar Rubio L. Administradora
A7: ACTIVIDADES EN LOS BLOQUES DE APARTAMENTOS y AREAS COMUNES DE LOS MISMOS
A8: Capitulo | B8: Items | C8: Descripcion de Actividad | D8: Unidad | E8: Cantidad | F8: Vr Unitario | G8: Vr Total
A9: 1 | C9: PRELIMINARES | G9: =SUM(G10:G11) -> 360000
B10: 1.1 | C10: Campamento de Obra | D10: Gbl | E10: 0.2 | F10: 1500000 | G10: =+E10*F10 -> 300000
B11: 1.2 | C11: Señalizacion y Seguridad de la Obra | D11: Gbl | E11: 0.2 | F11: 300000 | G11: =+E11*F11 -> 60000
A12: 2 | C12: MANTENIMIENTO DE CUBIERTAS | G12: =SUM(G13:G15) -> 1.1103565e+08
B13: 2.1 | C13: Recorrido de Cubiertas (Reemplazo de tejas en mal estado) | D13: M2 | E13: 1678.12 | F13: 38000 | G13: =+E13*F13 -> 63768560
B14: 2.3 | C14: Reparacion de morteros en cuchillas de cubierta-(30% DEL TOTAL) | D14: M2 | E14: 290.8665 | F14: ='[1]RESUMEN APU'!C77 -> 36529.104 | G14: =+E14*F14 -> 10625093
B15: 2.4 | C15: Suministro e Instalacion de Alfajias en lamina sobre muros perimetrales y medianeros en las cubiertas | D15: ML | E15: 372 | F15: ='[1]RESUMEN APU'!C80 -> 98500 | G15: =+E15*F15 -> 36642000
A16: 5 | C16: ASEO GENERAL DE OBRA Y RETIRO DE ESCOMBROS | G16: =+G17 -> 500000
B17: 5.1 | C17: Aseo General y Retiro de Escombros y Sobrantes | D17: GBL | E17: 0.2 | F17: 2500000 | G17: =+E17*F17 -> 500000
D19: TOTAL COSTO DIRECTO | G19: =+G9+G12+G16 -> 1.1189565e+08
D20: ADMINISTRACION | F20: 0.08 | G20: =+$G$19*F20 -> 8951652.2
D21: IMPREVISTOS | F21: 0.03 | G21: =+$G$19*F21 -> 3356869.6
D22: UTILIDAD | F22: 0.05 | G22: =+$G$19*F22 -> 5594782.6
D23: IVA/U | F23: 0.19 | G23: =+G22*F23 -> 1063008.7
D24: COSTO TOTAL | G24: =+G19+G20+G21+G22+G23 -> 1.3086197e+08

Sheet INTERIORES
A1: CONDOMINIO PARQUE RESIDENCIAL LOS CEDROS
A2: Cuadro General de Actividades, Unidades de Medida, Cantidades y Precios Unitarios
A3: COTIZACIÓN PINTURA EN INTERIORES DE TORRES
A4: Proponente: | D4: Levanto Informacion: | F4: Ing. Carlos Alberto Agudelo Restrepo
A5: Interventor: Ing. Luis Fernando Márquez Jaramillo | F5: Arq. Maria Fernanda Morales Palacio
A6: Ubicación Proyecto: Calle 50 Norte # 15-01 | D6: Fecha: Febrero de 2025 | F6: Sra Maria del Pilar Rubio L. Administradora
A7: ACTIVIDADES EN LOS BLOQUES DE APARTAMENTOS y AREAS COMUNES DE LOS MISMOS
A8: Capitulo | B8: Items | C8: Descripcion de Actividad | D8: Unidad | E8: Cantidad | F8: Vr Unitario | G8: Vr Total
A9: 1 | C9: PRELIMINARES | G9: =+G10+G11 -> 360000
B10: 1.1 | C10: Campamento de Obra | D10: Gbl | E10: 0.2 | F10: 1500000 | G10: =+E10*F10 -> 300000
B11: 1.2 | C11: Señalizacion y Seguridad de la Obra | D11: Gbl | E11: 0.2 | F11: 300000 | G11: =+E11*F11 -> 60000
A12: 2 | C12: ACABADO Y PINTURA | G12: =SUM(G13) -> 29965089
B13: 2.1 | C13: Suministro y Aplicación de Pintura tipo Vinilo en areas comunes internas de los bloques de aptos: paredes y cielos rasos | D13: M2 | E13: 2157.64 | F13: ='[1]RESUMEN APU'!C41 -> 13887.9 | G13: =+E13*F13 -> 29965089
A14: 3 | C14: ASEO GENERAL DE OBRA Y RETIRO DE ESCOMBROS | G14: =+G15 -> 500000
B15: 3.1 | C15: Aseo General y Retiro de Escombros y Sobrantes | D15: GBL | E15: 0.2 | F15: 2500000 | G15: =+E15*F15 -> 500000
D17: TOTAL COSTO DIRECTO | G17: =+G9+G12+G14 -> 30825089
D18: ADMINISTRACION | F18: 0.08 | G18: =+$G$17*F18 -> 2466007.1
D19: IMPREVISTOS | F19: 0.03 | G19: =+$G$17*F19 -> 924752.66
D20: UTILIDAD | F20: 0.05 | G20: =+$G$17*F20 -> 1541254.4
D21: IVA/U | F21: 0.19 | G21: =+G20*F21 -> 292838.34
D22: COSTO TOTAL | G22: =+G17+G18+G19+G20+G21 -> 36049941

Sheet PARQUEADEROS
A1: CONDOMINIO PARQUE RESIDENCIAL LOS CEDROS
A2: Cuadro General de Actividades, Unidades de Medida, Cantidades y Precios Unitarios
A3: COTIZACIÓN MATENIMIENTO DE PARQUEADEROS
A4: Proponente: | D4: Levanto Informacion: | F4: Ing. Carlos Alberto Agudelo Restrepo
A5: Interventor: Ing. Luis Fernando Márquez Jaramillo | F5: Arq. Maria Fernanda Morales Palacio
A6: Ubicación Proyecto: Calle 50 Norte # 15-01 | D6: Fecha: Febrero de 2025 | F6: Sra Maria del Pilar Rubio L. Administradora
A7: ACTIVIDADES EN LOS BLOQUES DE APARTAMENTOS y AREAS COMUNES DE LOS MISMOS
A8: Capitulo | B8: Items | C8: Descripcion de Actividad | D8: Unidad | E8: Cantidad | F8: Vr Unitario | G8: Vr Total
A9: 1 | C9: PRELIMINARES | G9: =+G10+G11 -> 1800000
B10: 1.1 | C10: Campamento de Obra | D10: Gbl | E10: 1 | F10: ='RESUMEN APU'!C4 -> 1500000 | G10: =+E10*F10 -> 1500000
B11: 1.2 | C11: Señalizacion y Seguridad de la Obra | D11: Gbl | E11: 1 | F11: ='RESUMEN APU'!C6 -> 300000 | G11: =+E11*F11 -> 300000
A12: 2 | C12: ACABADO Y PINTURA | G12: =SUM(G13:G14) -> 54409463
B13: 2.1 | C13: Suministro y Aplicación de Pintura tipo 3 en 1 en la totalidad de las estructuras metalicas de los parqueaderos externos | D13: M2 | E13: 1306.25 | F13: 24300 | G13: =+E13*F13 -> 31741875
B14: 2.2 | C14: Suministro y Aplicación de Pintuco Fill sobre las cubiertas de los parqueaderos | D14: M2 | E14: 1306.25 | F14: ='RESUMEN APU'!C53 -> 17353.178 | G14: =+E14*F14 -> 22667588
A15: 3 | C15: ASEO GENERAL DE OBRA Y RETIRO DE ESCOMBROS | G15: =+G16 -> 1550000
B16: 3.1 | C16: Aseo General y Retiro de Escombros y Sobrantes | D16: GBL | E16: 1 | F16: 1550000 | G16: =+E16*F16 -> 1550000
D18: TOTAL COSTO DIRECTO | G18: =+G9+G12+G15 -> 57759463
D19: ADMINISTRACION | F19: 0.08 | G19: =+$G$18*F19 -> 4620757.1
D20: IMPREVISTOS | F20: 0.03 | G20: =+$G$18*F20 -> 1732783.9
D21: UTILIDAD | F21: 0.05 | G21: =+$G$18*F21 -> 2887973.2
D22: IVA/U | F22: 0.19 | G22: =+G21*F22 -> 548714.9
D23: COSTO TOTAL | G23: =+G18+G19+G20+G21+G22 -> 67549693
G27: 5.8807737e+08
F28: 0.07 | G28: =G27*F28 -> 41165416
G29: =G28+G27 -> 629242782

Sheet envio zona social
A1: CONDOMINIO PARQUE RESIDENCIAL LOS CEDROS-ARMENIA-Quindío
A2: Cuadro General de Actividades, Unidades de Medida, Cantidades y Precios Unitarios
A3: ANEXO 01-OPCION 3
A4: Proponente: Fresh House S.A.S | D4: Levanto Informacion: | F4: Ing. Carlos Alberto Agudelo Restrepo
A5: Interventor: Ing. Luis Fernando Márquez Jaramillo | F5: Arq. Maria Fernanda Morales Palacio
A6: Ubicación Proyecto: Calle 50 Norte # 15-01 | D6: Fecha: Abril 11 | F6: Sra Maria del Pilar Rubio L. Administradora
A7: ACTIVIDADES EN AREAS COMUNES
A8: Capitulo | B8: Items | C8: Descripcion de Actividad | D8: Unidad | E8: Cantidad | F8: Vr Unitario | G8: Vr Total
A9: 1 | C9: PRELIMINARES | G9: =+G10+G11 -> 360000
B10: 1.1 | C10: Campamento de Obra | D10: Gbl | E10: 0.2 | F10: 1500000 | G10: =E10*F10 -> 300000
B11: 1.2 | C11: Señalizacion y Seguridad de la Obra | D11: Gbl | E11: 0.2 | F11: 300000 | G11: =E11*F11 -> 60000
A12: 2 | C12: PREPARACION DE SUPERFICIES | G12: =+G13+G14+G15+G16 -> 10704600
B13: 2.1 | C13: Lavado General de Superficies a Intervenir | D13: M2 | E13: 580 | F13: 3120 | G13: =E13*F13 -> 1809600
B14: 2.2 | C14: Retiro y Reemplazo de Graniplast Deteriorado en fachadas de las areas comunes (26% DEL TOTAL APROX) | D14: M2 | E14: 145 | F14: 45000 | G14: =E14*F14 -> 6525000
B15: 2.3 | C15: Reposicion de Mortero en mal estado en fachadas de las AREAS COMUNES | D15: M2 | E15: 10 | F15: 52000 | G15: =E15*F15 -> 520000
B16: 2.4 | C16: Retiro y Reemplazo de Superboard en mal estado en fachadas de las AREAS COMUNES | D16: M2 | E16: 25 | F16: 74000 | G16: =E16*F16 -> 1850000
A17: 3 | C17: ACABADO Y PINTURA | G17: =+G19+G21+G23+G24 -> 17585800
B18: PINTURA PARA EXTERIORES-TIPO KORAZA
B19: 3.1 | C19: Suministro y Aplicación de Pintura para exteriores, tipo Koraza, sobre superficies de Fachadas y Muros Externos de Las areas comunes | D19: M2 | E19: 580 | F19: 17500 | G19: =E19*F19 -> 10150000
B20: PINTURA PARA INTERIORES TIPO VINILO
B21: 3.5 | C21: Suministro y Aplicación de Pintura tipo Vinilo en areas comunes internas : paredes y cielos rasos | D21: M2 | E21: 200 | F21: 12000 | G21: =E21*F21 -> 2400000
B22: PINTURA ESMALTE TIPO 3 EN 1
B23: 3.6 | C23: Suministro y Aplicación de Pintura tipo 3 en 1, en puertas de porteria-motobombas | D23: UN | E23: 7 | F23: 121000 | G23: =E23*F23 -> 847000
B24: 3.7 | C24: Suministro y Aplicación de Pintura para Barandas Metalicas en areas exteriores: gimnasio, pasillos, cuarto de acueducto, piscina | D24: ML | E24: 187 | F24: 22400 | G24: =E24*F24 -> 4188800
A25: 4 | C25: TRATAMIENTOS ESPECIALES CONTRA HUMEDADES y | G25: =+G26+G27+G28 -> 2350600
B26: 4.2 | C26: Sellado Perimetral de enchape en terraza del gimnasio | D26: ML | E26: 49 | F26: 11300 | G26: =+E26*F26 -> 553700
B27: 4.3 | C27: Retiro y Reposicion de sello perimetral en elementos vidriados (30% DEL TOTAL) | D27: ML | E27: 100 | F27: 5200 | G27: =+E27*F27 -> 520000
B28: 4.4 | C28: Recorrido al enchape de la terraza sobre el gimnasio: revision y reemplazo general del emboquillado de todo el piso y sellado de juntas perimetrales. | D28: M2 | E28: 113 | F28: 11300 | G28: =F28*E28 -> 1276900
A29: 5 | C29: ASEO GENERAL DE OBRA Y RETIRO DE ESCOMBROS | G29: =+G30 -> 400000
B30: 5.1 | C30: Aseo General y Retiro de Escombros y Sobrantes | D30: GBL | E30: 0.8 | F30: 500000 | G30: =E30*F30 -> 400000
D31: TOTAL COSTO DIRECTO | G31: =+G9+G12+G17+G25+G29 -> 31401000
D32: ADMINISTRACION | F32: 0.08 | G32: =+$G$31*F32 -> 2512080
D33: IMPREVISTOS | F33: 0.03 | G33: =+$G$31*F33 -> 942030
D34: UTILIDAD | F34: 0.05 | G34: =+$G$31*F34 -> 1570050
D35: IVA/U | F35: 0.19 | G35: =+G34*F35 -> 298309.5
D36: COSTO TOTAL | G36: =+G31+G32+G33+G34+G35 -> 36723470

Sheet opc 2 cambio total cubierta (2)
A1: CONDOMINIO PARQUE RESIDENCIAL LOS CEDROS-ARMENIA-Quindío
A2: Cuadro General de Actividades, Unidades de Medida, Cantidades y Precios Unitarios
A3: ANEXO 01-OPCION 2
A4: Proponente: Fresh House S.A.S | D4: Levanto Informacion: | F4: Ing. Carlos Alberto Agudelo Restrepo
A5: Interventor: Ing. Luis Fernando Márquez Jaramillo | F5: Arq. Maria Fernanda Morales Palacio
A6: Ubicación Proyecto: Calle 50 Norte # 15-01 | D6: Fecha: Abril 11 | F6: Sra Maria del Pilar Rubio L. Administradora
A7: ACTIVIDADES EN LOS BLOQUES DE APARTAMENTOS y AREAS COMUNES DE LOS MISMOS
A8: Capitulo | B8: Items | C8: Descripcion de Actividad | D8: Unidad | E8: Cantidad | F8: Vr Unitario | G8: Vr Total
A9: 1 | C9: PRELIMINARES | G9: =+G10+G11 -> 1800000
B10: 1.1 | C10: Campamento de Obra | D10: Gbl | E10: 1 | F10: 1500000 | G10: =+E10*F10 -> 1500000
B11: 1.2 | C11: Señalizacion y Seguridad de la Obra | D11: Gbl | E11: 1 | F11: 300000 | G11: =+E11*F11 -> 300000
A12: 2 | C12: PREPARACION DE SUPERFICIES | G12: =+G13+G14+G15+G16+G17 -> 95150771
B13: 2.1 | C13: Lavado General de Superficies a Intervenir | D13: M2 | E13: 7304.6725 | F13: 3120 | G13: =+E13*F13 -> 22790578
B14: 2.2 | C14: Retiro y Reemplazo de Graniplast Deteriorado en fachadas de las tres torres (26% DEL TOTAL APROX) | D14: M2 | E14: 1205.1154 | F14: 45000 | G14: =+E14*F14 -> 54230193
B15: 2.3 | C15: Reposicion de Mortero en mal estado en fachadas de las tres torres | D15: M2 | E15: 90 | F15: 52000 | G15: =+E15*F15 -> 4680000
B16: 2.4 | C16: Retiro y Reemplazo de Superboard en mal estado en fachadas de las tres torres | D16: M2 | E16: 125 | F16: 74000 | G16: =+E16*F16 -> 9250000
B17: 2.5 | C17: Retiro y Reemplazo de Drywall en mal estado en cielos rasos de fachadas | D17: M2 | E17: 100 | F17: 42000 | G17: =+E17*F17 -> 4200000
A18: 3 | C18: ACABADO Y PINTURA | G18: =+G19+G24+G26 -> 2.1553517e+08
B19: PINTURA PARA EXTERIORES-TIPO KORAZA | G19: =+G20+G21+G22+G23 -> 99452618
B20: 3.1 | C20: Suministro y Aplicación de Pintura para exteriores, tipo Koraza, sobre superficies de Fachadas y Muros Externos de los bloques de apartamentos | D20: M2 | E20: 4629.4765 | F20: 17500 | G20: =+E20*F20 -> 81015839 | I20: =E20*17000 -> 78701101 | J20: =G20-I20 -> 2314738.2
B21: 3.2 | C21: Suministro y Aplicación de Pintura para exteriores tipo Koraza, en antepechos de terrazas en los primeros pisos de los bloques y en jardineras | D21: M2 | E21: 107.975 | F21: 28000 | G21: =+E21*F21 -> 3023300
B22: 3.3 | C22: Suministro y Aplicación de Pintura para exteriores, tipo Koraza, en elementos volumetricos de superboard en las fachadas | D22: M2 | E22: 455.3 | F22: 27200 | G22: =+E22*F22 -> 12384160
B23: 3.4 | C23: Suministro y Aplicación de Pintura para exteriores, tipo koraza, color gris basalto, sobre alfajias de escaleras de acceso a los bloques y de areas comunes externas. | D23: ML | E23: 373.99 | F23: 8100 | G23: =+E23*F23 -> 3029319
B24: PINTURA PARA INTERIORES TIPO VINILO | G24: =+G25 -> 25891680
B25: 3.5 | C25: Suministro y Aplicación de Pintura tipo Vinilo en areas comunes internas de los bloques de aptos: paredes y cielos rasos | D25: M2 | E25: 2157.64 | F25: 12000 | G25: =+E25*F25 -> 25891680
B26: PINTURA ESMALTE TIPO 3 EN 1 | G26: =+G27+G28+G29+G30+G31 -> 90190875
B27: 3.6 | C27: Suministro y Aplicación de Pintura tipo 3 en 1, en puertas de los apartamentos (estan incluidas las de los exteriores, porteria-motobombas) | D27: UN | E27: 92 | F27: 121000 | G27: =+E27*F27 -> 11132000
B28: 3.7 | C28: Suministro y Aplicación de Pintura para Barandas Metalicas en areas exteriores: gimnasio, pasillos, cuarto de acueducto, piscina, circulacion entre bloques, etc. | D28: ML | E28: 344.25 | F28: 22400 | G28: =+E28*F28 -> 7711200
B29: 3.8 | C29: Suministro y Aplicación de Pintura tipo 3 en 1 en la totalidad de las estructuras metalicas de los parqueaderos externos | D29: M2 | E29: 1306.25 | F29: 24300 | G29: =+E29*F29 -> 31741875
B30: 3.9 | C30: Suministro y Aplicación de Pintuco Fill sobre las cubiertas de los parqueaderos | D30: M2 | E30: 1306.25 | F30: 29600 | G30: =+E30*F30 -> 38665000
B31: 3.10 | C31: Suministro y Aplicacion de Pintura tipo 3 en 1 sobre rejas metalicas en las terrazas del primer piso | D31: M2 | E31: 42 | F31: 22400 | G31: =+E31*F31 -> 940800
A32: 4 | C32: TRATAMIENTOS ESPECIALES CONTRA HUMEDADES | G32: =+G33+G34+G35+G36+G37+G38+G39 -> 2.8348101e+08
B33: 4.1 | C33: Cambio Total de Cubiertas | D33: M2 | E33: 1678.12 | F33: 119000 | G33: =+E33*F33 -> 199696280 | H33: ='[3]opc 2 cambio total cubierta'!G33-'opc 2 cambio total cubierta (2)'!G33 -> 0
B34: 4.2 | C34: Sellado Perimetral de enchape en terraza del gimnasio | D34: ML | E34: 0 | F34: 11300 | G34: =+E34*F34 -> 0
B35: 4.3 | C35: Retiro y Reposicion de sello perimetral en elementos vidriados de los bloque de apartamentos (30% DEL TOTAL) | D35: ML | E35: 817.994 | F35: 5200 | G35: =+E35*F35 -> 4253568.8
B36: 4.4 | C36: Suministro e Instalacion de Cortagoteras en Balcones y Accesos a los bloques de aptos | D36: ML | E36: 1055.3 | F36: 37000 | G36: =+E36*F36 -> 39046100
B37: 4.5 | C37: Reparacion de morteros en cuchillas de cubierta-(30% DEL TOTAL) | D37: M2 | E37: 290.8665 | F37: 52000 | G37: =+E37*F37 -> 15125058
B38: 4.6 | C38: Suministro e Instalacion de Alfajias en lamina sobre muros perimetrales y medianeros en las cubiertas | D38: ML | E38: 372 | F38: 63000 | G38: =+E38*F38 -> 23436000
B39: 4.7 | C39: Impermeabilizacion de tres terrazas sobre los puntos fijos de las escaleras de los bloques | D39: M2 | E39: 65 | F39: 29600 | G39: =+E39*F39 -> 1924000
A40: 5 | C40: ASEO GENERAL DE OBRA Y RETIRO DE ESCOMBROS | G40: =+G41 -> 1550000
...
