Workbook

Sheet C.O. EL PORTAL
A2: EDIFICIO EL PORTAL
E3: DIMENSIONES | H3: DESCUENTOS
A4: TORRE | B4: FACHADA | C4: SECCIÓN | D4: DESCRIPCIÓN | E4: ALTO | F4: ANCHO | G4: TOTAL (M2) | H4: ALTO | I4: ANCHO | J4: CANTIDAD | K4: TOTAL (M2) | L4: CARTERAS (ML) | M4: DILATACIÓN (ML) | N4: ÁREA TOTAL
A5: 1 | B5: A | C5: 1 | D5: Muro con ventanas (Tableta) | E5: =(3*9)+0.8 -> 27.8 | F5: =3.35+1.4 -> 4.75 | G5: =E5*F5 -> 132.05 | H5: 1.2 | I5: 0.6 | J5: 6 | K5: =(H5*I5)*J5 -> 4.32 | L5: =((H5+I5)*2)*J5 -> 21.6 | N5: =G5-K8 -> 105.53
H6: 1.5 | I6: 1.4 | J6: 6 | K6: =(H6*I6)*J6 -> 12.6 | L6: =((H6+I6)*2)*J6 -> 34.8
H7: 1.6 | I7: 3 | J7: 2 | K7: =(H7*I7)*J7 -> 9.6 | L7: =((H7+I7)*2)*J7 -> 18.4
K8: =SUM(K5:K7) -> 26.52
C9: 2 | D9: Muro con ventanas (Blanco) | E9: =(3*8)+0.8 -> 24.8 | F9: 0.35 | G9: =E9*F9 -> 8.68 | H9: 2.5 | I9: 0.35 | J9: 3 | K9: =(H9*I9)*J9 -> 2.625 | L9: =((H9*I9))*J9 -> 2.625 | M9: =F9*8*2 -> 5.6 | N9: =G9-K9 -> 6.055
C10: 3 | D10: Muro con ventanas (Blanco) | E10: =E9 -> 24.8 | F10: =1.95+2.75 -> 4.7 | G10: =E10*F10 -> 116.56 | H10: 3 | I10: 2.75 | J10: 6 | K10: =(H10*I10)*J10 -> 49.5 | L10: =((H10*I10))*J10 -> 49.5 | M10: =F10*8*2 -> 75.2 | N10: =G10-K12 -> 46.435
H11: 2.5 | I11: 2.75 | J11: 3 | K11: =(H11*I11)*J11 -> 20.625 | L11: =((H11*I11))*J11 -> 20.625
K12: =SUM(K10:K11) -> 70.125
C13: 4 | D13: Muro sin ventanas (Blanco) | E13: =$E$9 -> 24.8 | F13: 0.2 | G13: =E13*F13 -> 4.96 | K13: =(H13*I13)*J13 -> 0 | L13: =((H13+I13)*2)*J13 -> 0 | M13: =F13*8*2 -> 3.2 | N13: =G13-K13 -> 4.96
C14: 5 | D14: Muro sin ventanas (Blanco) | E14: =$E$9 -> 24.8 | F14: 1.35 | G14: =E14*F14 -> 33.48 | K14: =(H14*I14)*J14 -> 0 | L14: =((H14+I14)*2)*J14 -> 0 | M14: =F14*8*2 -> 21.6 | N14: =G14-K14 -> 33.48
C15: 6 | D15: Muro sin ventanas (Blanco) | E15: =$E$9 -> 24.8 | F15: 2.4 | G15: =E15*F15 -> 59.52 | H15: 2.5 | I15: 1 | J15: 1 | K15: =(H15*I15)*J15 -> 2.5 | L15: =((H15*I15))*J15 -> 2.5 | M15: =F15*8*2 -> 38.4 | N15: =G15-K15 -> 57.02
C16: 7 | D16: Muro con ventanas (Blanco) | E16: =$E$9 -> 24.8 | F16: =3.4+0.4 -> 3.8 | G16: =E16*F16 -> 94.24 | H16: 1.2 | I16: 0.6 | J16: 7 | K16: =(H16*I16)*J16 -> 5.04 | L16: =((H16+I16)*2)*J16 -> 25.2 | M16: =F16*8*2 -> 60.8 | N16: =G16-K18 -> 74.5
H17: 1.5 | I17: 1.4 | J17: 7 | K17: =(H17*I17)*J17 -> 14.7 | L17: =((H17+I17)*2)*J17 -> 40.6
K18: =SUM(K16:K17) -> 19.74
B19: B | C19: 8 | D19: Muro con ventanas (Blanco) | E19: =$E$9 -> 24.8 | F19: =3.4+0.4 -> 3.8 | G19: =E19*F19 -> 94.24 | H19: 1.2 | I19: 0.6 | J19: 7 | K19: =(H19*I19)*J19 -> 5.04 | L19: =((H19+I19)*2)*J19 -> 25.2 | M19: =F19*8*2 -> 60.8 | N19: =G19-K21 -> 74.5
H20: 1.5 | I20: 1.4 | J20: 7 | K20: =(H20*I20)*J20 -> 14.7 | L20: =((H20+I20)*2)*J20 -> 40.6
K21: =SUM(K19:K20) -> 19.74
C22: 9 | D22: Muro sin ventanas (Blanco) | E22: =$E$9 -> 24.8 | F22: 2.4 | G22: =E22*F22 -> 59.52 | H22: 2.5 | I22: 1 | J22: 1 | K22: =(H22*I22)*J22 -> 2.5 | M22: =F22*8*2 -> 38.4 | N22: =G22-K22 -> 57.02
C23: 10 | D23: Muro sin ventanas (Blanco) | E23: =$E$9 -> 24.8 | F23: 1.35 | G23: =E23*F23 -> 33.48 | K23: =(H23*I23)*J23 -> 0 | M23: =F23*8*2 -> 21.6 | N23: =G23-K23 -> 33.48
C24: 11 | D24: Muro sin ventanas (Blanco) | E24: =$E$9 -> 24.8 | F24: 0.35 | G24: =E24*F24 -> 8.68 | K24: =(H24*I24)*J24 -> 0 | M24: =F24*8*2 -> 5.6 | N24: =G24-K24 -> 8.68
C25: 12 | D25: Muro con ventanas (Blanco) | E25: =$E$9 -> 24.8 | F25: =1.95+2.75 -> 4.7 | G25: =E25*F25 -> 116.56 | H25: 18 | I25: 2.75 | J25: 1 | K25: =(H25*I25)*J25 -> 49.5 | L25: =((H25*I25))*J25 -> 49.5 | M25: =F25*8*2 -> 75.2 | N25: =G25-K27 -> 46.435
H26: 2.5 | I26: 2.75 | J26: 3 | K26: =(H26*I26)*J26 -> 20.625 | L26: =((H26*I26))*J26 -> 20.625
K27: =SUM(K25:K26) -> 70.125
C28: 13 | D28: Muro con ventanas (Blanco) | E28: =(3*8)+0.8 -> 24.8 | F28: 0.35 | G28: =E28*F28 -> 8.68 | H28: 2.5 | I28: 0.35 | J28: 3 | K28: =(H28*I28)*J28 -> 2.625 | L28: =((H28*I28))*J28 -> 2.625 | M28: =F28*8*2 -> 5.6 | N28: =G28-K28 -> 6.055
C29: 14 | D29: Muro con ventanas (Tableta) | E29: =E5 -> 27.8 | F29: =1.4+3.35 -> 4.75 | G29: =E29*F29 -> 132.05 | H29: 1.2 | I29: 0.6 | J29: 6 | K29: =(H29*I29)*J29 -> 4.32 | L29: =((H29+I29)*2)*J29 -> 21.6 | N29: =G29-K32 -> 105.53
H30: 1.5 | I30: 1.4 | J30: 6 | K30: =(H30*I30)*J30 -> 12.6 | L30: =((H30+I30)*2)*J30 -> 34.8
H31: 1.6 | I31: 3 | J31: 2 | K31: =(H31*I31)*J31 -> 9.6 | L31: =((H31+I31)*2)*J31 -> 18.4
K32: =SUM(K29:K31) -> 26.52
B33: C | C33: 15 | D33: Muro sin ventana (Tableta) | E33: =(3*8)+0.8 -> 24.8 | F33: =1.9+0.85 -> 2.75 | G33: =E33*F33 -> 68.2 | K33: =(H33*I33)*J33 -> 0 | L33: =((H33+I33)*2)*J33 -> 0 | N33: =G33-K33 -> 68.2
C34: 16 | D34: Muro con ventana (Tableta) | E34: =(3*2)+0.8 -> 6.8 | F34: 2.65 | G34: =E34*F34 -> 18.02 | N34: =G34-K34 -> 18.02
C35: 17 | D35: Muro con ventana (Tableta) | E35: =$E$33 -> 24.8 | F35: 3.9 | G35: =E35*F35 -> 96.72 | H35: 1.8 | I35: 1 | J35: 7 | K35: =(H35*I35)*J35 -> 12.6 | L35: =((H35+I35)*2)*J35 -> 39.2 | N35: =G35-K35 -> 84.12
C36: 17-B | D36: Muro Piso 1 (Blanco) | E36: 3 | F36: =SUM(F33:F35) -> 9.3 | G36: =E36*F36 -> 27.9 | H36: 3 | I36: 2 | J36: 1 | K36: =(H36*I36)*J36 -> 6 | N36: =G36-K36 -> 21.9
B37: D | C37: 18 | D37: Muro con ventana (Tableta) | E37: =$E$33 -> 24.8 | F37: =7.7+1.55+2.15 -> 11.4 | G37: =E37*F37 -> 282.72 | H37: 1.8 | I37: 3.05 | J37: 14 | K37: =(H37*I37)*J37 -> 76.86 | L37: =((H37+I37)*2)*J37 -> 135.8 | N37: =G37-K40 -> 172.665
H38: 0.3 | I38: 0.45 | J38: 7 | K38: =(H38*I38)*J38 -> 0.945 | L38: =((H38+I38)*2)*J38 -> 10.5
H39: 15 | I39: 2.15 | J39: 1 | K39: =(H39*I39)*J39 -> 32.25 | L39: =H39*I39 -> 32.25
K40: =SUM(K37:K39) -> 110.055
C41: 18-B | D41: Muro Piso 1 (Blanco) | E41: 3 | F41: 11.4 | G41: =E41*F41 -> 34.2 | H41: 2.5 | I41: 2 | J41: 1 | K41: =(H41*I41)*J41 -> 5 | L41: =((H41+I41)*2)*J41 -> 9 | N41: =G41-K41 -> 29.2
...

Sheet RESUMEN CANTIDADES
A2: ITEM | B2: Descripción | C2: Presupuesto oficial
C5: Und | D5: Cant. | E5: Vr. Unitario | F5: Vr. Total
A6: EDIFICIO SAN CÁNCIO
A7: 1.1 | B7: FACHADA SUPERFICIE EN TABLETA CON DESCUENTOS | C7: M2 | D7: ='C.O. EL PORTAL'!N5+'C.O. EL PORTAL'!N29+'C.O. EL PORTAL'!N33+'C.O. EL PORTAL'!N34+'C.O. EL PORTAL'!N35+'C.O. EL PORTAL'!N37+'C.O. EL PORTAL'!N46+'C.O. EL PORTAL'!N51+'C.O. EL PORTAL'!N56+'C.O. EL PORTAL'!N58+'C.O. EL PORTAL'!N59 -> 915.55 | E7: 0 | F7: =D7*E7 -> 0
A8: 1.2 | B8: FACHADA SUPERFICIE EN TEXTURA BLANCA CON DESCUENTOS | C8: M2 | D8: ='C.O. EL PORTAL'!N63-'RESUMEN CANTIDADES'!D7 -> 1046.36 | E8: 0 | F8: =D8*E8 -> 0
A9: 1.3 | B9: FACHADA EN GENERAL SIN DESCUENTOS | C9: M2 | D9: ='C.O. EL PORTAL'!G63 -> 2611.86 | E9: 0 | F9: =D9*E9 -> 0
A10: 1.4 | B10: DILATACIONES EN TEXTURA BLANCA | C10: ML | D10: ='C.O. EL PORTAL'!M61 -> 1623.2 | E10: 0 | F10: =D10*E10 -> 0
A11: 1.5 | B11: CARTERAS EN VENTANAS EN GENERAL | C11: ML | D11: ='C.O. EL PORTAL'!L61 -> 1198.3
A12: 1.6 | B12: SELLO DE VENTANERÍA | C12: ML | D12: =D11 -> 1198.3 | E12: 0 | F12: =D12*E12 -> 0
