Workbook

Sheet DASHBOARD
B1: TOTALES
B2: LAVADO | D2: RESANE | F2: SELLO | H2: PINTURA | J2: TRAT. DILATACIONES | L2: CARPINTERIA METALICA
B3: =LAVADO!E76 -> 4308.162 | D3: 85 | F3: =SELLO!E42 -> 1272.6 | H3: ='PINTURA T.VERDE'!R64 -> 2447.356 | J3: ='TRT DIL'!E40 -> 1201.844 | L3: ='[1](4A) PINTURA CARP MET'!H40 -> 0
B5: EJECUTADO
B6: LAVADO | D6: RESANE | F6: SELLO | H6: PINTURA | J6: TRAT. DILATACIONES | L6: CARPINTERIA METALICA
B7: =LAVADO!L76 -> 1290.86 | D7: =RESANE!AC81+RESANE!AQ81+RESANE!BE81+RESANE!BS81+RESANE!CG81+RESANE!CU81 -> 0 | F7: =SELLO!L42 -> 42.84 | H7: ='PINTURA T.VERDE'!AC81+'PINTURA T.VERDE'!AQ81+'PINTURA T.VERDE'!BE81+'PINTURA T.VERDE'!BS81+'PINTURA T.VERDE'!CG81+'PINTURA T.VERDE'!CU81 -> 1000 | J7: ='TRT DIL'!L52 -> 135.8 | L7: ='[1](4A) PINTURA CARP MET'!H40 -> 0
B9: PENDIENTE
B10: LAVADO | D10: RESANE | F10: SELLO | H10: PINTURA | J10: TRAT. DILATACIONES | L10: CARPINTERIA METALICA
B11: =B3-B7 -> 3017.302 | D11: =D3-D7 -> 85 | F11: =F3-F7 -> 1229.76 | H11: =H3-H7 -> 1447.356 | J11: =J3-J7 -> 1066.044 | L11: =L3-L7 -> 0
B13: RENDIMIENTOS PROMEDIO
B14: LAVADO | D14: RESANE | F14: SELLO | H14: PINTURA | J14: TRAT. DILATACIONES | L14: CARPINTERIA METALICA
L15: ='[2]COTIZACIÓN (2)'!O15 -> 0
A18: EJECUCIÓN SEMANA ACTUAL (SEMANA 2)
C19: LUNES | E19: MARTES | G19: MIERCOLES | I19: JUEVES | K19: VIERNES | M19: SABADO
A20: LAVADO
A21: RESANE
A22: SELLO
A23: PINTURA
A24: SILICONITE
A25: CARPINTERIA METALICA
A26: CIELOS BALCONES
A28: EJECUCIÓN SEMANA PASADA (SEMANA 1)
C29: LUNES | E29: MARTES | G29: MIERCOLES | I29: JUEVES | K29: VIERNES | M29: SABADO
A30: LAVADO
A31: RESANE
A32: SELLO
A33: PINTURA
A34: SILICONITE
A35: CARPINTERIA METALICA
A36: CIELOS BALCONES
A38: PERSONAL EN SITIO Y ASISTENCIA
C39: LUNES | E39: MARTES | G39: MIERCOLES | I39: JUEVES | K39: VIERNES | M39: SABADO
A40: ALEXIS BETANCOURT | B40: EDWIN TORRES
A41: LISETH GONZALES | B41: DEIBER TORO
A42: CIPRIANO VALENCIA | B42: GERARDO HERRERA
A43: SEBASTIAN VALENCIA | B43: CIPRIANO VALENCIA
B44: DIEGO DUQUE
B45: JHONATAN BENÍTEZ
AD65: Actividad | AE65: Ejecutado | AF65: Pendiente
AD66: LAVADO | AE66: =B3 -> 4308.162 | AF66: =B11 -> 3017.302
...

Sheet SALARIOS
B2: ANÁLISIS DEL COSTO REAL DEL SALARIO
B3: DATOS DE ENTRADA
B4: SALARIO MINIMO MENSUAL VIGENTE 2025 | C4: 1423500
B5: SUBSIDIO DE TRANSPORTE 2025 | C5: 200000
B6: DOTACIÓN 3 VECES AL AÑO | C6: =150000*3 -> 450000
B9: ANÁLISIS DEL COSTO REAL DEL SALARIO
B10: FACTOR PRESTACIONAL > 2 SMMLV
B11: CONCEPTO | C11: PORCENTAJE
B12: PRESTACIONES SOCIALES | C12: 0
B13: Cesantias | C13: =100/12 -> 8.3333333
B14: Intereses a las cesantias | C14: =C13*0.01 -> 0.083333333
B15: Vacaciones | C15: =100/24 -> 4.1666667
B16: Prima anual | C16: =100/12 -> 8.3333333
B18: SEGURIDAD SOCIAL | C18: =SUM(C19:C21) -> 35.46
B19: Fondo de pensiones (A.F.P) | C19: 16
B20: Medicina familiar (E.P.S) | C20: 12.5
B21: Riesgos Laborales (A.R.L) | C21: 6.96
B23: APORTE PARAFISCALES | C23: =SUM(C24:C26) -> 9
B24: SENA | C24: 2
B25: ICBF | C25: 3
B26: Caja de compensación familiar | C26: 4
B28: PORCENTAJE PRESTACIONAL | C28: =C12+C18+C23 -> 44.46
B31: SEGURIDAD SOCIAL
B32: SEGURIDAD SOCIAL X MES | C32: 430000
B33: SEGURIDAD SOCIAL X DÍA | C33: =C32/30 -> 14333.333
B35: SALARIO SEMANAL NETO
B36: OFICIAL III | C36: 700000
B37: OFICIAL II | C37: 650000
B38: OFICIAL I | C38: 600000
B39: PRÁCTICO | C39: 450000
B40: AYUDANTE | C40: 400000
B42: RESIDENTE DE OBRA | C42: 625000
B43: PROFESIONAL SST | C43: 500000
B46: SALARIO DIARIO NETO
B47: OFICIAL III | C47: =C36/6 -> 116666.67
B48: OFICIAL II | C48: =C37/6 -> 108333.33
B49: OFICIAL I | C49: =C38/6 -> 100000
B50: PRÁCTICO | C50: =C39/6 -> 75000
B51: AYUDANTE | C51: =C40/6 -> 66666.667
B53: RESIDENTE DE OBRA | C53: =C42/6 -> 104166.67
...

Sheet NÓMINA
E2: 2 | F2: 3 | G2: 4 | H2: 5 | I2: 6 | J2: 7 | K2: 8 | L2: 9 | M2: 10 | N2: 11 | O2: 12 | P2: 13 | Q2: 14 | R2: 15 | S2: 16 | T2: 17 | U2: 18 | V2: 19 | W2: 20 | X2: 21 | Y2: 22 | Z2: 23 | AA2: 24 | AB2: 25 | AC2: 26 | AD2: 27 | AE2: 28 | AF2: 29 | AG2: 30 | AH2: 31 | AI2: 1 | AJ2: 2 | AK2: 3 | AL2: 4 | AM2: 5 | AN2: 6 | AO2: 7 | AP2: 8 | AQ2: 9 | AR2: 10 | AS2: 11
E3: LUNES | F3: MARTES | G3: MIÉRCOLES | H3: JUEVES | I3: VIERNES | J3: SÁBADO | K3: DOMINGO | L3: LUNES | M3: MARTES | N3: MIÉRCOLES | O3: JUEVES | P3: VIERNES | Q3: SÁBADO | R3: DOMINGO | S3: LUNES | T3: MARTES | U3: MIÉRCOLES | V3: JUEVES | W3: VIERNES | X3: SÁBADO | Y3: DOMINGO | Z3: LUNES | AA3: MARTES | AB3: MIÉRCOLES | AC3: JUEVES | AD3: VIERNES | AE3: SÁBADO | AF3: DOMINGO | AG3: LUNES | AH3: MARTES | AI3: MIÉRCOLES | AJ3: JUEVES | AK3: VIERNES | AL3: SÁBADO | AM3: DOMINGO | AN3: LUNES | AO3: MARTES | AP3: MIÉRCOLES | AQ3: JUEVES | AR3: VIERNES | AS3: SÁBADO
A4: NOMBRE | B4: CARGO | C4: DEDICACIÓN | D4: SALARIO DÍA
A5: RENSO MONTOYA | B5: GERENTE | C5: 0.34 | D5: =SALARIOS!C64 -> 118500 | E5: 0 | F5: =D5*C5 -> 40290 | G5: 0 | H5: 0 | I5: 0 | J5: 0 | L5: 0 | M5: 0 | N5: 0 | O5: 0 | P5: 0 | Q5: 0 | S5: 0 | T5: 0 | U5: 0 | V5: 0 | W5: 0 | X5: 0 | Y5: 0 | Z5: 0 | AA5: 0 | AB5: 0 | AC5: 0 | AD5: 0 | AE5: 0 | AF5: 0 | AG5: 0 | AH5: 0 | AI5: 0 | AJ5: 0 | AK5: 0 | AL5: 0 | AM5: 0 | AN5: 0 | AO5: 0 | AP5: 0 | AQ5: 0 | AR5: 0 | AS5: 0 | AT5: =SUM(E5:AS5) -> 40290
A6: GLORIA COLORADO | B6: ADMINIST | C6: 0.34 | D6: =D5 -> 118500 | E6: 0 | F6: =D6*C6 -> 40290 | G6: 0 | H6: 0 | I6: 0 | J6: 0 | L6: 0 | M6: 0 | N6: 0 | O6: 0 | P6: 0 | Q6: 0 | S6: 0 | T6: 0 | U6: 0 | V6: 0 | W6: 0 | X6: 0 | Y6: 0 | Z6: 0 | AA6: 0 | AB6: 0 | AC6: 0 | AD6: 0 | AE6: 0 | AF6: 0 | AG6: 0 | AH6: 0 | AI6: 0 | AJ6: 0 | AK6: 0 | AL6: 0 | AM6: 0 | AN6: 0 | AO6: 0 | AP6: 0 | AQ6: 0 | AR6: 0 | AS6: 0 | AT6: =SUM(E6:AS6) -> 40290
A7: ALEXIS BETANCOURT | B7: RESIDENTE | C7: 1 | D7: =SALARIOS!C64 -> 118500 | E7: 0 | F7: =D7*C7 -> 118500 | G7: 0 | H7: 0 | I7: 0 | J7: 0 | L7: 0 | M7: 0 | N7: 0 | O7: 0 | P7: 0 | Q7: 0 | S7: 0 | T7: 0 | U7: 0 | V7: 0 | W7: 0 | X7: 0 | Y7: 0 | Z7: 0 | AA7: 0 | AB7: 0 | AC7: 0 | AD7: 0 | AE7: 0 | AF7: 0 | AG7: 0 | AH7: 0 | AI7: 0 | AJ7: 0 | AK7: 0 | AL7: 0 | AM7: 0 | AN7: 0 | AO7: 0 | AP7: 0 | AQ7: 0 | AR7: 0 | AS7: 0 | AT7: =SUM(E7:AS7) -> 118500
A8: FELIPE MONTOYA | B8: AUX GERENCIA | C8: 0.34 | D8: =D7 -> 118500 | E8: 0 | F8: =D8*C8 -> 40290 | G8: 0 | H8: 0 | I8: 0 | J8: 0 | L8: 0 | M8: 0 | N8: 0 | O8: 0 | P8: 0 | Q8: 0 | S8: 0 | T8: 0 | U8: 0 | V8: 0 | W8: 0 | X8: 0 | Y8: 0 | Z8: 0 | AA8: 0 | AB8: 0 | AC8: 0 | AD8: 0 | AE8: 0 | AF8: 0 | AG8: 0 | AH8: 0 | AI8: 0 | AJ8: 0 | AK8: 0 | AL8: 0 | AM8: 0 | AN8: 0 | AO8: 0 | AP8: 0 | AQ8: 0 | AR8: 0 | AS8: 0 | AT8: =SUM(E8:AS8) -> 40290
A9: DIEGO LÓPEZ | B9: SUPERVISOR | C9: 0.5 | D9: =[3]SALARIOS!C64 -> 118166.67 | E9: 0 | F9: =D9*C9 -> 59083.333 | G9: 0 | H9: 0 | I9: 0 | J9: 0 | L9: 0 | M9: 0 | N9: 0 | O9: 0 | P9: 0 | Q9: 0 | S9: 0 | T9: 0 | U9: 0 | V9: 0 | W9: 0 | X9: 0 | Y9: 0 | Z9: 0 | AA9: 0 | AB9: 0 | AC9: 0 | AD9: 0 | AE9: 0 | AF9: 0 | AG9: 0 | AH9: 0 | AI9: 0 | AJ9: 0 | AK9: 0 | AL9: 0 | AM9: 0 | AN9: 0 | AO9: 0 | AP9: 0 | AQ9: 0 | AR9: 0 | AS9: 0 | AT9: =SUM(E9:AS9) -> 59083.333
A10: LISETH GONZÁLEZ | B10: PROF SST | C10: 0.34 | D10: =[3]SALARIOS!C65 -> 97333.333 | E10: 0 | F10: =D10*C10 -> 33093.333 | G10: 0 | H10: 0 | I10: 0 | J10: 0 | L10: 0 | M10: 0 | N10: 0 | O10: 0 | P10: 0 | Q10: 0 | S10: 0 | T10: 0 | U10: 0 | V10: 0 | W10: 0 | X10: 0 | Y10: 0 | Z10: 0 | AA10: 0 | AB10: 0 | AC10: 0 | AD10: 0 | AE10: 0 | AF10: 0 | AG10: 0 | AH10: 0 | AI10: 0 | AJ10: 0 | AK10: 0 | AL10: 0 | AM10: 0 | AN10: 0 | AO10: 0 | AP10: 0 | AQ10: 0 | AR10: 0 | AS10: 0 | AT10: =SUM(E10:AS10) -> 33093.333
E11: =SUM(E5:E10) -> 0 | F11: =SUM(F5:F10) -> 331546.67 | G11: =SUM(G5:G10) -> 0 | H11: =SUM(H5:H10) -> 0 | I11: =SUM(I5:I10) -> 0 | J11: =SUM(J5:J10) -> 0 | K11: =SUM(K5:K10) -> 0 | L11: =SUM(L5:L10) -> 0 | ... S11: =SUM(S5:S10) -> 0
A12: JONATHAN ARANGO | B12: OFICIAL II | C12: 1 | D12: =SALARIOS!C59 -> 122666.67 | E12: 0 | F12: 0 | G12: =$F$12 -> 0 | H12: =$F$12 -> 0 | I12: =$F$12 -> 0 | J12: =$F$12 -> 0 | K12: 0 | L12: =$F$12 -> 0 | M12: =$F$12 -> 0 | N12: =$F$12 -> 0 | O12: =$F$12 -> 0 | P12: =$F$12 -> 0 | Q12: =$F$12 -> 0 | R12: 0 | S12: 0 | T12: 0 | U12: 0 | V12: 0 | W12: 0 | X12: 0 | Y12: 0 | Z12: 0 | AA12: 0 | AB12: 0 | AC12: 0 | AD12: 0 | AE12: 0 | AF12: 0 | AG12: 0 | AH12: 0 | AI12: 0 | AJ12: 0 | AK12: 0 | AL12: 0 | AM12: 0 | AN12: 0 | AO12: 0 | AP12: 0 | AQ12: 0 | AR12: 0 | AS12: 0 | AT12: =SUM(E12:AS12) -> 0
A13: CIPRIANO CARDENAS | B13: OFICIAL III | C13: 1 | D13: =D12 -> 122666.67 | E13: 0 | F13: 0 | G13: =$F$13 -> 0 | H13: =$F$13 -> 0 | I13: =$F$13 -> 0 | J13: =$F$13 -> 0 | K13: 0 | L13: =$F$12 -> 0 | M13: =$F$12 -> 0 | N13: =$F$12 -> 0 | O13: =$F$12 -> 0 | P13: =$F$12 -> 0 | Q13: =$F$12 -> 0 | R13: 0 | S13: 0 | T13: 0 | U13: 0 | V13: 0 | W13: 0 | X13: 0 | Y13: 0 | Z13: 0 | AA13: 0 | AB13: 0 | AC13: 0 | AD13: 0 | AE13: 0 | AF13: 0 | AG13: 0 | AH13: 0 | AI13: 0 | AJ13: 0 | AK13: 0 | AL13: 0 | AM13: 0 | AN13: 0 | AO13: 0 | AP13: 0 | AQ13: 0 | AR13: 0 | AS13: 0 | AT13: =SUM(E13:AS13) -> 0
A14: BRAYAN MEJÍA | B14: OFICIAL II | C14: 1 | D14: =SALARIOS!C60 -> 114333.33 | E14: 0 | F14: 0 | G14: 0 | H14: 0 | I14: 0 | J14: 0 | K14: 0 | L14: =$F$12 -> 0 | M14: =$F$12 -> 0 | N14: =$F$12 -> 0 | O14: =$F$12 -> 0 | P14: =$F$12 -> 0 | Q14: =$F$12 -> 0 | R14: 0 | S14: 0 | T14: 0 | U14: 0 | V14: 0 | W14: 0 | X14: 0 | Y14: 0 | Z14: 0 | AA14: 0 | AB14: 0 | AC14: 0 | AD14: 0 | AE14: 0 | AF14: 0 | AG14: 0 | AH14: 0 | AI14: 0 | AJ14: 0 | AK14: 0 | AL14: 0 | AM14: 0 | AN14: 0 | AO14: 0 | AP14: 0 | AQ14: 0 | AR14: 0 | AS14: 0 | AT14: =SUM(E14:AS14) -> 0
A15: JUAN CARLOS | B15: OFICIAL II | C15: 1 | D15: =D14 -> 114333.33 | E15: 0 | F15: 0 | G15: 0 | H15: 0 | I15: 0 | J15: 0 | K15: 0 | L15: =$F$12 -> 0 | M15: =$F$12 -> 0 | N15: =$F$12 -> 0 | O15: =$F$12 -> 0 | P15: =$F$12 -> 0 | Q15: =$F$12 -> 0 | R15: 0 | S15: 0 | T15: =$N$15*$C$15 -> 0 | U15: =$N$15*$C$15 -> 0 | V15: =$N$15*$C$15 -> 0 | W15: =$N$15*$C$15 -> 0 | X15: =$N$15*$C$15 -> 0 | Y15: 0 | Z15: =$N$15*$C$15 -> 0 | AA15: =$N$15*$C$15 -> 0 | AB15: =$N$15*$C$15 -> 0 | AC15: =$N$15*$C$15 -> 0 | AD15: =$N$15*$C$15 -> 0 | AE15: =$N$15*$C$15 -> 0 | AF15: 0 | AG15: =$N$15*$C$15 -> 0 | AH15: =$N$15*$C$15 -> 0 | AI15: =$N$15*$C$15 -> 0 | AJ15: =$N$15*$C$15 -> 0 | AK15: =$N$15*$C$15 -> 0 | AL15: =$N$15*$C$15 -> 0 | AM15: 0 | AN15: =$N$15*$C$15 -> 0 | AO15: =$N$15*$C$15 -> 0 | AP15: =$N$15*$C$15 -> 0 | AQ15: =$N$15*$C$15 -> 0 | AR15: =$N$15*$C$15 -> 0 | AS15: =$N$15*$C$15 -> 0 | AT15: =SUM(E15:AS15) -> 0
A16: JEISON PORTAL | B16: OFICIAL I | C16: 1 | D16: =SALARIOS!C60 -> 114333.33 | E16: 0 | F16: 0 | G16: =$F$16 -> 0 | H16: =$F$16 -> 0 | I16: =$F$16 -> 0 | J16: =$F$16 -> 0 | K16: 0 | L16: =$F$12 -> 0 | M16: =$F$12 -> 0 | N16: =$F$12 -> 0 | O16: =$F$12 -> 0 | P16: =$F$12 -> 0 | Q16: =$F$12 -> 0 | R16: 0 | S16: 0 | T16: 0 | U16: 0 | V16: 0 | W16: 0 | X16: 0 | Y16: 0 | Z16: 0 | AA16: 0 | AB16: 0 | AC16: 0 | AD16: =$N$15*$C$15 -> 0 | AE16: =$N$15*$C$15 -> 0 | AF16: 0 | AG16: =$N$15*$C$15 -> 0 | AH16: 0 | AI16: 0 | AJ16: 0 | AK16: 0 | AL16: 0 | AM16: 0 | AN16: 0 | AO16: 0 | AP16: 0 | AQ16: 0 | AR16: 0 | AS16: 0 | AT16: =SUM(E16:AS16) -> 0
A17: DUBERNEY TORO | B17: OFICIAL I | C17: 1 | D17: =SALARIOS!C60 -> 114333.33 | E17: 0 | F17: 0 | G17: 0 | H17: 0 | I17: 0 | J17: 0 | K17: 0 | L17: =$F$12 -> 0 | M17: =$F$12 -> 0 | N17: =$F$12 -> 0 | O17: =$F$12 -> 0 | P17: =$F$12 -> 0 | Q17: =$F$12 -> 0 | R17: 0 | S17: 0 | T17: 0 | U17: 0 | V17: 0 | W17: 0 | X17: 0 | Y17: 0 | Z17: 0 | AA17: 0 | AB17: 0 | AC17: 0 | AD17: 0 | AE17: 0 | AF17: 0 | AG17: 0 | AH17: 0 | AI17: 0 | AJ17: 0 | AK17: 0 | AL17: 0 | AM17: 0 | AN17: 0 | AO17: 0 | AP17: 0 | AQ17: 0 | AR17: 0 | AS17: 0 | AT17: =SUM(E17:AS17) -> 0
A18: GREGORIO GONZÁLEZ | B18: OFICIAL II | C18: 1 | D18: =SALARIOS!C59 -> 122666.67 | E18: 0 | F18: 0 | G18: 0 | H18: 0 | I18: 0 | J18: 0 | K18: 0 | L18: =$F$12 -> 0 | M18: =$F$12 -> 0 | N18: =$F$12 -> 0 | O18: =$F$12 -> 0 | P18: =$F$12 -> 0 | Q18: =$F$12 -> 0 | R18: 0 | S18: 0 | T18: 0 | U18: 0 | V18: 0 | W18: 0 | X18: 0 | Y18: 0 | Z18: 0 | AA18: 0 | AB18: 0 | AC18: 0 | AD18: 0 | AE18: 0 | AF18: 0 | AG18: 0 | AH18: 0 | AI18: 0 | AJ18: 0 | AK18: 0 | AL18: 0 | AM18: 0 | AN18: 0 | AO18: 0 | AP18: 0 | AQ18: 0 | AR18: 0 | AS18: 0 | AT18: =SUM(E18:AS18) -> 0
A19: WILLIAN BETANCOURT | B19: PRÁCTICO | C19: 1 | D19: =SALARIOS!C62 -> 81000 | E19: 0 | F19: 0 | G19: 0 | H19: 0 | I19: 0 | J19: 0 | K19: 0 | L19: =$F$12 -> 0 | M19: =$F$12 -> 0 | N19: =$F$12 -> 0 | O19: =$F$12 -> 0 | P19: =$F$12 -> 0 | Q19: =$F$12 -> 0 | R19: 0 | S19: 0 | T19: 0 | U19: 0 | V19: 0 | W19: 0 | X19: 0 | Y19: 0 | Z19: 0 | AA19: 0 | AB19: 0 | AC19: 0 | AD19: 0 | AE19: 0 | AF19: 0 | AG19: 0 | AH19: 0 | AI19: 0 | AJ19: 0 | AK19: 0 | AL19: 0 | AM19: 0 | AN19: 0 | AO19: 0 | AP19: 0 | AQ19: 0 | AR19: 0 | AS19: 0 | AT19: =SUM(E19:AS19) -> 0
AT20: =SUM(AT5:AT18) -> 331546.67
E21: =SUM(E12:E20) -> 0 | F21: =SUM(F12:F20) -> 0 | G21: =SUM(G12:G20) -> 0 | H21: =SUM(H12:H20) -> 0 | I21: =SUM(I12:I20) -> 0 | J21: =SUM(J12:J20) -> 0 | K21: =SUM(K12:K20) -> 0 | L21: =SUM(L12:L20) -> 0 | ... AS21: =SUM(AS12:AS20) -> 0 | AT21: =SUM(E21:AS21) -> 0
E22: =E11 -> 0 | F22: =F11+F21 -> 331546.67 | G22: =G11+G21 -> 0 | H22: =H11+H21 -> 0 | I22: =I11+I21 -> 0 | J22: =J11+J21 -> 0 | K22: =K11+K21 -> 0 | L22: =L11+L21 -> 0 | M22: =M11+M21 -> 0 | ... S22: =S11+S21 -> 0

Sheet COS_PROG
F1: FLUJO DE CAJA - EDIFICIO HEBRÓN
F3: 21 | G3: 22 | H3: 23 | I3: 24 | J3: 25 | K3: 26 | L3: 27 | M3: 28 | N3: 29 | O3: 30 | P3: 1 | Q3: 2 | R3: 3 | S3: 4 | T3: 5 | U3: 6 | V3: 7 | W3: 8 | X3: 9 | Y3: 10 | Z3: 11 | AA3: 12 | AB3: 13 | AC3: 14 | AD3: 15 | AE3: 16 | AF3: 17 | AG3: 18 | AH3: 19 | AI3: 20 | AJ3: 21 | AK3: 22 | AL3: 23 | AM3: 24 | AN3: 25 | AO3: 26 | AP3: 27 | AQ3: 28 | AR3: 29 | AS3: 30 | AT3: 31
F4: LUNES | G4: MARTES | H4: MIÉRCOLES | I4: JUEVES | J4: VIERNES | K4: SÁBADO | L4: DOMINGO | M4: LUNES | N4: MARTES | O4: MIÉRCOLES | P4: JUEVES | Q4: VIERNES | R4: SÁBADO | S4: DOMINGO | T4: LUNES | U4: MARTES | V4: MIÉRCOLES | W4: JUEVES | X4: VIERNES | Y4: SÁBADO | Z4: DOMINGO | AA4: LUNES | AB4: MARTES | AC4: MIÉRCOLES | AD4: JUEVES | AE4: VIERNES | AF4: SÁBADO | AG4: DOMINGO | AH4: LUNES | AI4: MARTES | AJ4: MIÉRCOLES | AK4: JUEVES | AL4: VIERNES | AM4: SÁBADO | AN4: DOMINGO | AO4: LUNES | AP4: MARTES | AQ4: MIÉRCOLES | AR4: JUEVES | AS4: VIERNES | AT4: SÁBADO
B5: EGRESOS
B7: CONCEPTO | C7: DEDICACIÓN | D7: VALOR
B8: COSTO INDIRECTOS
B9: OFICINA | C9: 0.25 | F9: 50000 | G9: =$F$9 -> 50000 | H9: =$F$9 -> 50000 | I9: =$F$9 -> 50000 | J9: =$F$9 -> 50000 | K9: =$F$9 -> 50000 | L9: 0 | M9: =$F$9 -> 50000 | N9: =$F$9 -> 50000 | O9: =$F$9 -> 50000 | P9: =$F$9 -> 50000 | Q9: =$F$9 -> 50000 | R9: =$F$9 -> 50000 | S9: 0 | T9: =$F$9 -> 50000 | U9: =$F$9 -> 50000 | V9: =$F$9 -> 50000 | W9: =$F$9 -> 50000 | X9: =$F$9 -> 50000 | Y9: =$F$9 -> 50000 | Z9: 0 | AA9: 0 | AB9: =$F$9 -> 50000 | AC9: =$F$9 -> 50000 | AD9: =$F$9 -> 50000 | AE9: =$F$9 -> 50000 | AF9: =$F$9 -> 50000 | AG9: 0 | AH9: =$F$9 -> 50000 | AI9: =$F$9 -> 50000 | AJ9: =$F$9 -> 50000 | AK9: =$F$9 -> 50000 | AL9: =$F$9 -> 50000 | AM9: =$F$9 -> 50000 | AN9: 0 | AO9: =$F$9 -> 50000 | AP9: =$F$9 -> 50000 | AQ9: =$F$9 -> 50000 | AR9: =$F$9 -> 50000 | AS9: =$F$9 -> 50000 | AT9: =$F$9 -> 50000 | AU9: =SUM(F9:AT9) -> 1750000
B10: PAPELERIA | C10: 0.5 | F10: 5000 | G10: =$F$10 -> 5000 | H10: =$F$10 -> 5000 | I10: =$F$10 -> 5000 | J10: =$F$10 -> 5000 | K10: =$F$10 -> 5000 | L10: 0 | M10: =$D$10*$C$10 -> 0 | N10: =$D$10*$C$10 -> 0 | O10: =$D$10*$C$10 -> 0 | P10: =$D$10*$C$10 -> 0 | Q10: =$D$10*$C$10 -> 0 | R10: =$D$10*$C$10 -> 0 | S10: 0 | T10: =$D$10*$C$10 -> 0 | U10: =$D$10*$C$10 -> 0 | V10: =$D$10*$C$10 -> 0 | W10: =$D$10*$C$10 -> 0 | X10: =$D$10*$C$10 -> 0 | Y10: =$D$10*$C$10 -> 0 | Z10: 0 | AA10: =$D$10*$C$10 -> 0 | AB10: =$D$10*$C$10 -> 0 | AC10: =$D$10*$C$10 -> 0 | AD10: =$D$9*$C$10 -> 0 | AE10: =$D$10*$C$10 -> 0 | AF10: =$D$10*$C$10 -> 0 | AG10: 0 | AH10: =$D$10*$C$10 -> 0 | AI10: =$D$10*$C$10 -> 0 | AJ10: =$D$10*$C$10 -> 0 | AK10: =$D$10*$C$10 -> 0 | AL10: =$D$10*$C$10 -> 0 | AM10: =$D$10*$C$10 -> 0 | AN10: 0 | AO10: =$D$10*$C$10 -> 0 | AP10: =$D$10*$C$10 -> 0 | AQ10: =$D$10*$C$10 -> 0 | AR10: =$D$10*$C$10 -> 0 | AS10: =$D$10*$C$10 -> 0 | AT10: =$D$10*$C$10 -> 0 | AU10: =SUM(F10:AT10) -> 30000
B11: NÓMINA ADMINISTRATIVOS
B13: COSTO DIRECTOS
B14: NÓMINA DE TRABAJADORES | C14: 1 | F14: =NÓMINA!E21 -> 0 | G14: =NÓMINA!F21 -> 0 | H14: =NÓMINA!G21 -> 0 | I14: =NÓMINA!H21 -> 0 | J14: =NÓMINA!I21 -> 0 | K14: =NÓMINA!J21 -> 0 | L14: 0 | M14: =$D$14*$C$14 -> 0 | N14: =$D$14*$C$14 -> 0 | O14: =$D$14*$C$14 -> 0 | P14: =$D$14*$C$14 -> 0 | Q14: =$D$14*$C$14 -> 0 | R14: =$D$14*$C$14 -> 0 | S14: 0 | T14: =$D$14*$C$14 -> 0 | U14: =$D$14*$C$14 -> 0 | V14: =$D$14*$C$14 -> 0 | W14: =$D$14*$C$14 -> 0 | X14: =$D$14*$C$14 -> 0 | Y14: =$D$14*$C$14 -> 0 | Z14: 0 | AA14: =$D$10*$C$10 -> 0 | AB14: =$D$14*$C$14 -> 0 | AC14: =$D$14*$C$14 -> 0 | AD14: =$D$14*$C$14 -> 0 | AE14: =$D$14*$C$14 -> 0 | AF14: =$D$14*$C$14 -> 0 | AG14: 0 | AH14: =$D$14*$C$14 -> 0 | AI14: =$D$14*$C$14 -> 0 | AJ14: =$D$14*$C$14 -> 0 | AK14: =$D$14*$C$14 -> 0 | AL14: =$D$14*$C$14 -> 0 | AM14: =$D$14*$C$14 -> 0 | AN14: 0 | AO14: =$D$14*$C$14 -> 0 | AP14: =$D$14*$C$14 -> 0 | AQ14: =$D$14*$C$14 -> 0 | AR14: =$D$14*$C$14 -> 0 | AS14: =$D$14*$C$14 -> 0 | AT14: =$D$14*$C$14 -> 0 | AU14: =SUM(F14:AT14) -> 0
B15: MATERIALES | C15: 1 | F15: =D15 -> 0 | G15: =$D$14*$C$14 -> 0 | H15: =$D$14*$C$14 -> 0 | I15: =$D$14*$C$14 -> 0 | J15: =$D$14*$C$14 -> 0 | K15: =$D$14*$C$14 -> 0 | L15: 0 | M15: =$D$14*$C$14 -> 0 | N15: =$D$14*$C$14 -> 0 | O15: =$D$14*$C$14 -> 0 | P15: =$D$14*$C$14 -> 0 | Q15: =$D$14*$C$14 -> 0 | R15: =$D$14*$C$14 -> 0 | S15: 0 | T15: =$D$14*$C$14 -> 0 | U15: =$D$14*$C$14 -> 0 | V15: =$D$14*$C$14 -> 0 | W15: =$D$14*$C$14 -> 0 | X15: =$D$14*$C$14 -> 0 | Y15: =$D$14*$C$14 -> 0 | Z15: 0 | AA15: =$D$10*$C$10 -> 0 | AB15: =$D$14*$C$14 -> 0 | AC15: =$D$14*$C$14 -> 0 | AD15: =$D$14*$C$14 -> 0 | AE15: =$D$14*$C$14 -> 0 | AF15: =$D$14*$C$14 -> 0 | AG15: 0 | AH15: =$D$14*$C$14 -> 0 | AI15: =$D$14*$C$14 -> 0 | AJ15: =$D$14*$C$14 -> 0 | AK15: =$D$14*$C$14 -> 0 | AL15: =$D$14*$C$14 -> 0 | AM15: =$D$14*$C$14 -> 0 | AN15: 0 | AO15: =$D$14*$C$14 -> 0 | AP15: =$D$14*$C$14 -> 0 | AQ15: =$D$14*$C$14 -> 0 | AR15: =$D$14*$C$14 -> 0 | AS15: =$D$14*$C$14 -> 0 | AT15: =$D$14*$C$14 -> 0 | AU15: =SUM(F15:AT15) -> 0
B16: HERRAMIENTAS | C16: 1 | F16: =D16 -> 0 | G16: =$D$16*$C$16 -> 0 | H16: =$D$16*$C$16 -> 0 | I16: =$D$16*$C$16 -> 0 | J16: =$D$16*$C$16 -> 0 | K16: =$D$16*$C$16 -> 0 | L16: 0 | M16: =$D$16*$C$16 -> 0 | N16: =$D$16*$C$16 -> 0 | O16: =$D$16*$C$16 -> 0 | P16: =$D$16*$C$16 -> 0 | Q16: =$D$16*$C$16 -> 0 | R16: =$D$16*$C$16 -> 0 | S16: 0 | T16: =$D$16*$C$16 -> 0 | U16: =$D$16*$C$16 -> 0 | V16: =$D$16*$C$16 -> 0 | W16: =$D$16*$C$16 -> 0 | X16: =$D$16*$C$16 -> 0 | Y16: =$D$16*$C$16 -> 0 | Z16: 0 | AA16: =$F$16*$C$16 -> 0 | AB16: =$F$16*$C$16 -> 0 | AC16: =$F$16*$C$16 -> 0 | AD16: =$F$16*$C$16 -> 0 | AE16: =$F$16*$C$16 -> 0 | AF16: =$F$16*$C$16 -> 0 | AG16: 0 | AH16: =$F$16*$C$16 -> 0 | AI16: =$F$16*$C$16 -> 0 | AJ16: =$F$16*$C$16 -> 0 | AK16: =$F$16*$C$16 -> 0 | AL16: =$F$16*$C$16 -> 0 | AM16: =$F$16*$C$16 -> 0 | AN16: 0 | AO16: =$F$16*$C$16 -> 0 | AP16: =$F$16*$C$16 -> 0 | AQ16: =$F$16*$C$16 -> 0 | AR16: =$F$16*$C$16 -> 0 | AS16: =$F$16*$C$16 -> 0 | AT16: =$F$16*$C$16 -> 0 | AU16: =SUM(F16:AT16) -> 0
B17: ALQUILER DE EQUIPOS | C17: 1 | F17: =D17*C17 -> 0 | G17: =$D$17*$C$17 -> 0 | H17: =$D$17*$C$17 -> 0 | I17: =$D$17*$C$17 -> 0 | J17: =$D$17*$C$17 -> 0 | K17: =$D$17*$C$17 -> 0 | L17: 0 | M17: =$D$17*$C$17 -> 0 | N17: =$D$17*$C$17 -> 0 | O17: =$D$17*$C$17 -> 0 | P17: =$D$17*$C$17 -> 0 | Q17: =$D$17*$C$17 -> 0 | R17: =$D$17*$C$17 -> 0 | S17: 0 | T17: =$D$17*$C$17 -> 0 | U17: =$D$17*$C$17 -> 0 | V17: =$D$17*$C$17 -> 0 | W17: =$D$17*$C$17 -> 0 | X17: =$D$17*$C$17 -> 0 | Y17: =$D$17*$C$17 -> 0 | Z17: 0 | AA17: =$D$17*$C$17 -> 0 | AB17: =$D$17*$C$17 -> 0 | AC17: 0 | AD17: 0 | AE17: 0 | AF17: 0 | AG17: 0 | AH17: =$D$17*$C$17 -> 0 | AI17: =$D$17*$C$17 -> 0 | AJ17: =$D$17*$C$17 -> 0 | AK17: =$D$17*$C$17 -> 0 | AL17: =$D$17*$C$17 -> 0 | AM17: =$D$17*$C$17 -> 0 | AN17: 0 | AO17: =$D$17*$C$17 -> 0 | AP17: =$D$17*$C$17 -> 0 | AQ17: =$D$17*$C$17 -> 0 | AR17: =$D$17*$C$17 -> 0 | AS17: =$D$17*$C$17 -> 0 | AT17: =$D$17*$C$17 -> 0 | AU17: =SUM(F17:AT17) -> 0
B18: ALQUILER DE EQUIPOS ALTURAS | C18: 1 | F18: =D18*C18 -> 0 | G18: =$D$17*$C$17 -> 0 | H18: =$D$17*$C$17 -> 0 | I18: =$D$17*$C$17 -> 0 | J18: =$D$17*$C$17 -> 0 | K18: =$D$17*$C$17 -> 0 | L18: 0 | M18: =$D$17*$C$17 -> 0 | N18: =$D$17*$C$17 -> 0 | O18: =$D$17*$C$17 -> 0 | P18: =$D$17*$C$17 -> 0 | Q18: =$D$17*$C$17 -> 0 | R18: =$D$17*$C$17 -> 0 | S18: 0 | T18: =$D$17*$C$17 -> 0 | U18: =$D$17*$C$17 -> 0 | V18: =$D$17*$C$17 -> 0 | W18: =$D$17*$C$17 -> 0 | X18: =$D$17*$C$17 -> 0 | Y18: =$D$17*$C$17 -> 0 | Z18: 0 | AA18: =$D$17*$C$17 -> 0 | AB18: =$D$17*$C$17 -> 0 | AC18: 0 | AD18: 0 | AE18: 0 | AF18: 0 | AG18: 0 | AH18: =$D$17*$C$17 -> 0 | AI18: =$D$17*$C$17 -> 0 | AJ18: =$D$17*$C$17 -> 0 | AK18: =$D$17*$C$17 -> 0 | AL18: =$D$17*$C$17 -> 0 | AM18: =$D$17*$C$17 -> 0 | AN18: 0 | AO18: =$D$17*$C$17 -> 0 | AP18: =$D$17*$C$17 -> 0 | AQ18: =$D$17*$C$17 -> 0 | AR18: =$D$17*$C$17 -> 0 | AS18: =$D$17*$C$17 -> 0 | AT18: =$D$17*$C$17 -> 0 | AU18: =SUM(F18:AT18) -> 0
B20: IMPREVISTOS
B22: TOTAL EGRESOS | F22: =SUM(F9:F21) -> 55000 | G22: =SUM(G9:G21) -> 55000 | H22: =SUM(H9:H21) -> 55000 | I22: =SUM(I9:I21) -> 55000 | J22: =SUM(J9:J21) -> 55000 | K22: =SUM(K9:K21) -> 55000 | L22: =SUM(L9:L21) -> 0 | M22: =SUM(M9:M21) -> 50000 | ... R22: =SUM(R9:R21) -> 50000 | S22: =SUM(S16:S21) -> 0 | T22: =SUM(T9:T21) -> 50000 | U22: =SUM(U9:U21) -> 50000 | V22: =SUM(V9:V21) -> 50000 | W22: =SUM(W9:W21) -> 50000 | X22: =SUM(X9:X21) -> 50000 | Y22: =SUM(Y9:Y21) -> 50000 | Z22: =SUM(Z16:Z21) -> 0 | AA22: =SUM(AA9:AA21) -> 0 | AB22: =SUM(AB9:AB21) -> 50000 | AC22: =SUM(AC9:AC21) -> 50000 | AD22: =SUM(AD9:AD21) -> 50000 | AE22: =SUM(AE9:AE21) -> 50000 | AF22: =SUM(AF9:AF21) -> 50000 | AG22: =SUM(AG16:AG21) -> 0 | AH22: =SUM(AH9:AH21) -> 50000 | AI22: =SUM(AI9:AI21) -> 50000 | AJ22: =SUM(AJ9:AJ21) -> 50000 | AK22: =SUM(AK9:AK21) -> 50000 | AL22: =SUM(AL9:AL21) -> 50000 | AM22: =SUM(AM9:AM21) -> 50000 | AN22: =SUM(AN16:AN21) -> 0 | AO22: =SUM(AO9:AO21) -> 50000 | AP22: =SUM(AP9:AP21) -> 50000 | AQ22: =SUM(AQ9:AQ21) -> 50000 | AR22: =SUM(AR9:AR21) -> 50000 | AS22: =SUM(AS9:AS21) -> 50000 | AT22: =SUM(AT9:AT21) -> 50000 | AU22: =SUM(F22:AT22) -> 1780000
B23: ACUMULADO DE EGRESOS | F23: =F22 -> 55000 | G23: =F23+G22 -> 110000 | H23: =G23+H22 -> 165000 | I23: =H23+I22 -> 220000 | J23: =I23+J22 -> 275000 | K23: =J23+K22 -> 330000 | L23: =K23+L22 -> 330000 | M23: =L23+M22 -> 380000 | N23: =M23+N22 -> 430000 | ... AU23: =AT23+AU22 -> 3560000
B26: INGRESOS
B28: CONCEPTO
B29: COSTO INDIRECTOS
B30: ANTICIPO (INICIO DE OBRA) | C30: 0.2 | D30: 60000000 | F30: =D30 -> 60000000 | G30: =$F$9 -> 50000 | H30: =$F$9 -> 50000 | I30: =$F$9 -> 50000 | J30: =$F$9 -> 50000 | K30: =$F$9 -> 50000 | L30: 0 | M30: =$F$9 -> 50000 | N30: =$F$9 -> 50000 | O30: =$F$9 -> 50000 | P30: =$F$9 -> 50000 | Q30: =$F$9 -> 50000 | R30: =$F$9 -> 50000 | S30: 0 | T30: =$F$9 -> 50000 | U30: =$F$9 -> 50000 | V30: =$F$9 -> 50000 | W30: =$F$9 -> 50000 | X30: =$F$9 -> 50000 | Y30: =$F$9 -> 50000 | Z30: 0 | AA30: 0 | AB30: =$F$9 -> 50000 | AC30: =$F$9 -> 50000 | AD30: =$F$9 -> 50000 | AE30: =$F$9 -> 50000 | AF30: =$F$9 -> 50000 | AG30: 0 | AH30: =$F$9 -> 50000 | AI30: =$F$9 -> 50000 | AJ30: =$F$9 -> 50000 | AK30: =$F$9 -> 50000 | AL30: =$F$9 -> 50000 | AM30: =$F$9 -> 50000 | AN30: 0 | AO30: =$F$9 -> 50000 | AP30: =$F$9 -> 50000 | AQ30: =$F$9 -> 50000 | AR30: =$F$9 -> 50000 | AS30: =$F$9 -> 50000 | AT30: =$F$9 -> 50000 | AU30: =SUM(F30:AT30) -> 61700000
B31: PRESTAMO FRESHOUSE 1 | C31: 0.5 | F31: =D31 -> 0 | G31: =$D$10*$C$10 -> 0 | H31: =$D$10*$C$10 -> 0 | I31: =$D$10*$C$10 -> 0 | J31: =$D$10*$C$10 -> 0 | K31: =$D$10*$C$10 -> 0 | L31: 0 | M31: =$D$10*$C$10 -> 0 | N31: =$D$10*$C$10 -> 0 | O31: =$D$10*$C$10 -> 0 | P31: =$D$10*$C$10 -> 0 | Q31: =$D$10*$C$10 -> 0 | R31: =$D$10*$C$10 -> 0 | S31: 0 | T31: =$D$10*$C$10 -> 0 | U31: =$D$10*$C$10 -> 0 | V31: =$D$10*$C$10 -> 0 | W31: =$D$10*$C$10 -> 0 | X31: =$D$10*$C$10 -> 0 | Y31: =$D$10*$C$10 -> 0 | Z31: 0 | AA31: =$D$10*$C$10 -> 0 | AB31: =$D$10*$C$10 -> 0 | AC31: =$D$10*$C$10 -> 0 | AD31: =$D$9*$C$10 -> 0 | AE31: =$D$10*$C$10 -> 0 | AF31: =$D$10*$C$10 -> 0 | AG31: 0 | AH31: =$D$10*$C$10 -> 0 | AI31: =$D$10*$C$10 -> 0 | AJ31: =$D$10*$C$10 -> 0 | AK31: =$D$10*$C$10 -> 0 | AL31: =$D$10*$C$10 -> 0 | AM31: =$D$10*$C$10 -> 0 | AN31: 0 | AO31: =$D$10*$C$10 -> 0 | AP31: =$D$10*$C$10 -> 0 | AQ31: =$D$10*$C$10 -> 0 | AR31: =$D$10*$C$10 -> 0 | AS31: =$D$10*$C$10 -> 0 | AT31: =$D$10*$C$10 -> 0 | AU31: =SUM(F31:AT31) -> 0
B32: PRESTAMO FRESHOUSE 2 | C32: 1.5
B35: TOTAL INGRESOS | F35: =SUM(F30:F34) -> 60000000 | G35: =SUM(G30:G34) -> 50000 | H35: =SUM(H30:H34) -> 50000 | I35: =SUM(I30:I34) -> 50000 | J35: =SUM(J30:J34) -> 50000 | K35: =SUM(K30:K34) -> 50000 | L35: =SUM(L30:L34) -> 0 | M35: =SUM(M30:M34) -> 50000 | ... R35: =SUM(R30:R34) -> 50000 | S35: =SUM(S34:S34) -> 0 | T35: =SUM(T30:T34) -> 50000 | U35: =SUM(U30:U34) -> 50000 | V35: =SUM(V30:V34) -> 50000 | W35: =SUM(W30:W34) -> 50000 | X35: =SUM(X30:X34) -> 50000 | Y35: =SUM(Y30:Y34) -> 50000 | Z35: =SUM(Z34:Z34) -> 0 | AA35: =SUM(AA30:AA34) -> 0 | AB35: =SUM(AB30:AB34) -> 50000 | AC35: =SUM(AC30:AC34) -> 50000 | AD35: =SUM(AD30:AD34) -> 50000 | AE35: =SUM(AE30:AE34) -> 50000 | AF35: =SUM(AF30:AF34) -> 50000 | AG35: =SUM(AG34:AG34) -> 0 | AH35: =SUM(AH30:AH34) -> 50000 | AI35: =SUM(AI30:AI34) -> 50000 | AJ35: =SUM(AJ30:AJ34) -> 50000 | AK35: =SUM(AK30:AK34) -> 50000 | AL35: =SUM(AL30:AL34) -> 50000 | AM35: =SUM(AM30:AM34) -> 50000 | AN35: =SUM(AN34:AN34) -> 0 | AO35: =SUM(AO30:AO34) -> 50000 | AP35: =SUM(AP30:AP34) -> 50000 | AQ35: =SUM(AQ30:AQ34) -> 50000 | AR35: =SUM(AR30:AR34) -> 50000 | AS35: =SUM(AS30:AS34) -> 50000 | AT35: =SUM(AT30:AT34) -> 50000 | AU35: =SUM(F35:AT35) -> 61700000
B36: ACUMULADO DE INGRESOS | F36: =F35 -> 60000000 | G36: =F36+G35 -> 60050000 | H36: =G36+H35 -> 60100000 | I36: =H36+I35 -> 60150000 | J36: =I36+J35 -> 60200000 | K36: =J36+K35 -> 60250000 | L36: =K36+L35 -> 60250000 | M36: =L36+M35 -> 60300000 | N36: =M36+N35 -> 60350000 | ... AU36: =AT36+AU35 -> 123400000
B39: SALDOS
B41: TOTAL SALDO | F41: =F35-F22 -> 59945000 | G41: =G35-G22 -> -5000 | H41: =H35-H22 -> -5000 | I41: =I35-I22 -> -5000 | J41: =J35-J22 -> -5000 | K41: =K35-K22 -> -5000 | L41: =L35-L22 -> 0 | M41: =M35-M22 -> 0 | ... AT41: =AT35-AT22 -> 0 | AU41: =SUM(F41:AT41) -> 59920000
B42: ACUMULADO DE SALDOS | F42: =F41 -> 59945000 | G42: =F42+G41 -> 59940000 | H42: =G42+H41 -> 59935000 | I42: =H42+I41 -> 59930000 | J42: =I42+J41 -> 59925000 | K42: =J42+K41 -> 59920000 | L42: =K42+L41 -> 59920000 | M42: =L42+M41 -> 59920000 | N42: =M42+N41 -> 59920000 | ... AU42: =AT42+AU41 -> 119840000
F44: =420000/65 -> 6461.5385

Sheet RESANE
A2: EDIFICIO TORRE VERDE | Q2: CANTIDAD EJECUTADA | AC2: TOTAL EJECUTADO | AQ2: TOTAL EJECUTADO | BE2: TOTAL EJECUTADO | BG2: CANTIDAD EJECUTADA | BS2: TOTAL EJECUTADO | CG2: TOTAL EJECUTADO | CU2: TOTAL EJECUTADO
A3: REALIZADO POR: ARQ ALEXIS BETANCOURT | E3: DIMENSIONES | H3: DESCUENTOS | Q3: 45817 | S3: =+Q3+1 -> 45818 | U3: =+S3+1 -> 45819 | W3: =+U3+1 -> 45820 | Y3: =+W3+1 -> 45821 | AA3: =+Y3+1 -> 45822 | AC3: SEMANA 1 | AE3: =AA3+2 -> 45824 | AG3: =+AE3+1 -> 45825 | AI3: =+AG3+1 -> 45826 | AK3: =+AI3+1 -> 45827 | AM3: =+AK3+1 -> 45828 | AO3: =+AM3+1 -> 45829 | AQ3: SEMANA 2 | AS3: =AO3+2 -> 45831 | AU3: =+AS3+1 -> 45832 | AW3: =+AU3+1 -> 45833 | AY3: =+AW3+1 -> 45834 | BA3: =+AY3+1 -> 45835 | BC3: =+BA3+1 -> 45836 | BE3: SEMANA 3 | BG3: =BC3+2 -> 45838 | BI3: =+BG3+1 -> 45839 | BK3: =+BI3+1 -> 45840 | BM3: =+BK3+1 -> 45841 | BO3: =+BM3+1 -> 45842 | BQ3: =+BO3+1 -> 45843 | BS3: SEMANA 4 | BU3: =BQ3+2 -> 45845 | BW3: =+BU3+1 -> 45846 | BY3: =+BW3+1 -> 45847 | CA3: =+BY3+1 -> 45848 | CC3: =+CA3+1 -> 45849 | CE3: =+CC3+1 -> 45850 | CG3: SEMANA 5 | CI3: =CE3+2 -> 45852 | CK3: =+CI3+1 -> 45853 | CM3: =+CK3+1 -> 45854 | CO3: =+CM3+1 -> 45855 | CQ3: =+CO3+1 -> 45856 | CS3: =+CQ3+1 -> 45857 | CU3: SEMANA 6
A4: TORRE | B4: FACHADA | C4: SECCIÓN | D4: DESCRIPCIÓN | E4: ALTO | F4: ANCHO | G4: TOTAL (M2) | H4: ALTO | I4: ANCHO | J4: CANTIDAD | K4: TOTAL (M2) | L4: ÁREA TOTAL (BLANCO) | M4: ÁREA TOTAL (VERDE) | N4: ÁREA TOTAL (NEGRO) | O4: CIELO RASO | Q4: M2 | R4: % | S4: M2 | T4: % | U4: M2 | V4: % | W4: M2 | X4: % | Y4: M2 | Z4: % | AB4: % | AC4: M2 | AD4: % | AE4: M2 | AF4: % | AG4: M2 | AH4: % | AI4: M2 | AJ4: % | AK4: M2 | AL4: % | AM4: M2 | AN4: % | AP4: % | AQ4: M2 | AR4: % | AS4: M2 | AT4: % | AU4: M2 | AV4: % | AW4: M2 | AX4: % | AY4: M2 | AZ4: % | BA4: M2 | BB4: % | BD4: % | BE4: M2 | BF4: % | BG4: M2 | BH4: % | BI4: M2 | BJ4: % | BK4: M2 | BL4: % | BM4: M2 | BN4: % | BO4: M2 | BP4: % | BR4: % | BS4: M2 | BT4: % | BU4: M2 | BV4: % | BW4: M2 | BX4: % | BY4: M2 | BZ4: % | CA4: M2 | CB4: % | CC4: M2 | CD4: % | CF4: % | CG4: M2 | CH4: % | CI4: M2 | CJ4: % | CK4: M2 | CL4: % | CM4: M2 | CN4: % | CO4: M2 | CP4: % | CQ4: M2 | CR4: % | CT4: % | CU4: M2 | CV4: %
A5: B | B5: CULATA IZQ | C5: 1 | D5: Muro con ventana (Negro) | E5: =(2.5*14)+0.6 -> 35.6 | F5: 9.7 | G5: =E5*F5 -> 345.32 | H5: 1.5 | I5: 1.2 | J5: 14 | K5: =(H5*I5)*J5 -> 25.2 | N5: =G5-(K5+K6) -> 318.86 | P5: =SUM(L5:O5) -> 318.86 | Q5: 0 | R5: =Q5/$P5 -> 0 | S5: 0 | T5: =S5/$P5 -> 0 | U5: 0 | V5: =U5/$P5 -> 0 | W5: 0 | X5: =W5/$P5 -> 0 | Y5: 0 | Z5: =Y5/$P5 -> 0 | AA5: 0 | AB5: =AA5/$P5 -> 0 | AC5: =Q5+S5+U5+W5+Y5+AA5 -> 0 | AD5: =AC5/$P5 -> 0 | AE5: 0 | AF5: =AE5/$P5 -> 0 | AG5: 0 | AH5: =AG5/$P5 -> 0 | AI5: 0 | AJ5: =AI5/$P5 -> 0 | AK5: 0 | AL5: =AK5/$P5 -> 0 | AM5: 0 | AN5: =AM5/$P5 -> 0 | AO5: 0 | AP5: =AO5/$P5 -> 0 | AQ5: =AE5+AG5+AI5+AK5+AM5+AO5 -> 0 | AR5: =AQ5/$P5 -> 0 | AS5: 0 | AT5: =AS5/$P5 -> 0 | AU5: 0 | AV5: =AU5/$P5 -> 0 | AW5: 0 | AX5: =AW5/$P5 -> 0 | AY5: 0 | AZ5: =AY5/$P5 -> 0 | BA5: 0 | BB5: =BA5/$P5 -> 0 | BC5: 0 | BD5: =BC5/$P5 -> 0 | BE5: =AS5+AU5+AW5+AY5+BA5+BC5 -> 0 | BF5: =BE5/$P5 -> 0 | BG5: 0 | BH5: =BG5/$P5 -> 0 | BI5: 0 | BJ5: =BI5/$P5 -> 0 | BK5: 0 | BL5: =BK5/$P5 -> 0 | BM5: 0 | BN5: =BM5/$P5 -> 0 | BO5: 0 | BP5: =BO5/$P5 -> 0 | BQ5: 0 | BR5: =BQ5/$P5 -> 0 | BS5: =BG5+BI5+BK5+BM5+BO5+BQ5 -> 0 | BT5: =BS5/$P5 -> 0 | BU5: 0 | BV5: =BU5/$P5 -> 0 | BW5: 0 | BX5: =BW5/$P5 -> 0 | BY5: 0 | BZ5: =BY5/$P5 -> 0 | CA5: 0 | CB5: =CA5/$P5 -> 0 | CC5: 0 | CD5: =CC5/$P5 -> 0 | CE5: 0 | CF5: =CE5/$P5 -> 0 | CG5: =BU5+BW5+BY5+CA5+CC5+CE5 -> 0 | CH5: =CG5/$P5 -> 0 | CI5: 0 | CJ5: =CI5/$P5 -> 0 | CK5: 0 | CL5: =CK5/$P5 -> 0 | CM5: 0 | CN5: =CM5/$P5 -> 0 | CO5: 0 | CP5: =CO5/$P5 -> 0 | CQ5: 0 | CR5: =CQ5/$P5 -> 0 | CS5: 0 | CT5: =CS5/$P5 -> 0 | CU5: =CI5+CK5+CM5+CO5+CQ5+CS5 -> 0 | CV5: =CU5/$P5 -> 0
H6: 0.3 | I6: 0.3 | J6: 14 | K6: =(H6*I6)*J6 -> 1.26 | P6: =SUM(L6:O6) -> 0 | Q6: 0 | S6: 0 | U6: 0 | W6: 0 | Y6: 0 | AA6: 0 | AC6: =Q6+S6+U6+W6+Y6+AA6 -> 0 | AE6: 0 | AG6: 0 | AI6: 0 | AK6: 0 | AM6: 0 | AO6: 0 | AQ6: =AE6+AG6+AI6+AK6+AM6+AO6 -> 0 | AS6: 0 | AU6: 0 | AW6: 0 | AY6: 0 | BA6: 0 | BC6: 0 | BE6: =AS6+AU6+AW6+AY6+BA6+BC6 -> 0 | BG6: 0 | BI6: 0 | BK6: 0 | BM6: 0 | BO6: 0 | BQ6: 0 | BS6: =BG6+BI6+BK6+BM6+BO6+BQ6 -> 0 | BU6: 0 | BW6: 0 | BY6: 0 | CA6: 0 | CC6: 0 | CE6: 0 | CG6: =BU6+BW6+BY6+CA6+CC6+CE6 -> 0 | CI6: 0 | CK6: 0 | CM6: 0 | CO6: 0 | CQ6: 0 | CS6: 0 | CU6: =CI6+CK6+CM6+CO6+CQ6+CS6 -> 0
B7: POSTERIOR | C7: 2 | D7: Muro con ventana (Negro) | E7: =E5 -> 35.6 | F7: 6.1 | G7: =E7*F7 -> 217.16 | H7: 1.5 | I7: 1.2 | J7: 28 | K7: =(H7*I7)*J7 -> 50.4 | N7: =G7-K7 -> 166.76 | P7: =SUM(L7:O7) -> 166.76 | Q7: 0 | R7: =Q7/$P7 -> 0 | S7: 0 | T7: =S7/$P7 -> 0 | U7: 0 | V7: =U7/$P7 -> 0 | W7: 0 | X7: =W7/$P7 -> 0 | Y7: 0 | Z7: =Y7/$P7 -> 0 | AA7: 0 | AB7: =AA7/$P7 -> 0 | AC7: =Q7+S7+U7+W7+Y7+AA7 -> 0 | AD7: =AC7/$P7 -> 0 | AE7: 0 | AF7: =AE7/$P7 -> 0 | AG7: 0 | AH7: =AG7/$P7 -> 0 | AI7: 0 | AJ7: =AI7/$P7 -> 0 | AK7: 0 | AL7: =AK7/$P7 -> 0 | AM7: 0 | AN7: =AM7/$P7 -> 0 | AO7: 0 | AP7: =AO7/$P7 -> 0 | AQ7: =AE7+AG7+AI7+AK7+AM7+AO7 -> 0 | AR7: =AQ7/$P7 -> 0 | AS7: 0 | AT7: =AS7/$P7 -> 0 | AU7: 0 | AV7: =AU7/$P7 -> 0 | AW7: 0 | AX7: =AW7/$P7 -> 0 | AY7: 0 | AZ7: =AY7/$P7 -> 0 | BA7: 0 | BB7: =BA7/$P7 -> 0 | BC7: 0 | BD7: =BC7/$P7 -> 0 | BE7: =AS7+AU7+AW7+AY7+BA7+BC7 -> 0 | BF7: =BE7/$P7 -> 0 | BG7: 0 | BH7: =BG7/$P7 -> 0 | BI7: 0 | BJ7: =BI7/$P7 -> 0 | BK7: 0 | BL7: =BK7/$P7 -> 0 | BM7: 0 | BN7: =BM7/$P7 -> 0 | BO7: 0 | BP7: =BO7/$P7 -> 0 | BQ7: 0 | BR7: =BQ7/$P7 -> 0 | BS7: =BG7+BI7+BK7+BM7+BO7+BQ7 -> 0 | BT7: =BS7/$P7 -> 0 | BU7: 0 | BV7: =BU7/$P7 -> 0 | BW7: 0 | BX7: =BW7/$P7 -> 0 | BY7: 0 | BZ7: =BY7/$P7 -> 0 | CA7: 0 | CB7: =CA7/$P7 -> 0 | CC7: 0 | CD7: =CC7/$P7 -> 0 | CE7: 0 | CF7: =CE7/$P7 -> 0 | CG7: =BU7+BW7+BY7+CA7+CC7+CE7 -> 0 | CH7: =CG7/$P7 -> 0 | CI7: 0 | CJ7: =CI7/$P7 -> 0 | CK7: 0 | CL7: =CK7/$P7 -> 0 | CM7: 0 | CN7: =CM7/$P7 -> 0 | CO7: 0 | CP7: =CO7/$P7 -> 0 | CQ7: 0 | CR7: =CQ7/$P7 -> 0 | CS7: 0 | CT7: =CS7/$P7 -> 0 | CU7: =CI7+CK7+CM7+CO7+CQ7+CS7 -> 0 | CV7: =CU7/$P7 -> 0
C8: 3 | D8: Muro escaleras (Negro) | E8: 35 | F8: 3.1 | G8: =E8*F8 -> 108.5 | H8: 0.25 | I8: 3.1 | J8: 14 | K8: =(H8*I8)*J8 -> 10.85 | N8: =G8-K8 -> 97.65 | P8: =SUM(L8:O8) -> 97.65 | Q8: 0 | R8: =Q8/$P8 -> 0 | S8: 0 | T8: =S8/$P8 -> 0 | U8: 0 | V8: =U8/$P8 -> 0 | W8: 0 | X8: =W8/$P8 -> 0 | Y8: 0 | Z8: =Y8/$P8 -> 0 | AA8: 0 | AB8: =AA8/$P8 -> 0 | AC8: =Q8+S8+U8+W8+Y8+AA8 -> 0 | AD8: =AC8/$P8 -> 0 | AE8: 0 | AF8: =AE8/$P8 -> 0 | AG8: 0 | AH8: =AG8/$P8 -> 0 | AI8: 0 | AJ8: =AI8/$P8 -> 0 | AK8: 0 | AL8: =AK8/$P8 -> 0 | AM8: 0 | AN8: =AM8/$P8 -> 0 | AO8: 0 | AP8: =AO8/$P8 -> 0 | AQ8: =AE8+AG8+AI8+AK8+AM8+AO8 -> 0 | AR8: =AQ8/$P8 -> 0 | AS8: 0 | AT8: =AS8/$P8 -> 0 | AU8: 0 | AV8: =AU8/$P8 -> 0 | AW8: 0 | AX8: =AW8/$P8 -> 0 | AY8: 0 | AZ8: =AY8/$P8 -> 0 | BA8: 0 | BB8: =BA8/$P8 -> 0 | BC8: 0 | BD8: =BC8/$P8 -> 0 | BE8: =AS8+AU8+AW8+AY8+BA8+BC8 -> 0 | BF8: =BE8/$P8 -> 0 | BG8: 0 | BH8: =BG8/$P8 -> 0 | BI8: 0 | BJ8: =BI8/$P8 -> 0 | BK8: 0 | BL8: =BK8/$P8 -> 0 | BM8: 0 | BN8: =BM8/$P8 -> 0 | BO8: 0 | BP8: =BO8/$P8 -> 0 | BQ8: 0 | BR8: =BQ8/$P8 -> 0 | BS8: =BG8+BI8+BK8+BM8+BO8+BQ8 -> 0 | BT8: =BS8/$P8 -> 0 | BU8: 0 | BV8: =BU8/$P8 -> 0 | BW8: 0 | BX8: =BW8/$P8 -> 0 | BY8: 0 | BZ8: =BY8/$P8 -> 0 | CA8: 0 | CB8: =CA8/$P8 -> 0 | CC8: 0 | CD8: =CC8/$P8 -> 0 | CE8: 0 | CF8: =CE8/$P8 -> 0 | CG8: =BU8+BW8+BY8+CA8+CC8+CE8 -> 0 | CH8: =CG8/$P8 -> 0 | CI8: 0 | CJ8: =CI8/$P8 -> 0 | CK8: 0 | CL8: =CK8/$P8 -> 0 | CM8: 0 | CN8: =CM8/$P8 -> 0 | CO8: 0 | CP8: =CO8/$P8 -> 0 | CQ8: 0 | CR8: =CQ8/$P8 -> 0 | CS8: 0 | CT8: =CS8/$P8 -> 0 | CU8: =CI8+CK8+CM8+CO8+CQ8+CS8 -> 0 | CV8: =CU8/$P8 -> 0
C9: 4 | D9: Muro escaleras (Blanco) | E9: 35 | F9: 2.15 | G9: =E9*F9 -> 75.25 | L9: =G9-K9 -> 75.25 | P9: =SUM(L9:O9) -> 75.25 | Q9: 0 | R9: =Q9/$P9 -> 0 | S9: 0 | T9: =S9/$P9 -> 0 | U9: 0 | V9: =U9/$P9 -> 0 | W9: 0 | X9: =W9/$P9 -> 0 | Y9: 0 | Z9: =Y9/$P9 -> 0 | AA9: 0 | AB9: =AA9/$P9 -> 0 | AC9: =Q9+S9+U9+W9+Y9+AA9 -> 0 | AD9: =AC9/$P9 -> 0 | AE9: 0 | AF9: =AE9/$P9 -> 0 | AG9: 0 | AH9: =AG9/$P9 -> 0 | AI9: 0 | AJ9: =AI9/$P9 -> 0 | AK9: 0 | AL9: =AK9/$P9 -> 0 | AM9: 0 | AN9: =AM9/$P9 -> 0 | AO9: 0 | AP9: =AO9/$P9 -> 0 | AQ9: =AE9+AG9+AI9+AK9+AM9+AO9 -> 0 | AR9: =AQ9/$P9 -> 0 | AS9: 0 | AT9: =AS9/$P9 -> 0 | AU9: 0 | AV9: =AU9/$P9 -> 0 | AW9: 0 | AX9: =AW9/$P9 -> 0 | AY9: 0 | AZ9: =AY9/$P9 -> 0 | BA9: 0 | BB9: =BA9/$P9 -> 0 | BC9: 0 | BD9: =BC9/$P9 -> 0 | BE9: =AS9+AU9+AW9+AY9+BA9+BC9 -> 0 | BF9: =BE9/$P9 -> 0 | BG9: 0 | BH9: =BG9/$P9 -> 0 | BI9: 0 | BJ9: =BI9/$P9 -> 0 | BK9: 0 | BL9: =BK9/$P9 -> 0 | BM9: 0 | BN9: =BM9/$P9 -> 0 | BO9: 0 | BP9: =BO9/$P9 -> 0 | BQ9: 0 | BR9: =BQ9/$P9 -> 0 | BS9: =BG9+BI9+BK9+BM9+BO9+BQ9 -> 0 | BT9: =BS9/$P9 -> 0 | BU9: 0 | BV9: =BU9/$P9 -> 0 | BW9: 0 | BX9: =BW9/$P9 -> 0 | BY9: 0 | BZ9: =BY9/$P9 -> 0 | CA9: 0 | CB9: =CA9/$P9 -> 0 | CC9: 0 | CD9: =CC9/$P9 -> 0 | CE9: 0 | CF9: =CE9/$P9 -> 0 | CG9: =BU9+BW9+BY9+CA9+CC9+CE9 -> 0 | CH9: =CG9/$P9 -> 0 | CI9: 0 | CJ9: =CI9/$P9 -> 0 | CK9: 0 | CL9: =CK9/$P9 -> 0 | CM9: 0 | CN9: =CM9/$P9 -> 0 | CO9: 0 | CP9: =CO9/$P9 -> 0 | CQ9: 0 | CR9: =CQ9/$P9 -> 0 | CS9: 0 | CT9: =CS9/$P9 -> 0 | CU9: =CI9+CK9+CM9+CO9+CQ9+CS9 -> 0 | CV9: =CU9/$P9 -> 0
C10: 5 | D10: Muro escaleras (Blanco) | E10: =E8 -> 35 | F10: 1.8 | G10: =E10*F10 -> 63 | L10: =G10-K10 -> 63 | P10: =SUM(L10:O10) -> 63 | Q10: 0 | R10: =Q10/$P10 -> 0 | S10: 0 | T10: =S10/$P10 -> 0 | U10: 0 | V10: =U10/$P10 -> 0 | W10: 0 | X10: =W10/$P10 -> 0 | Y10: 0 | Z10: =Y10/$P10 -> 0 | AA10: 0 | AB10: =AA10/$P10 -> 0 | AC10: =Q10+S10+U10+W10+Y10+AA10 -> 0 | AD10: =AC10/$P10 -> 0 | AE10: 0 | AF10: =AE10/$P10 -> 0 | AG10: 0 | AH10: =AG10/$P10 -> 0 | AI10: 0 | AJ10: =AI10/$P10 -> 0 | AK10: 0 | AL10: =AK10/$P10 -> 0 | AM10: 0 | AN10: =AM10/$P10 -> 0 | AO10: 0 | AP10: =AO10/$P10 -> 0 | AQ10: =AE10+AG10+AI10+AK10+AM10+AO10 -> 0 | AR10: =AQ10/$P10 -> 0 | AS10: 0 | AT10: =AS10/$P10 -> 0 | AU10: 0 | AV10: =AU10/$P10 -> 0 | AW10: 0 | AX10: =AW10/$P10 -> 0 | AY10: 0 | AZ10: =AY10/$P10 -> 0 | BA10: 0 | BB10: =BA10/$P10 -> 0 | BC10: 0 | BD10: =BC10/$P10 -> 0 | BE10: =AS10+AU10+AW10+AY10+BA10+BC10 -> 0 | BF10: =BE10/$P10 -> 0 | BG10: 0 | BH10: =BG10/$P10 -> 0 | BI10: 0 | BJ10: =BI10/$P10 -> 0 | BK10: 0 | BL10: =BK10/$P10 -> 0 | BM10: 0 | BN10: =BM10/$P10 -> 0 | BO10: 0 | BP10: =BO10/$P10 -> 0 | BQ10: 0 | BR10: =BQ10/$P10 -> 0 | BS10: =BG10+BI10+BK10+BM10+BO10+BQ10 -> 0 | BT10: =BS10/$P10 -> 0 | BU10: 0 | BV10: =BU10/$P10 -> 0 | BW10: 0 | BX10: =BW10/$P10 -> 0 | BY10: 0 | BZ10: =BY10/$P10 -> 0 | CA10: 0 | CB10: =CA10/$P10 -> 0 | CC10: 0 | CD10: =CC10/$P10 -> 0 | CE10: 0 | CF10: =CE10/$P10 -> 0 | CG10: =BU10+BW10+BY10+CA10+CC10+CE10 -> 0 | CH10: =CG10/$P10 -> 0 | CI10: 0 | CJ10: =CI10/$P10 -> 0 | CK10: 0 | CL10: =CK10/$P10 -> 0 | CM10: 0 | CN10: =CM10/$P10 -> 0 | CO10: 0 | CP10: =CO10/$P10 -> 0 | CQ10: 0 | CR10: =CQ10/$P10 -> 0 | CS10: 0 | CT10: =CS10/$P10 -> 0 | CU10: =CI10+CK10+CM10+CO10+CQ10+CS10 -> 0 | CV10: =CU10/$P10 -> 0
C11: 6 | D11: Muro escaleras (Blanco) | E11: =E8 -> 35 | F11: 2.05 | G11: =E11*F11 -> 71.75 | L11: =G11-K11 -> 71.75 | P11: =SUM(L11:O11) -> 71.75 | Q11: 0 | R11: =Q11/$P11 -> 0 | S11: 0 | T11: =S11/$P11 -> 0 | U11: 0 | V11: =U11/$P11 -> 0 | W11: 0 | X11: =W11/$P11 -> 0 | Y11: 0 | Z11: =Y11/$P11 -> 0 | AA11: 0 | AB11: =AA11/$P11 -> 0 | AC11: =Q11+S11+U11+W11+Y11+AA11 -> 0 | AD11: =AC11/$P11 -> 0 | AE11: 0 | AF11: =AE11/$P11 -> 0 | AG11: 0 | AH11: =AG11/$P11 -> 0 | AI11: 0 | AJ11: =AI11/$P11 -> 0 | AK11: 0 | AL11: =AK11/$P11 -> 0 | AM11: 0 | AN11: =AM11/$P11 -> 0 | AO11: 0 | AP11: =AO11/$P11 -> 0 | AQ11: =AE11+AG11+AI11+AK11+AM11+AO11 -> 0 | AR11: =AQ11/$P11 -> 0 | AS11: 0 | AT11: =AS11/$P11 -> 0 | AU11: 0 | AV11: =AU11/$P11 -> 0 | AW11: 0 | AX11: =AW11/$P11 -> 0 | AY11: 0 | AZ11: =AY11/$P11 -> 0 | BA11: 0 | BB11: =BA11/$P11 -> 0 | BC11: 0 | BD11: =BC11/$P11 -> 0 | BE11: =AS11+AU11+AW11+AY11+BA11+BC11 -> 0 | BF11: =BE11/$P11 -> 0 | BG11: 0 | BH11: =BG11/$P11 -> 0 | BI11: 0 | BJ11: =BI11/$P11 -> 0 | BK11: 0 | BL11: =BK11/$P11 -> 0 | BM11: 0 | BN11: =BM11/$P11 -> 0 | BO11: 0 | BP11: =BO11/$P11 -> 0 | BQ11: 0 | BR11: =BQ11/$P11 -> 0 | BS11: =BG11+BI11+BK11+BM11+BO11+BQ11 -> 0 | BT11: =BS11/$P11 -> 0 | BU11: 0 | BV11: =BU11/$P11 -> 0 | BW11: 0 | BX11: =BW11/$P11 -> 0 | BY11: 0 | BZ11: =BY11/$P11 -> 0 | CA11: 0 | CB11: =CA11/$P11 -> 0 | CC11: 0 | CD11: =CC11/$P11 -> 0 | CE11: 0 | CF11: =CE11/$P11 -> 0 | CG11: =BU11+BW11+BY11+CA11+CC11+CE11 -> 0 | CH11: =CG11/$P11 -> 0 | CI11: 0 | CJ11: =CI11/$P11 -> 0 | CK11: 0 | CL11: =CK11/$P11 -> 0 | CM11: 0 | CN11: =CM11/$P11 -> 0 | CO11: 0 | CP11: =CO11/$P11 -> 0 | CQ11: 0 | CR11: =CQ11/$P11 -> 0 | CS11: 0 | CT11: =CS11/$P11 -> 0 | CU11: =CI11+CK11+CM11+CO11+CQ11+CS11 -> 0 | CV11: =CU11/$P11 -> 0
C12: 7 | D12: Antepecho poseta PF (Blanco) (X14) | E12: 0.5 | F12: 1.44 | G12: =E12*F12*14 -> 10.08 | L12: =G12-K12 -> 10.08 | P12: =SUM(L12:O12) -> 10.08 | Q12: 0 | R12: =Q12/$P12 -> 0 | S12: 0 | T12: =S12/$P12 -> 0 | U12: 0 | V12: =U12/$P12 -> 0 | W12: 0 | X12: =W12/$P12 -> 0 | Y12: 0 | Z12: =Y12/$P12 -> 0 | AA12: 0 | AB12: =AA12/$P12 -> 0 | AC12: =Q12+S12+U12+W12+Y12+AA12 -> 0 | AD12: =AC12/$P12 -> 0 | AE12: 0 | AF12: =AE12/$P12 -> 0 | AG12: 0 | AH12: =AG12/$P12 -> 0 | AI12: 0 | AJ12: =AI12/$P12 -> 0 | AK12: 0 | AL12: =AK12/$P12 -> 0 | AM12: 0 | AN12: =AM12/$P12 -> 0 | AO12: 0 | AP12: =AO12/$P12 -> 0 | AQ12: =AE12+AG12+AI12+AK12+AM12+AO12 -> 0 | AR12: =AQ12/$P12 -> 0 | AS12: 0 | AT12: =AS12/$P12 -> 0 | AU12: 0 | AV12: =AU12/$P12 -> 0 | AW12: 0 | AX12: =AW12/$P12 -> 0 | AY12: 0 | AZ12: =AY12/$P12 -> 0 | BA12: 0 | BB12: =BA12/$P12 -> 0 | BC12: 0 | BD12: =BC12/$P12 -> 0 | BE12: =AS12+AU12+AW12+AY12+BA12+BC12 -> 0 | BF12: =BE12/$P12 -> 0 | BG12: 0 | BH12: =BG12/$P12 -> 0 | BI12: 0 | BJ12: =BI12/$P12 -> 0 | BK12: 0 | BL12: =BK12/$P12 -> 0 | BM12: 0 | BN12: =BM12/$P12 -> 0 | BO12: 0 | BP12: =BO12/$P12 -> 0 | BQ12: 0 | BR12: =BQ12/$P12 -> 0 | BS12: =BG12+BI12+BK12+BM12+BO12+BQ12 -> 0 | BT12: =BS12/$P12 -> 0 | BU12: 0 | BV12: =BU12/$P12 -> 0 | BW12: 0 | BX12: =BW12/$P12 -> 0 | BY12: 0 | BZ12: =BY12/$P12 -> 0 | CA12: 0 | CB12: =CA12/$P12 -> 0 | CC12: 0 | CD12: =CC12/$P12 -> 0 | CE12: 0 | CF12: =CE12/$P12 -> 0 | CG12: =BU12+BW12+BY12+CA12+CC12+CE12 -> 0 | CH12: =CG12/$P12 -> 0 | CI12: 0 | CJ12: =CI12/$P12 -> 0 | CK12: 0 | CL12: =CK12/$P12 -> 0 | CM12: 0 | CN12: =CM12/$P12 -> 0 | CO12: 0 | CP12: =CO12/$P12 -> 0 | CQ12: 0 | CR12: =CQ12/$P12 -> 0 | CS12: 0 | CT12: =CS12/$P12 -> 0 | CU12: =CI12+CK12+CM12+CO12+CQ12+CS12 -> 0 | CV12: =CU12/$P12 -> 0
C13: 8 | D13: Muro escaleras (Blanco) | E13: 35 | F13: 5.18 | G13: =E13*F13 -> 181.3 | H13: 0.25 | I13: 3.1 | J13: 14 | K13: =(H13*I13)*J13 -> 10.85 | L13: =G13-K13 -> 170.45 | P13: =SUM(L13:O13) -> 170.45 | Q13: 0 | R13: =Q13/$P13 -> 0 | S13: 0 | T13: =S13/$P13 -> 0 | U13: 0 | V13: =U13/$P13 -> 0 | W13: 0 | X13: =W13/$P13 -> 0 | Y13: 0 | Z13: =Y13/$P13 -> 0 | AA13: 0 | AB13: =AA13/$P13 -> 0 | AC13: =Q13+S13+U13+W13+Y13+AA13 -> 0 | AD13: =AC13/$P13 -> 0 | AE13: 0 | AF13: =AE13/$P13 -> 0 | AG13: 0 | AH13: =AG13/$P13 -> 0 | AI13: 0 | AJ13: =AI13/$P13 -> 0 | AK13: 0 | AL13: =AK13/$P13 -> 0 | AM13: 0 | AN13: =AM13/$P13 -> 0 | AO13: 0 | AP13: =AO13/$P13 -> 0 | AQ13: =AE13+AG13+AI13+AK13+AM13+AO13 -> 0 | AR13: =AQ13/$P13 -> 0 | AS13: 0 | AT13: =AS13/$P13 -> 0 | AU13: 0 | AV13: =AU13/$P13 -> 0 | AW13: 0 | AX13: =AW13/$P13 -> 0 | AY13: 0 | AZ13: =AY13/$P13 -> 0 | BA13: 0 | BB13: =BA13/$P13 -> 0 | BC13: 0 | BD13: =BC13/$P13 -> 0 | BE13: =AS13+AU13+AW13+AY13+BA13+BC13 -> 0 | BF13: =BE13/$P13 -> 0 | BG13: 0 | BH13: =BG13/$P13 -> 0 | BI13: 0 | BJ13: =BI13/$P13 -> 0 | BK13: 0 | BL13: =BK13/$P13 -> 0 | BM13: 0 | BN13: =BM13/$P13 -> 0 | BO13: 0 | BP13: =BO13/$P13 -> 0 | BQ13: 0 | BR13: =BQ13/$P13 -> 0 | BS13: =BG13+BI13+BK13+BM13+BO13+BQ13 -> 0 | BT13: =BS13/$P13 -> 0 | BU13: 0 | BV13: =BU13/$P13 -> 0 | BW13: 0 | BX13: =BW13/$P13 -> 0 | BY13: 0 | BZ13: =BY13/$P13 -> 0 | CA13: 0 | CB13: =CA13/$P13 -> 0 | CC13: 0 | CD13: =CC13/$P13 -> 0 | CE13: 0 | CF13: =CE13/$P13 -> 0 | CG13: =BU13+BW13+BY13+CA13+CC13+CE13 -> 0 | CH13: =CG13/$P13 -> 0 | CI13: 0 | CJ13: =CI13/$P13 -> 0 | CK13: 0 | CL13: =CK13/$P13 -> 0 | CM13: 0 | CN13: =CM13/$P13 -> 0 | CO13: 0 | CP13: =CO13/$P13 -> 0 | CQ13: 0 | CR13: =CQ13/$P13 -> 0 | CS13: 0 | CT13: =CS13/$P13 -> 0 | CU13: =CI13+CK13+CM13+CO13+CQ13+CS13 -> 0 | CV13: =CU13/$P13 -> 0
C14: 8.1 | D14: Cielo raso escaleras (X14) | E14: 1 | F14: =2.15+1.44 -> 3.59 | G14: =E14*F14*14 -> 50.26 | O14: =G14 -> 50.26 | P14: =SUM(L14:O14) -> 50.26 | Q14: 0 | R14: =Q14/$P14 -> 0 | S14: 0 | T14: =S14/$P14 -> 0 | U14: 0 | V14: =U14/$P14 -> 0 | W14: 0 | X14: =W14/$P14 -> 0 | Y14: 0 | Z14: =Y14/$P14 -> 0 | AA14: 0 | AB14: =AA14/$P14 -> 0 | AC14: =Q14+S14+U14+W14+Y14+AA14 -> 0 | AD14: =AC14/$P14 -> 0 | AE14: 0 | AF14: =AE14/$P14 -> 0 | AG14: 0 | AH14: =AG14/$P14 -> 0 | AI14: 0 | AJ14: =AI14/$P14 -> 0 | AK14: 0 | AL14: =AK14/$P14 -> 0 | AM14: 0 | AN14: =AM14/$P14 -> 0 | AO14: 0 | AP14: =AO14/$P14 -> 0 | AQ14: =AE14+AG14+AI14+AK14+AM14+AO14 -> 0 | AR14: =AQ14/$P14 -> 0 | AS14: 0 | AT14: =AS14/$P14 -> 0 | AU14: 0 | AV14: =AU14/$P14 -> 0 | AW14: 0 | AX14: =AW14/$P14 -> 0 | AY14: 0 | AZ14: =AY14/$P14 -> 0 | BA14: 0 | BB14: =BA14/$P14 -> 0 | BC14: 0 | BD14: =BC14/$P14 -> 0 | BE14: =AS14+AU14+AW14+AY14+BA14+BC14 -> 0 | BF14: =BE14/$P14 -> 0 | BG14: 0 | BH14: =BG14/$P14 -> 0 | BI14: 0 | BJ14: =BI14/$P14 -> 0 | BK14: 0 | BL14: =BK14/$P14 -> 0 | BM14: 0 | BN14: =BM14/$P14 -> 0 | BO14: 0 | BP14: =BO14/$P14 -> 0 | BQ14: 0 | BR14: =BQ14/$P14 -> 0 | BS14: =BG14+BI14+BK14+BM14+BO14+BQ14 -> 0 | BT14: =BS14/$P14 -> 0 | BU14: 0 | BV14: =BU14/$P14 -> 0 | BW14: 0 | BX14: =BW14/$P14 -> 0 | BY14: 0 | BZ14: =BY14/$P14 -> 0 | CA14: 0 | CB14: =CA14/$P14 -> 0 | CC14: 0 | CD14: =CC14/$P14 -> 0 | CE14: 0 | CF14: =CE14/$P14 -> 0 | CG14: =BU14+BW14+BY14+CA14+CC14+CE14 -> 0 | CH14: =CG14/$P14 -> 0 | CI14: 0 | CJ14: =CI14/$P14 -> 0 | CK14: 0 | CL14: =CK14/$P14 -> 0 | CM14: 0 | CN14: =CM14/$P14 -> 0 | CO14: 0 | CP14: =CO14/$P14 -> 0 | CQ14: 0 | CR14: =CQ14/$P14 -> 0 | CS14: 0 | CT14: =CS14/$P14 -> 0 | CU14: =CI14+CK14+CM14+CO14+CQ14+CS14 -> 0 | CV14: =CU14/$P14 -> 0
C15: 9 | D15: Muro con ventana (Verde) | E15: =E5 -> 35.6 | F15: 5.3 | G15: =E15*F15 -> 188.68 | H15: 1.5 | I15: 1.2 | J15: 28 | K15: =(H15*I15)*J15 -> 50.4 | M15: =G15-K15 -> 138.28 | P15: =SUM(L15:O15) -> 138.28 | Q15: 0 | R15: =Q15/$P15 -> 0 | S15: 0 | T15: =S15/$P15 -> 0 | U15: 0 | V15: =U15/$P15 -> 0 | W15: 0 | X15: =W15/$P15 -> 0 | Y15: 0 | Z15: =Y15/$P15 -> 0 | AA15: 0 | AB15: =AA15/$P15 -> 0 | AC15: =Q15+S15+U15+W15+Y15+AA15 -> 0 | AD15: =AC15/$P15 -> 0 | AE15: 0 | AF15: =AE15/$P15 -> 0 | AG15: 0 | AH15: =AG15/$P15 -> 0 | AI15: 0 | AJ15: =AI15/$P15 -> 0 | AK15: 0 | AL15: =AK15/$P15 -> 0 | AM15: 0 | AN15: =AM15/$P15 -> 0 | AO15: 0 | AP15: =AO15/$P15 -> 0 | AQ15: =AE15+AG15+AI15+AK15+AM15+AO15 -> 0 | AR15: =AQ15/$P15 -> 0 | AS15: 0 | AT15: =AS15/$P15 -> 0 | AU15: 0 | AV15: =AU15/$P15 -> 0 | AW15: 0 | AX15: =AW15/$P15 -> 0 | AY15: 0 | AZ15: =AY15/$P15 -> 0 | BA15: 0 | BB15: =BA15/$P15 -> 0 | BC15: 0 | BD15: =BC15/$P15 -> 0 | BE15: =AS15+AU15+AW15+AY15+BA15+BC15 -> 0 | BF15: =BE15/$P15 -> 0 | BG15: 0 | BH15: =BG15/$P15 -> 0 | BI15: 0 | BJ15: =BI15/$P15 -> 0 | BK15: 0 | BL15: =BK15/$P15 -> 0 | BM15: 0 | BN15: =BM15/$P15 -> 0 | BO15: 0 | BP15: =BO15/$P15 -> 0 | BQ15: 0 | BR15: =BQ15/$P15 -> 0 | BS15: =BG15+BI15+BK15+BM15+BO15+BQ15 -> 0 | BT15: =BS15/$P15 -> 0 | BU15: 0 | BV15: =BU15/$P15 -> 0 | BW15: 0 | BX15: =BW15/$P15 -> 0 | BY15: 0 | BZ15: =BY15/$P15 -> 0 | CA15: 0 | CB15: =CA15/$P15 -> 0 | CC15: 0 | CD15: =CC15/$P15 -> 0 | CE15: 0 | CF15: =CE15/$P15 -> 0 | CG15: =BU15+BW15+BY15+CA15+CC15+CE15 -> 0 | CH15: =CG15/$P15 -> 0 | CI15: 0 | CJ15: =CI15/$P15 -> 0 | CK15: 0 | CL15: =CK15/$P15 -> 0 | CM15: 0 | CN15: =CM15/$P15 -> 0 | CO15: 0 | CP15: =CO15/$P15 -> 0 | CQ15: 0 | CR15: =CQ15/$P15 -> 0 | CS15: 0 | CT15: =CS15/$P15 -> 0 | CU15: =CI15+CK15+CM15+CO15+CQ15+CS15 -> 0 | CV15: =CU15/$P15 -> 0
C16: 10 | D16: Placa de balcón (Negro) (x14) | E16: 0.3 | F16: 2.91 | G16: =E16*F16*14 -> 12.222 | N16: =G16 -> 12.222 | P16: =SUM(L16:O16) -> 12.222 | Q16: 0 | R16: =Q16/$P16 -> 0 | S16: 0 | T16: =S16/$P16 -> 0 | U16: 0 | V16: =U16/$P16 -> 0 | W16: 0 | X16: =W16/$P16 -> 0 | Y16: 0 | Z16: =Y16/$P16 -> 0 | AA16: 0 | AB16: =AA16/$P16 -> 0 | AC16: =Q16+S16+U16+W16+Y16+AA16 -> 0 | AD16: =AC16/$P16 -> 0 | AE16: 0 | AF16: =AE16/$P16 -> 0 | AG16: 0 | AH16: =AG16/$P16 -> 0 | AI16: 0 | AJ16: =AI16/$P16 -> 0 | AK16: 0 | AL16: =AK16/$P16 -> 0 | AM16: 0 | AN16: =AM16/$P16 -> 0 | AO16: 0 | AP16: =AO16/$P16 -> 0 | AQ16: =AE16+AG16+AI16+AK16+AM16+AO16 -> 0 | AR16: =AQ16/$P16 -> 0 | AS16: 0 | AT16: =AS16/$P16 -> 0 | AU16: 0 | AV16: =AU16/$P16 -> 0 | AW16: 0 | AX16: =AW16/$P16 -> 0 | AY16: 0 | AZ16: =AY16/$P16 -> 0 | BA16: 0 | BB16: =BA16/$P16 -> 0 | BC16: 0 | BD16: =BC16/$P16 -> 0 | BE16: =AS16+AU16+AW16+AY16+BA16+BC16 -> 0 | BF16: =BE16/$P16 -> 0 | BG16: 0 | BH16: =BG16/$P16 -> 0 | BI16: 0 | BJ16: =BI16/$P16 -> 0 | BK16: 0 | BL16: =BK16/$P16 -> 0 | BM16: 0 | BN16: =BM16/$P16 -> 0 | BO16: 0 | BP16: =BO16/$P16 -> 0 | BQ16: 0 | BR16: =BQ16/$P16 -> 0 | BS16: =BG16+BI16+BK16+BM16+BO16+BQ16 -> 0 | BT16: =BS16/$P16 -> 0 | BU16: 0 | BV16: =BU16/$P16 -> 0 | BW16: 0 | BX16: =BW16/$P16 -> 0 | BY16: 0 | BZ16: =BY16/$P16 -> 0 | CA16: 0 | CB16: =CA16/$P16 -> 0 | CC16: 0 | CD16: =CC16/$P16 -> 0 | CE16: 0 | CF16: =CE16/$P16 -> 0 | CG16: =BU16+BW16+BY16+CA16+CC16+CE16 -> 0 | CH16: =CG16/$P16 -> 0 | CI16: 0 | CJ16: =CI16/$P16 -> 0 | CK16: 0 | CL16: =CK16/$P16 -> 0 | CM16: 0 | CN16: =CM16/$P16 -> 0 | CO16: 0 | CP16: =CO16/$P16 -> 0 | CQ16: 0 | CR16: =CQ16/$P16 -> 0 | CS16: 0 | CT16: =CS16/$P16 -> 0 | CU16: =CI16+CK16+CM16+CO16+CQ16+CS16 -> 0 | CV16: =CU16/$P16 -> 0
C17: 10.1 | D17: Cielo raso balcón (X14) | E17: 0.6 | F17: 1.71 | G17: =E17*F17*14 -> 14.364 | O17: =G17 -> 14.364 | P17: =SUM(L17:O17) -> 14.364 | Q17: 0 | R17: =Q17/$P17 -> 0 | S17: 0 | T17: =S17/$P17 -> 0 | U17: 0 | V17: =U17/$P17 -> 0 | W17: 0 | X17: =W17/$P17 -> 0 | Y17: 0 | Z17: =Y17/$P17 -> 0 | AA17: 0 | AB17: =AA17/$P17 -> 0 | AC17: =Q17+S17+U17+W17+Y17+AA17 -> 0 | AD17: =AC17/$P17 -> 0 | AE17: 0 | AF17: =AE17/$P17 -> 0 | AG17: 0 | AH17: =AG17/$P17 -> 0 | AI17: 0 | AJ17: =AI17/$P17 -> 0 | AK17: 0 | AL17: =AK17/$P17 -> 0 | AM17: 0 | AN17: =AM17/$P17 -> 0 | AO17: 0 | AP17: =AO17/$P17 -> 0 | AQ17: =AE17+AG17+AI17+AK17+AM17+AO17 -> 0 | AR17: =AQ17/$P17 -> 0 | AS17: 0 | AT17: =AS17/$P17 -> 0 | AU17: 0 | AV17: =AU17/$P17 -> 0 | AW17: 0 | AX17: =AW17/$P17 -> 0 | AY17: 0 | AZ17: =AY17/$P17 -> 0 | BA17: 0 | BB17: =BA17/$P17 -> 0 | BC17: 0 | BD17: =BC17/$P17 -> 0 | BE17: =AS17+AU17+AW17+AY17+BA17+BC17 -> 0 | BF17: =BE17/$P17 -> 0 | BG17: 0 | BH17: =BG17/$P17 -> 0 | BI17: 0 | BJ17: =BI17/$P17 -> 0 | BK17: 0 | BL17: =BK17/$P17 -> 0 | BM17: 0 | BN17: =BM17/$P17 -> 0 | BO17: 0 | BP17: =BO17/$P17 -> 0 | BQ17: 0 | BR17: =BQ17/$P17 -> 0 | BS17: =BG17+BI17+BK17+BM17+BO17+BQ17 -> 0 | BT17: =BS17/$P17 -> 0 | BU17: 0 | BV17: =BU17/$P17 -> 0 | BW17: 0 | BX17: =BW17/$P17 -> 0 | BY17: 0 | BZ17: =BY17/$P17 -> 0 | CA17: 0 | CB17: =CA17/$P17 -> 0 | CC17: 0 | CD17: =CC17/$P17 -> 0 | CE17: 0 | CF17: =CE17/$P17 -> 0 | CG17: =BU17+BW17+BY17+CA17+CC17+CE17 -> 0 | CH17: =CG17/$P17 -> 0 | CI17: 0 | CJ17: =CI17/$P17 -> 0 | CK17: 0 | CL17: =CK17/$P17 -> 0 | CM17: 0 | CN17: =CM17/$P17 -> 0 | CO17: 0 | CP17: =CO17/$P17 -> 0 | CQ17: 0 | CR17: =CQ17/$P17 -> 0 | CS17: 0 | CT17: =CS17/$P17 -> 0 | CU17: =CI17+CK17+CM17+CO17+CQ17+CS17 -> 0 | CV17: =CU17/$P17 -> 0
C18: 11 | D18: Muro con ventana (Verde) | E18: =E5 -> 35.6 | F18: 4.62 | G18: =E18*F18 -> 164.472 | H18: 1 | I18: 0.75 | J18: 28 | K18: =(H18*I18)*J18 -> 21 | M18: =G18-K18 -> 143.472 | P18: =SUM(L18:O18) -> 143.472 | Q18: 0 | R18: =Q18/$P18 -> 0 | S18: 0 | T18: =S18/$P18 -> 0 | U18: 0 | V18: =U18/$P18 -> 0 | W18: 0 | X18: =W18/$P18 -> 0 | Y18: 0 | Z18: =Y18/$P18 -> 0 | AA18: 0 | AB18: =AA18/$P18 -> 0 | AC18: =Q18+S18+U18+W18+Y18+AA18 -> 0 | AD18: =AC18/$P18 -> 0 | AE18: 0 | AF18: =AE18/$P18 -> 0 | AG18: 0 | AH18: =AG18/$P18 -> 0 | AI18: 0 | AJ18: =AI18/$P18 -> 0 | AK18: 0 | AL18: =AK18/$P18 -> 0 | AM18: 0 | AN18: =AM18/$P18 -> 0 | AO18: 0 | AP18: =AO18/$P18 -> 0 | AQ18: =AE18+AG18+AI18+AK18+AM18+AO18 -> 0 | AR18: =AQ18/$P18 -> 0 | AS18: 0 | AT18: =AS18/$P18 -> 0 | AU18: 0 | AV18: =AU18/$P18 -> 0 | AW18: 0 | AX18: =AW18/$P18 -> 0 | AY18: 0 | AZ18: =AY18/$P18 -> 0 | BA18: 0 | BB18: =BA18/$P18 -> 0 | BC18: 0 | BD18: =BC18/$P18 -> 0 | BE18: =AS18+AU18+AW18+AY18+BA18+BC18 -> 0 | BF18: =BE18/$P18 -> 0 | BG18: 0 | BH18: =BG18/$P18 -> 0 | BI18: 0 | BJ18: =BI18/$P18 -> 0 | BK18: 0 | BL18: =BK18/$P18 -> 0 | BM18: 0 | BN18: =BM18/$P18 -> 0 | BO18: 0 | BP18: =BO18/$P18 -> 0 | BQ18: 0 | BR18: =BQ18/$P18 -> 0 | BS18: =BG18+BI18+BK18+BM18+BO18+BQ18 -> 0 | BT18: =BS18/$P18 -> 0 | BU18: 0 | BV18: =BU18/$P18 -> 0 | BW18: 0 | BX18: =BW18/$P18 -> 0 | BY18: 0 | BZ18: =BY18/$P18 -> 0 | CA18: 0 | CB18: =CA18/$P18 -> 0 | CC18: 0 | CD18: =CC18/$P18 -> 0 | CE18: 0 | CF18: =CE18/$P18 -> 0 | CG18: =BU18+BW18+BY18+CA18+CC18+CE18 -> 0 | CH18: =CG18/$P18 -> 0 | CI18: 0 | CJ18: =CI18/$P18 -> 0 | CK18: 0 | CL18: =CK18/$P18 -> 0 | CM18: 0 | CN18: =CM18/$P18 -> 0 | CO18: 0 | CP18: =CO18/$P18 -> 0 | CQ18: 0 | CR18: =CQ18/$P18 -> 0 | CS18: 0 | CT18: =CS18/$P18 -> 0 | CU18: =CI18+CK18+CM18+CO18+CQ18+CS18 -> 0 | CV18: =CU18/$P18 -> 0
C19: 12 | D19: Placa de balcón (Negro) (x14) | E19: 0.3 | F19: 2.91 | G19: =E19*F19*14 -> 12.222 | N19: =G19 -> 12.222 | P19: =SUM(L19:O19) -> 12.222 | Q19: 0 | R19: =Q19/$P19 -> 0 | S19: 0 | T19: =S19/$P19 -> 0 | U19: 0 | V19: =U19/$P19 -> 0 | W19: 0 | X19: =W19/$P19 -> 0 | Y19: 0 | Z19: =Y19/$P19 -> 0 | AA19: 0 | AB19: =AA19/$P19 -> 0 | AC19: =Q19+S19+U19+W19+Y19+AA19 -> 0 | AD19: =AC19/$P19 -> 0 | AE19: 0 | AF19: =AE19/$P19 -> 0 | AG19: 0 | AH19: =AG19/$P19 -> 0 | AI19: 0 | AJ19: =AI19/$P19 -> 0 | AK19: 0 | AL19: =AK19/$P19 -> 0 | AM19: 0 | AN19: =AM19/$P19 -> 0 | AO19: 0 | AP19: =AO19/$P19 -> 0 | AQ19: =AE19+AG19+AI19+AK19+AM19+AO19 -> 0 | AR19: =AQ19/$P19 -> 0 | AS19: 0 | AT19: =AS19/$P19 -> 0 | AU19: 0 | AV19: =AU19/$P19 -> 0 | AW19: 0 | AX19: =AW19/$P19 -> 0 | AY19: 0 | AZ19: =AY19/$P19 -> 0 | BA19: 0 | BB19: =BA19/$P19 -> 0 | BC19: 0 | BD19: =BC19/$P19 -> 0 | BE19: =AS19+AU19+AW19+AY19+BA19+BC19 -> 0 | BF19: =BE19/$P19 -> 0 | BG19: 0 | BH19: =BG19/$P19 -> 0 | BI19: 0 | BJ19: =BI19/$P19 -> 0 | BK19: 0 | BL19: =BK19/$P19 -> 0 | BM19: 0 | BN19: =BM19/$P19 -> 0 | BO19: 0 | BP19: =BO19/$P19 -> 0 | BQ19: 0 | BR19: =BQ19/$P19 -> 0 | BS19: =BG19+BI19+BK19+BM19+BO19+BQ19 -> 0 | BT19: =BS19/$P19 -> 0 | BU19: 0 | BV19: =BU19/$P19 -> 0 | BW19: 0 | BX19: =BW19/$P19 -> 0 | BY19: 0 | BZ19: =BY19/$P19 -> 0 | CA19: 0 | CB19: =CA19/$P19 -> 0 | CC19: 0 | CD19: =CC19/$P19 -> 0 | CE19: 0 | CF19: =CE19/$P19 -> 0 | CG19: =BU19+BW19+BY19+CA19+CC19+CE19 -> 0 | CH19: =CG19/$P19 -> 0 | CI19: 0 | CJ19: =CI19/$P19 -> 0 | CK19: 0 | CL19: =CK19/$P19 -> 0 | CM19: 0 | CN19: =CM19/$P19 -> 0 | CO19: 0 | CP19: =CO19/$P19 -> 0 | CQ19: 0 | CR19: =CQ19/$P19 -> 0 | CS19: 0 | CT19: =CS19/$P19 -> 0 | CU19: =CI19+CK19+CM19+CO19+CQ19+CS19 -> 0 | CV19: =CU19/$P19 -> 0
C20: 12.1 | D20: Cielo raso balcón (X14) | E20: 0.6 | F20: 1.71 | G20: =E20*F20*14 -> 14.364 | O20: =G20 -> 14.364 | P20: =SUM(L20:O20) -> 14.364 | Q20: 0 | R20: =Q20/$P20 -> 0 | S20: 0 | T20: =S20/$P20 -> 0 | U20: 0 | V20: =U20/$P20 -> 0 | W20: 0 | X20: =W20/$P20 -> 0 | Y20: 0 | Z20: =Y20/$P20 -> 0 | AA20: 0 | AB20: =AA20/$P20 -> 0 | AC20: =Q20+S20+U20+W20+Y20+AA20 -> 0 | AD20: =AC20/$P20 -> 0 | AE20: 0 | AF20: =AE20/$P20 -> 0 | AG20: 0 | AH20: =AG20/$P20 -> 0 | AI20: 0 | AJ20: =AI20/$P20 -> 0 | AK20: 0 | AL20: =AK20/$P20 -> 0 | AM20: 0 | AN20: =AM20/$P20 -> 0 | AO20: 0 | AP20: =AO20/$P20 -> 0 | AQ20: =AE20+AG20+AI20+AK20+AM20+AO20 -> 0 | AR20: =AQ20/$P20 -> 0 | AS20: 0 | AT20: =AS20/$P20 -> 0 | AU20: 0 | AV20: =AU20/$P20 -> 0 | AW20: 0 | AX20: =AW20/$P20 -> 0 | AY20: 0 | AZ20: =AY20/$P20 -> 0 | BA20: 0 | BB20: =BA20/$P20 -> 0 | BC20: 0 | BD20: =BC20/$P20 -> 0 | BE20: =AS20+AU20+AW20+AY20+BA20+BC20 -> 0 | BF20: =BE20/$P20 -> 0 | BG20: 0 | BH20: =BG20/$P20 -> 0 | BI20: 0 | BJ20: =BI20/$P20 -> 0 | BK20: 0 | BL20: =BK20/$P20 -> 0 | BM20: 0 | BN20: =BM20/$P20 -> 0 | BO20: 0 | BP20: =BO20/$P20 -> 0 | BQ20: 0 | BR20: =BQ20/$P20 -> 0 | BS20: =BG20+BI20+BK20+BM20+BO20+BQ20 -> 0 | BT20: =BS20/$P20 -> 0 | BU20: 0 | BV20: =BU20/$P20 -> 0 | BW20: 0 | BX20: =BW20/$P20 -> 0 | BY20: 0 | BZ20: =BY20/$P20 -> 0 | CA20: 0 | CB20: =CA20/$P20 -> 0 | CC20: 0 | CD20: =CC20/$P20 -> 0 | CE20: 0 | CF20: =CE20/$P20 -> 0 | CG20: =BU20+BW20+BY20+CA20+CC20+CE20 -> 0 | CH20: =CG20/$P20 -> 0 | CI20: 0 | CJ20: =CI20/$P20 -> 0 | CK20: 0 | CL20: =CK20/$P20 -> 0 | CM20: 0 | CN20: =CM20/$P20 -> 0 | CO20: 0 | CP20: =CO20/$P20 -> 0 | CQ20: 0 | CR20: =CQ20/$P20 -> 0 | CS20: 0 | CT20: =CS20/$P20 -> 0 | CU20: =CI20+CK20+CM20+CO20+CQ20+CS20 -> 0 | CV20: =CU20/$P20 -> 0
C21: 13 | D21: Muro con ventana (Blanco) | E21: =E5 -> 35.6 | F21: 5.3 | G21: =E21*F21 -> 188.68 | H21: 1.5 | I21: 1.2 | J21: 28 | K21: =(H21*I21)*J21 -> 50.4 | L21: =G21-K21 -> 138.28 | P21: =SUM(L21:O21) -> 138.28 | Q21: 0 | R21: =Q21/$P21 -> 0 | S21: 0 | T21: =S21/$P21 -> 0 | U21: 0 | V21: =U21/$P21 -> 0 | W21: 0 | X21: =W21/$P21 -> 0 | Y21: 0 | Z21: =Y21/$P21 -> 0 | AA21: 0 | AB21: =AA21/$P21 -> 0 | AC21: =Q21+S21+U21+W21+Y21+AA21 -> 0 | AD21: =AC21/$P21 -> 0 | AE21: 0 | AF21: =AE21/$P21 -> 0 | AG21: 0 | AH21: =AG21/$P21 -> 0 | AI21: 0 | AJ21: =AI21/$P21 -> 0 | AK21: 0 | AL21: =AK21/$P21 -> 0 | AM21: 0 | AN21: =AM21/$P21 -> 0 | AO21: 0 | AP21: =AO21/$P21 -> 0 | AQ21: =AE21+AG21+AI21+AK21+AM21+AO21 -> 0 | AR21: =AQ21/$P21 -> 0 | AS21: 0 | AT21: =AS21/$P21 -> 0 | AU21: 0 | AV21: =AU21/$P21 -> 0 | AW21: 0 | AX21: =AW21/$P21 -> 0 | AY21: 0 | AZ21: =AY21/$P21 -> 0 | BA21: 0 | BB21: =BA21/$P21 -> 0 | BC21: 0 | BD21: =BC21/$P21 -> 0 | BE21: =AS21+AU21+AW21+AY21+BA21+BC21 -> 0 | BF21: =BE21/$P21 -> 0 | BG21: 0 | BH21: =BG21/$P21 -> 0 | BI21: 0 | BJ21: =BI21/$P21 -> 0 | BK21: 0 | BL21: =BK21/$P21 -> 0 | BM21: 0 | BN21: =BM21/$P21 -> 0 | BO21: 0 | BP21: =BO21/$P21 -> 0 | BQ21: 0 | BR21: =BQ21/$P21 -> 0 | BS21: =BG21+BI21+BK21+BM21+BO21+BQ21 -> 0 | BT21: =BS21/$P21 -> 0 | BU21: 0 | BV21: =BU21/$P21 -> 0 | BW21: 0 | BX21: =BW21/$P21 -> 0 | BY21: 0 | BZ21: =BY21/$P21 -> 0 | CA21: 0 | CB21: =CA21/$P21 -> 0 | CC21: 0 | CD21: =CC21/$P21 -> 0 | CE21: 0 | CF21: =CE21/$P21 -> 0 | CG21: =BU21+BW21+BY21+CA21+CC21+CE21 -> 0 | CH21: =CG21/$P21 -> 0 | CI21: 0 | CJ21: =CI21/$P21 -> 0 | CK21: 0 | CL21: =CK21/$P21 -> 0 | CM21: 0 | CN21: =CM21/$P21 -> 0 | CO21: 0 | CP21: =CO21/$P21 -> 0 | CQ21: 0 | CR21: =CQ21/$P21 -> 0 | CS21: 0 | CT21: =CS21/$P21 -> 0 | CU21: =CI21+CK21+CM21+CO21+CQ21+CS21 -> 0 | CV21: =CU21/$P21 -> 0
C22: 14 | D22: Muro escaleras (Blanco) | E22: 35 | F22: 4.8 | G22: =E22*F22 -> 168 | H22: 0.25 | I22: 3.1 | J22: 14 | K22: =(H22*I22)*J22 -> 10.85 | L22: =G22-K22 -> 157.15 | P22: =SUM(L22:O22) -> 157.15 | Q22: 0 | R22: =Q22/$P22 -> 0 | S22: 0 | T22: =S22/$P22 -> 0 | U22: 0 | V22: =U22/$P22 -> 0 | W22: 0 | X22: =W22/$P22 -> 0 | Y22: 0 | Z22: =Y22/$P22 -> 0 | AA22: 0 | AB22: =AA22/$P22 -> 0 | AC22: =Q22+S22+U22+W22+Y22+AA22 -> 0 | AD22: =AC22/$P22 -> 0 | AE22: 0 | AF22: =AE22/$P22 -> 0 | AG22: 0 | AH22: =AG22/$P22 -> 0 | AI22: 0 | AJ22: =AI22/$P22 -> 0 | AK22: 0 | AL22: =AK22/$P22 -> 0 | AM22: 0 | AN22: =AM22/$P22 -> 0 | AO22: 0 | AP22: =AO22/$P22 -> 0 | AQ22: =AE22+AG22+AI22+AK22+AM22+AO22 -> 0 | AR22: =AQ22/$P22 -> 0 | AS22: 0 | AT22: =AS22/$P22 -> 0 | AU22: 0 | AV22: =AU22/$P22 -> 0 | AW22: 0 | AX22: =AW22/$P22 -> 0 | AY22: 0 | AZ22: =AY22/$P22 -> 0 | BA22: 0 | BB22: =BA22/$P22 -> 0 | BC22: 0 | BD22: =BC22/$P22 -> 0 | BE22: =AS22+AU22+AW22+AY22+BA22+BC22 -> 0 | BF22: =BE22/$P22 -> 0 | BG22: 0 | BH22: =BG22/$P22 -> 0 | BI22: 0 | BJ22: =BI22/$P22 -> 0 | BK22: 0 | BL22: =BK22/$P22 -> 0 | BM22: 0 | BN22: =BM22/$P22 -> 0 | BO22: 0 | BP22: =BO22/$P22 -> 0 | BQ22: 0 | BR22: =BQ22/$P22 -> 0 | BS22: =BG22+BI22+BK22+BM22+BO22+BQ22 -> 0 | BT22: =BS22/$P22 -> 0 | BU22: 0 | BV22: =BU22/$P22 -> 0 | BW22: 0 | BX22: =BW22/$P22 -> 0 | BY22: 0 | BZ22: =BY22/$P22 -> 0 | CA22: 0 | CB22: =CA22/$P22 -> 0 | CC22: 0 | CD22: =CC22/$P22 -> 0 | CE22: 0 | CF22: =CE22/$P22 -> 0 | CG22: =BU22+BW22+BY22+CA22+CC22+CE22 -> 0 | CH22: =CG22/$P22 -> 0 | CI22: 0 | CJ22: =CI22/$P22 -> 0 | CK22: 0 | CL22: =CK22/$P22 -> 0 | CM22: 0 | CN22: =CM22/$P22 -> 0 | CO22: 0 | CP22: =CO22/$P22 -> 0 | CQ22: 0 | CR22: =CQ22/$P22 -> 0 | CS22: 0 | CT22: =CS22/$P22 -> 0 | CU22: =CI22+CK22+CM22+CO22+CQ22+CS22 -> 0 | CV22: =CU22/$P22 -> 0
