Workbook

Sheet APU O.G
A1: EDIFICIO ATLANTIS
A3: APU IV - Revestimiento de Piso Tipo DECK sobre cuartos de los equipos de piscina y jacuzzi
A5: ACTIVIDAD: Desmontaje de piso tipo Deck | D5: ITEM | E5: 1.0
D6: UNIDAD | E6: M2
A7: I. EQUIPOS
A8: DESCRIPCIÓN | B8: UNIDAD | C8: RENDIMIENTO | D8: TARIFA | E8: VALOR - PARCIAL
A9: Herramienta menor | B9: %MO | C9: 0.1 | D9: =E27 -> 3611.1111 | E9: =C9*D9 -> 361.11111
A11: SUB - TOTAL | E11: =SUM(E9:E9) -> 361.11111
A12: II. MATERIALES
A13: DESCRIPCIÓN | B13: UNIDAD | C13: CANTIDAD | D13: PRECIO - UNIT | E13: VALOR - PARCIAL
A15: Desperdicio 2% | E15: =SUM(E14:E14)*0.02 -> 0
A17: SUB - TOTAL | E17: =SUM(E14:E15) -> 0
A18: III. TRANSPORTE
A19: DESCRIPCIÓN | B19: UNIDAD | C19: RENDIMIENTO | D19: TARIFA | E19: VALOR - PARCIAL
A20: Acarreo LUV | B20: Día | C20: 0 | D20: 0 | E20: 0
A22: SUB - TOTAL | E22: =SUM(E20) -> 0
A23: IV. MANO DE OBRA
A24: DESCRIPCIÓN | B24: UNIDAD | C24: RENDIMIENTO | D24: JORNAL | E24: VALOR - PARCIAL
A25: Oficial | B25: Día | C25: 36 | D25: 130000 | E25: =D25/C25 -> 3611.1111
A27: SUB - TOTAL | E27: =SUM(E25) -> 3611.1111
A29: TOTAL UNITARIO | E29: =SUM(E11,E17,E22,E27) -> 3972.2222
A32: ACTIVIDAD: Restructuración e instalación de lámina de fibrocemento | D32: ITEM | E32: 2
D33: UNIDAD | E33: M2
A34: I. EQUIPOS
A35: DESCRIPCIÓN | B35: UNIDAD | C35: RENDIMIENTO | D35: TARIFA | E35: VALOR - PARCIAL
A36: Herramienta menor | B36: %MO | C36: 0.05 | D36: =E58 -> 7000 | E36: =C36*D36 -> 350
A38: SUB - TOTAL | E38: =SUM(E36:E36) -> 350
A39: II. MATERIALES
A40: DESCRIPCIÓN | B40: UNIDAD | C40: CANTIDAD | D40: PRECIO - UNIT | E40: VALOR - PARCIAL
A41: Lamina fibrocemento de 10mm | B41: Und | C41: 0.35 | D41: 96000 | E41: =C41*D41 -> 33600
A42: Paral Estructural | B42: Und | C42: 1 | D42: 9500 | E42: =C42*D42 -> 9500
A43: Canal Estructural | B43: Und | C43: 1 | D43: 9000 | E43: =C43*D43 -> 9000
A44: Tornillos | B44: Und | C44: 50 | D44: 40 | E44: =C44*D44 -> 2000
A46: Desperdicio 2% | E46: 0
A48: SUB - TOTAL | E48: =SUM(E41:E46) -> 54100
A49: III. TRANSPORTE
A50: DESCRIPCIÓN | B50: UNIDAD | C50: RENDIMIENTO | D50: TARIFA | E50: VALOR - PARCIAL
A51: Acarreo LUV | B51: Día | C51: 0.025 | D51: 60000 | E51: =D51*C51 -> 1500
A53: SUB - TOTAL | E53: =SUM(E51) -> 1500
A54: IV. MANO DE OBRA
...

Sheet RESUMEN APU
A1: EDIFICIO ATLANTIS
A3: ITEM | B3: DESCRIPCIÓN | C3: VALOR
A4: 4 | B4: APU IV - Revestimiento de Piso Tipo DECK sobre cuartos de los equipos de piscina y jacuzzi | C4: =SUM(C5:C9) -> 167654.78
A5: 4.1 | B5: Desmontaje de piso tipo Deck | C5: ='APU O.G'!E29 -> 3972.2222
A6: 4.2 | B6: Restructuración e instalación de lámina de fibrocemento | C6: ='APU O.G'!E60 -> 62950
A7: 4.3 | B7: Impermeabilización de laminas de fibrocemento | C7: ='APU O.G'!E89 -> 11263
A8: 4.4 | B8: Mortero de alistamiento | C8: ='APU O.G'!E118 -> 12166.778
A9: 4.5 | B9: Instalación de piso cerámico incluye boquilla | C9: ='APU O.G'!E150 -> 77302.778
A11: 6 | B11: APU VI - Bordillos de contencion de agua de escorrentia superficial | C11: =SUM(C12:C14) -> 47258.167
A12: 6.1 | B12: Anclaje de barras (pelos) de refuerzo en placa | C12: ='APU O.G'!E182 -> 14151.5
A13: 6.2 | B13: Formaleta para bordillo | C13: ='APU O.G'!E213 -> 16056.667
A14: 6.3 | B14: Fundición de bordillo | C14: ='APU O.G'!E241 -> 17050
A16: 3 | B16: APU III - Retiro de recubrimiento e Impermeabilizacion en area adyacente a la Piscina Pequeña | C16: =SUM(C17:C21) -> 153795.78 | D16: =C17+C19+C20 -> 55393
A17: 3.1 | B17: Remoción de superficie sintética | C17: ='APU O.G'!E332 -> 3900
A18: 3.2 | B18: Demolición de enchape y mortero existentes | C18: ='APU O.G'!E360 -> 21100
A19: 3.3 | B19: Reparación de fisuras y Mortero de nivelación | C19: ='APU O.G'!E389 -> 41730 | D19: 41730
A20: 3.4 | B20: Impermeabilización de superficie | C20: ='APU O.G'!E445 -> 9763 | D20: =D19+29330 -> 71060
A21: 3.5 | B21: Instalación de piso cerámico incluye boquilla | C21: ='APU O.G'!E476 -> 77302.778
A23: 5 | B23: APU V - Construccion de rejilla de drenaje en peatonal | C23: =SUM(C24:C27) -> 461302
A24: 5.1 | B24: Perforación placa e instalación de rejilla | C24: ='APU O.G'!E273 -> 75200
A25: 5.2 | B25: Revestimiento de canal | C25: ='APU O.G'!E303 -> 91102
A26: 5.3 | B26: Suministro e instalación de rejilla metálica | C26: 250000
A27: 5.4 | B27: Desague de tuberia de ALL en 3 " | C27: 45000

Sheet Hoja1
A2: EDIFICIO ATLANTIS
A4: APU 2.1
A6: ACTIVIDAD: Desmontaje de grama | D6: ITEM | E6: A
D7: UNIDAD | E7: M2
A8: I. EQUIPOS
A9: DESCRIPCIÓN | B9: UNIDAD | C9: RENDIMIENTO | D9: TARIFA | E9: VALOR - PARCIAL
A10: Herramienta menor | B10: %MO | C10: 0.1 | D10: =E28 -> 3611.1111 | E10: =C10*D10 -> 361.11111
A12: SUB - TOTAL | E12: =SUM(E10:E10) -> 361.11111
A13: II. MATERIALES
A14: DESCRIPCIÓN | B14: UNIDAD | C14: CANTIDAD | D14: PRECIO - UNIT | E14: VALOR - PARCIAL
A16: Desperdicio 2% | E16: =SUM(E15:E15)*0.02 -> 0
A18: SUB - TOTAL | E18: =SUM(E15:E16) -> 0
A19: III. TRANSPORTE
A20: DESCRIPCIÓN | B20: UNIDAD | C20: RENDIMIENTO | D20: TARIFA | E20: VALOR - PARCIAL
A21: Acarreo LUV | B21: Día | C21: 0 | D21: 0 | E21: 0
A23: SUB - TOTAL | E23: =SUM(E21) -> 0
A24: IV. MANO DE OBRA
A25: DESCRIPCIÓN | B25: UNIDAD | C25: RENDIMIENTO | D25: JORNAL | E25: VALOR - PARCIAL
A26: Oficial | B26: Día | C26: 36 | D26: 130000 | E26: =D26/C26 -> 3611.1111
A28: SUB - TOTAL | E28: =SUM(E26) -> 3611.1111
A30: ACTIVIDAD: Reparación de fisuras y Mortero de nivelación | D30: ITEM | E30: B
D31: UNIDAD | E31: M2
A32: I. EQUIPOS
A33: DESCRIPCIÓN | B33: UNIDAD | C33: RENDIMIENTO | D33: TARIFA | E33: VALOR - PARCIAL
A34: Herramienta menor | B34: %MO | C34: 0.25 | D34: =E54 -> 7000 | E34: =C34*D34 -> 1750
A36: SUB - TOTAL | E36: =SUM(E34:E34) -> 1750
A37: II. MATERIALES
A38: DESCRIPCIÓN | B38: UNIDAD | C38: CANTIDAD | D38: PRECIO - UNIT | E38: VALOR - PARCIAL
A39: Mortero 1:3 | B39: Und | C39: 0.06 | D39: 511000 | E39: =C39*D39 -> 30660
A40: Acronal | B40: GL | C40: 0.02 | D40: 56000 | E40: =C40*D40 -> 1120
E41: =C41*D41 -> 0
A42: Desperdicio 2% | E42: 0
A44: SUB - TOTAL | E44: =SUM(E39:E42) -> 31780
A45: III. TRANSPORTE
A46: DESCRIPCIÓN | B46: UNIDAD | C46: RENDIMIENTO | D46: TARIFA | E46: VALOR - PARCIAL
A47: Acarreo LUV | B47: Día | C47: 0.02 | D47: 60000 | E47: =D47*C47 -> 1200
A49: SUB - TOTAL | E49: =SUM(E47) -> 1200
A50: IV. MANO DE OBRA
A51: DESCRIPCIÓN | B51: UNIDAD | C51: RENDIMIENTO | D51: JORNAL | E51: VALOR - PARCIAL
A52: CUADRILLA 1: 1 Oficial y 1 ayudante | B52: Día | C52: 30 | D52: 210000 | E52: =D52/C52 -> 7000
...

Sheet Hoja2
A1: EDIFICIO ATLANTIS
A3: ITEM | B3: DESCRIPCIÓN | C3: VALOR
A4: 2.1 | B4: Impermeabilizacion de Zonas de anterior Grama Sintetica | C4: =SUM(C5:C8) -> 186300 | D4: 186300
A5: A | B5: Retiro grama | C5: =Hoja1!E28 -> 3611.1111
A6: B | B6: Reparación de fisuras y Mortero de nivelación | C6: =Hoja1!E261 -> 41730
A7: C | B7: Impermeabilización Sikalastic 612 | C7: =Hoja1!E143 -> 135924.93 | E7: 41730
A8: D | B8: Sustitución de sistemas de evacuación | C8: 5033.9556
A11: ITEM | B11: DESCRIPCIÓN | C11: VALOR
A12: 2.2 | B12: Impermeabilizacion de lozas de concreto sobre areas comunes en terrazas 2 y 3 (turco, pto fijo de escalera, etc) | C12: =SUM(C13:C14) -> 142155.93
A13: A | B13: Limpieza Profunda | C13: =Hoja1!E292 -> 6230.992
A14: B | B14: Impermeabilización Sikalastic 612 | C14: =Hoja1!E143 -> 135924.93
A17: ITEM | B17: DESCRIPCIÓN | C17: VALOR
A18: 2.3 | B18: Impermeabilizacion y Mantenimiento Integral a Jardineras de terrazas 2 y 3 | C18: =SUM(C19:C22) -> 159500 | E18: 159500
A19: A | B19: Retiro de tierra y vegetación | C19: 20900
A20: B | B20: Lavado a profundidad | C20: 5768
A21: C | B21: Reparación de fisuras y Mortero de nivelación | C21: 41730
A22: D | B22: Impermeabilización Sikalastic 560 | C22: =Hoja1!E114 -> 91102
E24: 176000
A25: ITEM | B25: DESCRIPCIÓN | C25: VALOR
A26: 2.4 | B26: Impermeabilizacion en area adyacente a la piscina pequeña | C26: =SUM(C27:C31) -> 238999.11
A27: A | B27: Remoción de superficie sintética | C27: =C5 -> 3611.1111
A28: B | B28: Demolición de enchape y mortero existentes | C28: 21100
A29: C | B29: Reparación de fisuras y Mortero de nivelación | C29: 41730 | D29: 18456
A30: D | B30: Impermeabilización de superficie | C30: =Hoja1!E114 -> 91102
A31: E | B31: Instalación de piso cerámico incluye boquilla | C31: 81456
