Workbook

Sheet APU O.G
A1: EDIFICIO ATLANTIS
A3: APUII-5 | Impermeabilizacion y Revestimiento de pisos Deck en cuarto de equipos de Piscina y Jacuzzi
A5: Desmonte de deck existente | D5: ITEM | E5: II.5.1
D6: UNIDAD | E6: M2
A7: I. EQUIPOS
A8: DESCRIPCIÓN | B8: UNIDAD | C8: RENDIMIENTO | D8: TARIFA | E8: VALOR - PARCIAL
A9: Herramienta menor | B9: %MO | C9: 0.1 | D9: =E27 -> 3714.2857 | E9: =C9*D9 -> 371.42857
A11: SUB - TOTAL | E11: =SUM(E9:E9) -> 371.42857
A12: II. MATERIALES
A13: DESCRIPCIÓN | B13: UNIDAD | C13: CANTIDAD | D13: PRECIO - UNIT | E13: VALOR - PARCIAL
A15: Desperdicio 2% | E15: =SUM(E14:E14)*0.02 -> 0
A17: SUB - TOTAL | E17: =SUM(E14:E15) -> 0
A18: III. TRANSPORTE
A19: DESCRIPCIÓN | B19: UNIDAD | C19: RENDIMIENTO | D19: TARIFA | E19: VALOR - PARCIAL
A20: Acarreo LUV | B20: Día | C20: 0 | D20: 0 | E20: 0
A22: SUB - TOTAL | E22: =SUM(E20) -> 0
A23: IV. MANO DE OBRA
A24: DESCRIPCIÓN | B24: UNIDAD | C24: RENDIMIENTO | D24: JORNAL | E24: VALOR - PARCIAL
A25: 1 Oficial + 1 Ayudante | B25: Día | C25: 35 | D25: 130000 | E25: =D25/C25 -> 3714.2857
A27: SUB - TOTAL | E27: =SUM(E25) -> 3714.2857
A29: TOTAL UNITARIO | E29: =SUM(E11,E17,E22,E27) -> 4085.7143
A32: Mantenimiento integral de la estructura de soporte | D32: ITEM | E32: II.5.2
D33: UNIDAD | E33: M2
A34: I. EQUIPOS
A35: DESCRIPCIÓN | B35: UNIDAD | C35: RENDIMIENTO | D35: TARIFA | E35: VALOR - PARCIAL
A36: Herramienta menor | B36: %MO | C36: 0.05 | D36: =E57 -> 4666.6667 | E36: =C36*D36 -> 233.33333
A38: SUB - TOTAL | E38: =SUM(E36:E36) -> 233.33333
A39: II. MATERIALES
A40: DESCRIPCIÓN | B40: UNIDAD | C40: CANTIDAD | D40: PRECIO - UNIT | E40: VALOR - PARCIAL
A41: Paral Estructural | B41: Und | C41: 0.60602657 | D41: 9500 | E41: =C41*D41 -> 5757.2524
A42: Canal Estructural | B42: Und | C42: 0.6061 | D42: 9000 | E42: =C42*D42 -> 5454.9
A43: Tornillos | B43: Und | C43: 50 | D43: 40 | E43: =C43*D43 -> 2000
A45: Desperdicio 2% | E45: 0
A47: SUB - TOTAL | E47: =SUM(E41:E45) -> 13212.152
A48: III. TRANSPORTE
A49: DESCRIPCIÓN | B49: UNIDAD | C49: RENDIMIENTO | D49: TARIFA | E49: VALOR - PARCIAL
A50: Acarreo LUV | B50: Día | C50: 0.01935 | D50: 60000 | E50: =D50*C50 -> 1161
A52: SUB - TOTAL | E52: =SUM(E50) -> 1161
A53: IV. MANO DE OBRA
A54: DESCRIPCIÓN | B54: UNIDAD | C54: RENDIMIENTO | D54: JORNAL | E54: VALOR - PARCIAL
...

Sheet RESUMEN APU
A3: PROYECTO EDIFICIO ATLANTIS
A4: RESUMEN APU
A7: Item | B7: Descripción | C7: UM | D7: Valor
A8: I | B8: Preliminares de obra | C8: M2
A9: I.1 | B9: Campamento | C9: Gl | D9: 650000
A10: I.2 | B10: Señalizacion y Seguridad en Obra | C10: Gl | D10: 170000
A11: I.3 | B11: Asesoria y/o Consulta Tecnica | C11: Gl | D11: 0
A12: II | B12: Impermeabilizaciónes | C12: M2
A13: II.1 | B13: Impermeabilizacion de Zonas de anterior Grama Sintetica | C13: M2 | D13: 186300 | H13: =480/15 -> 32
A14: II.2 | B14: Impermeabilizacion de losas de concreto sobre areas comunes en terrazas 2 y 3 (turco, pto fijo de escalera, etc) | C14: M2 | D14: 186300
A15: II.3 | B15: Impermeabilizacion y Mantenimiento Integral a Jardineras de terrazas 2 y 3 | C15: M2 | D15: 159500
A16: II.4 | B16: Impermeabilizacion en area adyacente a la piscina pequeña | C16: M2 | D16: 176000
A17: II.5 | B17: Impermeabilizacion y Revestimiento de pisos Deck en cuarto de equipos de Piscina y Jacuzzi | C17: M2 | D17: =SUM(D18:D22) -> 190200
A18: II.5.1 | B18: Desmonte de deck existente | D18: ='APU O.G'!E29 -> 4085.7143
A19: II.5.2 | B19: Mantenimiento integral de la estructura de soporte | D19: ='APU O.G'!E59 -> 19273.152
A20: II.5.3 | B20: Impermeabilización de superficie | D20: ='APU O.G'!E89 -> 91101.633
A21: II.5.4 | B21: Instalación de Deck nuevo | D21: ='APU O.G'!E118 -> 66684
A22: II.5.5 | B22: Adecuación de la compuerta de acceso | D22: ='APU O.G'!E147 -> 9055.5
A23: II.6 | B23: Impermeabilizacion y Mantenimeinto Integral a Viga Canal de la cubierta de la torre 4 | C23: ML | D23: =SUM(D24:D26) -> 39000
A24: II.6.1 | B24: Rasqueteado de superfice de Viga Canal (Retiro de material existente) | C24: M2 | D24: ='APU O.G'!E176 -> 2322.2222
A25: II.6.2 | B25: Corrección de pendientes de Viga Canal | C25: M2 | D25: ='APU O.G'!E207 -> 17686.152
A26: II.6.3 | B26: Impermeabilización de Viga Canal con Sika Techo E | C26: M2 | D26: ='APU O.G'!E235 -> 18991.626
A27: II.7 | B27: Recorrido General a la cubierta de Fibrocemento de la torre 4 | C27: M2 | D27: 24300
A28: II.8 | B28: Recorrido a Canales Perimetrales de Domos de Iluminacion Cenital | C28: ML | D28: 25000
A29: II.9 | B29: Recorrido General a Domos de iluminacion Cenital | C29: M2 | D29: 20300
A30: II.10 | B30: Impermeabilizacion y Tratamiento de Materas | C30: M2 | D30: 215000 | E30: =SUM(D31:D36) -> 215000
A31: II.10.1 | B31: Retiro de tierra y vegetación | C31: M2 | D31: ='APU O.G'!E264 -> 20900
A32: II.10.2 | B32: Impermeabilización interior matera | C32: M2 | D32: =D26 -> 18991.626
A33: II.10.3 | B33: Corte de matera en concreto | C33: M2 | D33: 12164
A34: II.10.4 | B34: Fundición de placa en matera | C34: M2 | D34: ='APU O.G'!E293 -> 52237.5
A35: II.10.5 | B35: Impermeabilización de matera general | C35: M2 | D35: =D20 -> 91101.633
A36: II.10.6 | B36: Aplicación de pintura Koraza en parte exterior matera | C36: M3 | D36: ='APU O.G'!E324 -> 19605.241
