Workbook

Sheet medidas definitivas
B1: MEDIDAS EDIFICIO ATLANTIS ARMENIA QUINDIO
B3: PASILLOS TORRES | I3: VACIOS | O3: BARANDAS
B4: CARAS | C4: # PISOS | D4: ML | E4: H | F4: M2 | G4: M2 TOTAL | I4: CARAS | J4: # PISOS | K4: ML | L4: H | M4: M2 | N4: M2 TOTAL | O4: ML
B5: LOBBY ACCESO T1 Y T2 PAREDES | C5: 1 | D5: 91.8 | E5: 2.9 | F5: =+C5*D5*E5 -> 266.22 | G5: =+F5 -> 266.22 | I5: ESCALERAS T1 | J5: 10 | K5: 13
B6: LOBBY ACCESO T1 Y T2 TECHO | C6: 1 | D6: 128 | G6: =+D6*C6 -> 128 | I6: ENTRE TORRE 1 TORRE 2 | J6: 10 | K6: 10.9 | L6: 2.9 | M6: =+L6*K6 -> 31.61 | N6: =+M6*J6 -> 316.1
B7: PASILLOS T1 PAREDES | C7: 10 | D7: =33-10 -> 23 | E7: 2.4 | F7: =+C7*D7*E7 -> 552 | G7: =+F7 -> 552 | I7: TORRE 2 FRENTE A ESCALERAS | J7: 12 | K7: 11.3 | L7: 2.9 | M7: =+L7*K7 -> 32.77 | N7: =+M7*J7 -> 393.24 | O7: 10.2
B8: PASILLOS T1 TECHO | C8: 10 | D8: 32.85 | G8: =+D8*C8 -> 328.5 | I8: TORRE 2 DIAGONAL ASCENSOR | J8: 12 | K8: 17.8 | L8: 2.9 | M8: =+L8*K8 -> 51.62 | N8: =+M8*J8 -> 619.44 | O8: 4.9
B9: PASILLOS T2 PAREDES | C9: 12 | D9: =31.64-20 -> 11.64 | E9: 2.4 | F9: =+C9*D9*E9 -> 335.232 | G9: =+F9 -> 335.232 | I9: TORRE 2 ENTRE VESTIERES T2 Y T3 | J9: 12 | K9: 16.8 | L9: 2.9 | M9: =+L9*K9 -> 48.72 | N9: =+M9*J9 -> 584.64
B10: PASILLOS T2 TECHO | C10: 12 | D10: 23.3 | G10: =+D10*C10 -> 279.6 | I10: ENTRE TORRE 2 Y TORRE 3 (609) | J10: 12 | K10: 18 | L10: 2.9 | M10: =+L10*K10 -> 52.2 | N10: =+M10*J10 -> 626.4 | O10: 5.5
B11: LOBBY ACCESO T3 Y T4 PAREDES | C11: 1 | D11: =107-10 -> 97 | E11: 2.9 | F11: =+C11*D11*E11 -> 281.3 | G11: =+F11 -> 281.3 | I11: FRENTE ESCALERAS TORRE 3 | J11: 12 | K11: 7.5 | L11: 2.9 | M11: =+L11*K11 -> 21.75 | N11: =+M11*J11 -> 261 | O11: 11.6
B12: LOBBY ACCESO T3 Y T4 TECHO | C12: 1 | D12: 154.2 | G12: =+D12*C12 -> 154.2 | I12: ENTRE TORRE 3 Y TORRE 4 | J12: 12 | K12: 19.2 | L12: 2.9 | M12: =+L12*K12 -> 55.68 | N12: =+M12*J12 -> 668.16
B13: PASILLOS T3 PAREDES | C13: 12 | D13: =36.4-20 -> 16.4 | E13: 2.4 | F13: =+C13*D13*E13 -> 472.32 | G13: =+F13 -> 472.32 | I13: FRENTE ESCALERAS TORRE 4 | J13: 12 | K13: 7.5 | L13: 2.9 | M13: =+L13*K13 -> 21.75 | N13: =+M13*J13 -> 261 | O13: 11.7
B14: PASILLOS T3 TECHO | C14: 12 | D14: 30.4 | G14: =+D14*C14 -> 364.8 | I14: DIAGONAL ASCENSOR TORRE 4 | J14: 12 | K14: 15.7 | L14: 2.9 | M14: =+L14*K14 -> 45.53 | N14: =+M14*J14 -> 546.36 | O14: 5.2
B15: PASILLOS T4 PAREDES | C15: 12 | D15: 25.6 | E15: 2.4 | F15: =+C15*D15*E15 -> 737.28 | G15: =+F15 -> 737.28
B16: PASILLOS T4 TECHO | C16: 12 | D16: 34.6 | G16: =+D16*C16 -> 415.2 | L16: TOTAL | N16: =SUM(N6:N15) -> 4276.34 | O16: =SUM(O13:O15) -> 16.9
F17: TOTAL | G17: =SUM(G5:G16) -> 4314.652
B19: ELEMENTOS VOLUMÉTRICOS | I19: ZONA COMERCIAL
B20: FACHADA LATERAL | I20: CARAS | J20: # PISOS | K20: M2 | N20: M2 TOTAL
B21: LAVADO | C21: 3350 | F21: =+C22+C23 -> 2734.44 | I21: FACHADA CRA 19 LOCALES | J21: 1 | K21: 553.4 | N21: =+K21 -> 553.4
B22: GRANIPLAST | C22: =1258.72*2 -> 2517.44 | I22: FACHADA LATERAL LOCALES | J22: 1 | K22: 438.5 | N22: =+K22 -> 438.5
B23: CARAS LATERALES | C23: =(300+130+40+25+33+35+38+46+27+31+32+42+28+51+34+42+45+31+45+30)*0.2 -> 217 | I23: CIELO RASO TORRE 1 PISO 2 | J23: 1 | K23: 115.6 | N23: =+K23*J23 -> 115.6
B24: FACHADA CRA 19 | I24: CIELO RASO TORRE 2-3 PISO 3 | J24: 1 | K24: 118.2 | N24: =+K24*J24 -> 118.2
B25: LAVADO | C25: 3350 | F25: =+C26+C27 -> 2734.44 | I25: CIELO RASO TORRE 4 PISO 4 | J25: 1 | K25: 256 | N25: =+K25*J25 -> 256
B26: GRANIPLAST | C26: =1258.72*2 -> 2517.44 | I26: CIELO RASO MALL DE COMIDAS | J26: 1 | K26: 219.64 | N26: =+K26*J26 -> 219.64
B27: CARAS LATERALES | C27: =(300+130+40+25+33+35+38+46+27+31+32+42+28+51+34+42+45+31+45+30)*0.2 -> 217 | I27: PAREDES MALL DE COMIDAS | J27: 1 | K27: =109.8-50 -> 59.8 | N27: =+K27*J27 -> 59.8
B28: FACHADA FRONTAL | L28: TOTAL | N28: =SUM(N22:N27) -> 1207.74
B29: LAVADO | C29: 265.8 | F29: =+C30+C31 -> 204.5
B30: GRANIPLAST | C30: 185.6 | I30: BALCONES
B31: CARAS LATERALES | C31: =63*0.3 -> 18.9 | I31: APARTAMENTOS
B32: FACHADA POSTERIOR | I32: CARAS | J32: # PISOS | K32: M2 | N32: M2 TOTAL
B33: LAVADO | C33: =16*30 -> 480 | F33: =+C33 -> 480 | I33: TECHOS BALCONES | J33: TODOS | K33: =2.6+8.3+5.3+6+3.3+2+1.6+1.1+3.5+4.7+1.2+2+2.5+1.8+3.4+5.7+4.7+1.8+1.2+2.7+1.8+1.4+1.2+1.4+2.2+2.7+1.6+1.2+1.4+2.2+3.4+2.5+2+2.3+2.2+1.9+1.9+1.8+1.2+2.4+1.2+1.8+1.4+1.5+1.4+1.4+1.3+1.2+2.1+1.2+1.4+5.4+1.7+5.5+8+5.2+1.4+7.3+1.8+1.8 -> 158.1 | N33: =+K33 -> 158.1
B34: ELEMENTOS VOLUMÉTRICOS METÁLICOS EN TERRAZAS | I34: MURO BALCÓN EXTERIOR ABUSARDADO | J34: TODOS | K34: =158.1*2.5*0.6 -> 237.15 | N34: =+K34 -> 237.15
B35: ARCO ML | C35: =15+10.7+15.14+16.2 -> 57.04 | F35: =+C35 -> 57.04 | I35: MURO BALCÓN INTERIOR PINTURA | J35: 1 | K35: =158.1*2.5*0.3 -> 118.575 | N35: =+K35*J35 -> 118.575
B36: M2 | C36: =+C35*1.3 -> 74.152 | F36: =+C36 -> 74.152 | I36: COMERCIO
I37: CARAS | J37: # PISOS | K37: M2 | N37: M2 TOTAL
I38: MURO BALCÓN EXTERIOR ABUSARDADO | J38: TODOS | K38: =+(17.5+18+25.92+20.8)*0.6 -> 49.332 | N38: =+K38 -> 49.332
B39: DOMOS EN POLICARBONATO | I39: MURO BALCÓN INTERIOR PINTURA | J39: TODOS | K39: =+(17.5+18+25.92+20.8)*0.3 -> 24.666 | N39: =+K39 -> 24.666
B40: DESCRIPCIÓN | C40: M2 | D40: ML CANAL | F40: M2 CANAL
B41: CUBIERTA TEJA TORRE 4 PISO 14 | C41: 63.9 | D41: 34.5 | F41: 3.5 | I41: AREA DE VENTANAS
B42: PARQUE INFANTIL-SALÓN SOCIAL | C42: 53.2 | D42: 33.6 | F42: 5.1 | I42: DESCRIPCIÓN | J42: M2 | M42: ML
...

Sheet CUADRO GENERAL DE ACTIVIDADES
A1: EDIFICIO ATLANTIS-ARMENIA
A2: Impermeabilizaciones y Mantenimiento Integral en el area de Terrazas, Cubiertas y Zonas Humedas
A3: ANEXO-01 CUADRO GENERAL DE OFERTA
A4: Oferente: | D4: Convocante: Edificio Atlantis
A5: Rep Legal Oferente: | D5: Rep. Legal Convocante:
A6: INTERVENTORIA: Ing. Luis Fernando Márquez Jaramillo
A7: Fecha:
A8: Capitulo | B8: Item | C8: Descripcion | D8: Unidad | E8: Cantidad | F8: Vr Unitario | G8: Vr Total
A9: I | C9: PRELIMINARES | G9: =+G10+G11+G12 -> 10820000
B10: I.1 | C10: Campamento | D10: Gl | E10: 1 | F10: 650000 | G10: =+E10*F10 -> 650000
B11: I.2 | C11: Señalizacion y Seguridad en Obra | D11: Gl | E11: 1 | F11: 170000 | G11: =+E11*F11 -> 170000
B12: I.3 | C12: Asesoria y/o Consulta Tecnica | D12: Gl | E12: 1 | F12: 10000000 | G12: =+E12*F12 -> 10000000
A13: II | C13: IMPERMEABILIZACIONES | G13: =+SUM(G14:G23) -> 1.5343297e+08
B14: II.1 | C14: Impermeabilizacion de Zonas de anterior Grama Sintetica | D14: M2 | E14: 510 | F14: 186300 | G14: =+E14*F14 -> 95013000
B15: II.2 | C15: Impermeabilizacion de lozas de concreto sobre areas comunes en terrazas 2 y 3 (turco, pto fijo de escalera, etc) | D15: M2 | E15: 60 | F15: 142155.93 | G15: =+E15*F15 -> 8529355.5
B16: II.3 | C16: Impermeabilizacion y Mantenimiento Integral a Jardineras de terrazas 2 y 3 | D16: M2 | E16: 70 | F16: 159500 | G16: =+E16*F16 -> 11165000
B17: II.4 | C17: Impermeabilizacion en area adyacente a la piscina pequeña | D17: M2 | E17: 36 | F17: 238999.11 | G17: =+E17*F17 -> 8603968
B18: II.5 | C18: Impermeabilizacion y Revestimiento de pisos Deck en cuarto de equipos de Piscina y Jacussi | D18: M2 | E18: 42 | F18: 190200 | G18: =+E18*F18 -> 7988400
B19: II.6 | C19: Impermeabilizacion y Mantenimeinto Integral a Viga Canal de la cubierta de la torre 4 | D19: ML | E19: 55 | F19: 39000 | G19: =+E19*F19 -> 2145000
B20: II.7 | C20: Recorrido General a la cubierta de Fibrocemento de la torre 4 | D20: M2 | E20: 305 | F20: 24300 | G20: =+E20*F20 -> 7411500
B21: II.8 | C21: Recorrido a Canales Perimetrales de Domos de Iluminacion Cenital | D21: ML | E21: 105 | F21: 25000 | G21: =+E21*F21 -> 2625000
B22: II.9 | C22: Recorrido General a Domos de iluminacion Cenital | D22: M2 | E22: 172.5 | F22: 20300 | G22: =+E22*F22 -> 3501750
B23: II.10 | C23: Impermeabilizacion y Tratamiento de Materas | D23: M2 | E23: 30 | F23: 215000 | G23: =+E23*F23 -> 6450000
A24: III | C24: INFRAESTRUCTURA PARA EL TRATAMIENTO GENERAL DE AGUAS DE ESCORRENTIA y PLUVIALES | G24: =+G25+G26+G27+G28 -> 15688400
B25: III.1 | C25: Construccion de Rejilla de Drenaje en Peatonal DE Torre 1 | D25: ML | E25: 3 | F25: 450800 | G25: =+E25*F25 -> 1352400
B26: III.2 | C26: Construccion de Bordillos de Contencion de Aguas de escorrentia en terrazas 1, 2 y 3 | D26: ML | E26: 20 | F26: 54050 | G26: =+E26*F26 -> 1081000
B27: III.3 | C27: Construccion de Cubierta sobre sistema de aireacion eolica | D27: M2 | E27: 25 | F27: 463000 | G27: =+E27*F27 -> 11575000
B28: III.4 | C28: Suministro e Instalacion de Cinta EPDM sobre junta de dilatacion entre las torres 2 y 3 | D28: ML | E28: 12 | F28: 140000 | G28: =+E28*F28 -> 1680000
A29: IV | C29: REPARACIONES EN CIELORASOS, CARTERAS Y ESTRUCTURAS LIVIANAS EN LAS TERRAZAS | G29: =+G30+G31 -> 5627250
B30: IV.1 | C30: Reparacion de Cielorasos en Zonas de Areas Comunes de la terraz 2 | D30: M2 | E30: 45 | F30: 91500 | G30: =+E30*F30 -> 4117500
B31: IV.2 | C31: Reparacion de Carteras de los cielos Rasos de la terraza 2 | D31: M2 | E31: 16.5 | F31: 91500 | G31: =+E31*F31 -> 1509750
A32: V | C32: SUMINISTRO Y APLICACIÓN DE PINTURA | G32: =+G33+G34+G35+G36+G37+G38+G39 -> 16401000
B33: V.1 | C33: Suministro y Aplicación de Pintura Tipo Vinilo I sobre paredes de espacios interiores en la terraza 2 (Gimnasio, Salon Social y WCs) | D33: M2 | E33: 110 | F33: 14000 | G33: =+E33*F33 -> 1540000
B34: V.2 | C34: Suministro y Aplicación de Pintura Tipo Koraza para exteriores (muros y fachadas de apartamentos hacia la torre 2, juegos muro azul, muros de soporte de estructuras metalicas elevadas y barandas) | D34: M2 | E34: 250 | F34: 17500 | G34: =+E34*F34 -> 4375000
B35: V.3 | C35: Suministro y Aplicación de Pintura tipo Koraza gris basalto para exteriores en Alfajias de las terrazas | D35: ML | E35: 300 | F35: 8100 | G35: =+E35*F35 -> 2430000
B36: V.4 | C36: Suministro y Aplicación de Pintura de Trafico sobre sendero peatonal de la terraza de la torre 1 | D36: M2 | E36: 110 | F36: 19000 | G36: =+E36*F36 -> 2090000
B37: V.5 | C37: Suministro y Aplicación de Pintura tipo Pintulux 3 en 1 sobre elementos metalicos elevados en terrazas 1, 2 y 3 | D37: ML | E37: 60 | F37: 13400 | G37: =+E37*F37 -> 804000
B38: V.6 | C38: Suministro y Aplicación de Pintura Tipo Pintulux 3 en 1 sobre barandas y Pasamanos de las terrazas | D38: ML | E38: 310 | F38: 13400 | G38: =+E38*F38 -> 4154000
B39: V.7 | C39: Suministro y Aplicación de Sellador Hidropelente Tipo SikaTransparente 10 en paredes de Jardineras de las torres 2 y 3 | D39: M2 | E39: 70 | F39: 14400 | G39: =+E39*F39 -> 1008000
A40: VI | C40: ASEO GENERAL Y RETIRO DE ESCOMBROS | G40: =+G41 -> 450000
...

Sheet APU IMPERMEABILIZACIÓN
A1: EDIFICIO ATLANTIS
A3: APU 2.1
A5: ACTIVIDAD: Desmontaje de grama | D5: ITEM | E5: A
D6: UNIDAD | E6: M2
A7: I. EQUIPOS
A8: DESCRIPCIÓN | B8: UNIDAD | C8: RENDIMIENTO | D8: TARIFA | E8: VALOR - PARCIAL
A9: Herramienta menor | B9: %MO | C9: 0.1 | D9: =E27 -> 3611.1111 | E9: =C9*D9 -> 361.11111
A11: SUB - TOTAL | E11: =SUM(E9:E9) -> 361.11111
A12: II. MATERIALES
A13: DESCRIPCIÓN | B13: UNIDAD | C13: CANTIDAD | D13: PRECIO - UNIT | E13: VALOR - PARCIAL
A15: Desperdicio 2% | E15: =SUM(E14:E14)*0.02 -> 0
A17: SUB - TOTAL | E17: =SUM(E14:E15) -> 0
A18: III. TRANSPORTE
A19: DESCRIPCIÓN | B19: UNIDAD | C19: RENDIMIENTO | D19: TARIFA | E19: VALOR - PARCIAL
A20: Acarreo LUV | B20: Día | C20: 0 | D20: 0 | E20: 0
A22: SUB - TOTAL | E22: =SUM(E20) -> 0
A23: IV. MANO DE OBRA
A24: DESCRIPCIÓN | B24: UNIDAD | C24: RENDIMIENTO | D24: JORNAL | E24: VALOR - PARCIAL
A25: Oficial | B25: Día | C25: 36 | D25: 130000 | E25: =D25/C25 -> 3611.1111
A27: SUB - TOTAL | E27: =SUM(E25) -> 3611.1111
A29: ACTIVIDAD: Reparación de fisuras y Mortero de nivelación | D29: ITEM | E29: B
D30: UNIDAD | E30: M2
A31: I. EQUIPOS
A32: DESCRIPCIÓN | B32: UNIDAD | C32: RENDIMIENTO | D32: TARIFA | E32: VALOR - PARCIAL
A33: Herramienta menor | B33: %MO | C33: 0.25 | D33: =E53 -> 7000 | E33: =C33*D33 -> 1750
A35: SUB - TOTAL | E35: =SUM(E33:E33) -> 1750
A36: II. MATERIALES
A37: DESCRIPCIÓN | B37: UNIDAD | C37: CANTIDAD | D37: PRECIO - UNIT | E37: VALOR - PARCIAL
A38: Mortero 1:3 | B38: Und | C38: 0.06 | D38: 511000 | E38: =C38*D38 -> 30660
A39: Acronal | B39: GL | C39: 0.02 | D39: 56000 | E39: =C39*D39 -> 1120
E40: =C40*D40 -> 0
A41: Desperdicio 2% | E41: 0
A43: SUB - TOTAL | E43: =SUM(E38:E41) -> 31780
A44: III. TRANSPORTE
A45: DESCRIPCIÓN | B45: UNIDAD | C45: RENDIMIENTO | D45: TARIFA | E45: VALOR - PARCIAL
A46: Acarreo LUV | B46: Día | C46: 0.02 | D46: 60000 | E46: =D46*C46 -> 1200
A48: SUB - TOTAL | E48: =SUM(E46) -> 1200
A49: IV. MANO DE OBRA
A50: DESCRIPCIÓN | B50: UNIDAD | C50: RENDIMIENTO | D50: JORNAL | E50: VALOR - PARCIAL
A51: CUADRILLA 1: 1 Oficial y 1 ayudante | B51: Día | C51: 30 | D51: 210000 | E51: =D51/C51 -> 7000
...

Sheet RESUMEN APU
A1: EDIFICIO ATLANTIS
A3: ITEM | B3: DESCRIPCIÓN | C3: VALOR
A4: 2.1 | B4: Impermeabilizacion de Zonas de anterior Grama Sintetica | C4: =SUM(C5:C8) -> 186300
A5: A | B5: Retiro grama | C5: ='APU IMPERMEABILIZACIÓN'!E27 -> 3611.1111
A6: B | B6: Reparación de fisuras y Mortero de nivelación | C6: ='APU IMPERMEABILIZACIÓN'!E55 -> 41730
A7: C | B7: Impermeabilización Sikalastic 612 | C7: ='APU IMPERMEABILIZACIÓN'!E84 -> 135924.93
A8: D | B8: Sustitución de sistemas de evacuación | C8: 5033.9556
A11: ITEM | B11: DESCRIPCIÓN | C11: VALOR
A12: 2.2 | B12: Impermeabilizacion de lozas de concreto sobre areas comunes en terrazas 2 y 3 (turco, pto fijo de escalera, etc) | C12: =SUM(C13:C14) -> 142155.93
A13: A | B13: Limpieza Profunda | C13: ='APU IMPERMEABILIZACIÓN'!E116 -> 6230.992
A14: B | B14: Impermeabilización Sikalastic 612 | C14: ='APU IMPERMEABILIZACIÓN'!E145 -> 135924.93
A17: ITEM | B17: DESCRIPCIÓN | C17: VALOR
A18: 2.3 | B18: Impermeabilizacion y Mantenimiento Integral a Jardineras de terrazas 2 y 3 | C18: =SUM(C19:C22) -> 159500
A19: A | B19: Retiro de tierra y vegetación | C19: ='APU IMPERMEABILIZACIÓN'!E173 -> 20900
A20: B | B20: Lavado a profundidad | C20: 5768
A21: C | B21: Reparación de fisuras y Mortero de nivelación | C21: ='APU IMPERMEABILIZACIÓN'!E201 -> 41730
A22: D | B22: Impermeabilización Sikalastic 560 | C22: ='APU IMPERMEABILIZACIÓN'!E230 -> 91102
A25: ITEM | B25: DESCRIPCIÓN | C25: VALOR
A26: 2.4 | B26: Impermeabilizacion en area adyacente a la piscina pequeña | C26: =SUM(C27:C31) -> 238999.11
A27: A | B27: Remoción de superficie sintética | C27: =C5 -> 3611.1111
A28: B | B28: Demolición de enchape y mortero existentes | C28: 21100
A29: C | B29: Reparación de fisuras y Mortero de nivelación | C29: 41730
A30: D | B30: Impermeabilización de superficie | C30: =[1]Hoja1!E114 -> 91102
A31: E | B31: Instalación de piso cerámico incluye boquilla | C31: 81456
A34: ITEM | B34: DESCRIPCIÓN | C34: VALOR
A35: 2.5 | B35: Impermeabilizacion y Revestimiento de pisos Deck en cuarto de equipos de Piscina y Jacuzzi | C35: =SUM(C36:C40) -> 190200
A36: A | B36: Desmonte de deck existente | C36: 4085.7143
A37: B | B37: Mantenimiento integral de la estructura de soporte | C37: 19273.152
A38: C | B38: Impermeabilización de superficie | C38: 91101.633
A39: D | B39: Instalación de Deck nuevo | C39: 66684
A40: E | B40: Adecuación de la compuerta de acceso | C40: 9055.5
A43: ITEM | B43: DESCRIPCIÓN | C43: VALOR
A44: 2.6 | B44: Impermeabilizacion y Mantenimeinto Integral a Viga Canal de la cubierta de la torre 4 | C44: =SUM(C45:C47) -> 39000
A45: A | B45: Rasqueteado de superfice de Viga Canal (Retiro de material existente) | C45: 2322.2222
A46: B | B46: Corrección de pendientes de Viga Canal | C46: 17686.152
A47: C | B47: Impermeabilización de Viga Canal con Sika Techo E | C47: 18991.626
A50: II.7 | B50: Recorrido General a la cubierta de Fibrocemento de la torre 4 | C50: 24300
A51: II.8 | B51: Recorrido a Canales Perimetrales de Domos de Iluminacion Cenital | C51: 25000
A52: II.9 | B52: Recorrido General a Domos de iluminacion Cenital | C52: 20300
A54: ITEM | B54: DESCRIPCIÓN | C54: VALOR
...
